Workbook
Name DGDFH: #REF!
Name JKHLILU: #REF!
Name 汇率: #REF!
Name 混凝土: #REF!
Name 混凝土4: #REF!
Name 矿粉: #REF!
Name 沥青: #REF!
Name 目标: #REF!
Name 生产列1: #REF!
Name 生产列11: #REF!
Name 生产列15: #REF!
Name 生产列16: #REF!
Name 生产列17: #REF!
Name 生产列19: #REF!
Name 生产列2: #REF!
Name 生产列20: #REF!
Name 生产列3: #REF!
Name 生产列4: #REF!
Name 生产列5: #REF!
Name 生产列6: #REF!
Name 生产列7: #REF!
Name 生产列8: #REF!
Name 生产列9: #REF!
Name 生产期: #REF!
Name 生产期1: #REF!
Name 生产期11: #REF!
Name 生产期15: #REF!
Name 生产期16: #REF!
Name 生产期17: #REF!
Name 生产期19: #REF!
Name 生产期2: #REF!
Name 生产期20: #REF!
Name 生产期3: #REF!
Name 生产期4: #REF!
Name 生产期5: #REF!
Name 生产期6: #REF!
Name 生产期7: #REF!
Name 生产期8: #REF!
Name 生产期9: #REF!
Name 水泥混凝土: #REF!
Name 我: #REF!

Sheet 封面
A7: 检 验 报 告
C25: 产品名称: | H25: M7.5砂浆配合比 | U25: M7.5砂浆配合比
C26: 委托单位: | H26: =水泥砂浆配合比设计报告3!D3 -> XX
C27: 检测类别: | H27: 委 托 检 验
A39: 注 意 事 项
A41: 1、 | C41: 无“检测报告专用章”无效。
A42: 2、 | C42: 复制报告未重新加盖上述印报告章无效。
A43: 3、 | C43: 报告无主检、审核、批准人签名无效。
A44: 4、 | C44: 报告涂改无效。
A45: 5、 | C45: 对检测报告若有异议，应于收到报告之日起十五日内向检测
C46: 单位提出，逾期不予受理。
A47: 6、 | C47: 送样和委托检测仅对来样试样负责。
A48: 7、 | C48: 本报告不得用作广告宣传。
A49: 8、 | C49: 送检试样须在委托书约定保留期内领取，逾期我单位将自行
C50: 处理。
A62: 检 测 报 告 首 页
A63: 检测项目 | D63: =H25 -> M7.5砂浆配合比 | M63: 送样日期 | P63: =[1]砼细集封面!$P$63 -> -2
M64: 报告编号 | P64: =水泥砂浆配合比设计报告3!O2 -> 0
A65: 委托单位 | D65: =H26 -> XX
A66: 检测单位 | D66: =A33 -> 0 | M66: 检测类别 | P66: 委 托 检 验
A67: 委托单位联系方式 | D67: =[1]砼细集封面!$D$67 -> XX | M67: 委托书编号
A69: 生产单位 | D69: =原材料技术指标报告!C16 -> XX | M69: 水 泥 | P69: =原材料技术指标报告!C7 -> 广西华润
P70: =原材料技术指标报告!D7 -> P·C32.5
A71: 试样数量 | D71: 1 | M71: 取样地点 | P71: =D69 -> XX | U71: =水泥砂浆配合比设计报告3!J4 -> JGJ/T 98-2010、JGJ/T 70-2009、JTG E30-2005 | V71: 、
A72: 样品处置 | D72: 检测单位处置 | M72: 抽（送）样者 | P72: =[1]砼细集封面!$P$72 -> XX | U72: =水泥砂浆配合比设计报告3!J5 -> GB50203-20l1
A73: 检测依据 | D73: =U71&V71&U72 -> JGJ/T 98-2010、JGJ/T 70-2009、JTG E30-2005、GB50203-20l1 | U73: 经检验采用三个不同水灰比试验，确定实验室配合比：配制M7.5砂浆配合比，每立方米材料用量（kg/m3）=水泥:砂:水=1:6.91:1.10，7天抗压强度6.8MPa，28天抗压强度11.2MPa， 满足规范要求。
D74: =U74&U75&U76&U77&U78&U79&U80&U81&U82&U83&U84&U85&U86&U87&U88&U89&U90 -> 经检验采用三个不同水灰比试验，确定试验室配合比：配制M7.5砂浆配合比，每立方米材料用量（kg/m3）=245：1680：223：=1：6.86：0.91。7天抗压强度8.8MPa，28天抗压强度13.6Mpa。满足规范试配强度：9.0Mpa，详见水泥砂浆配合比设计试验检测报告。 | U74: 经检验采用三个不同水灰比试验，确定试验室配合比：配制
U75: M7.5
A76: 检 | U76: 砂浆配合比，每立方米材料用量（kg/m3）=
U77: =砂浆配合比记录1!Q24 -> 245：1680：223：
U78: =
A79: 测 | U79: =砂浆配合比记录1!G23 -> 1：6.86：0.91
U80: 。
U81: 7天抗压强度 | V81: =TEXT(A1,"0.00")&V88&W88&X88&Y88&Z88 -> 0.005.35:5.23:5.1
A82: 结 | U82: =砂浆配合比记录2!M14 -> 8.8
U83: MPa，
M84: （检测报告专用章） | U84: 28天抗压强度
A85: 论 | U85: =砂浆配合比记录2!N14 -> 13.6
L86: 签发日期： | O86: =水泥砂浆配合比设计报告3!J14+1 -> 29 | U86: Mpa。
U87: 满足规范试配强度： | V87: 两个快速合并电子表格多个单元格内容的技巧
...

Sheet 原材料技术指标报告
A1: 水泥砂浆配合比设计原材料技术指标报告 | J1: JB010514
A2: =[2]砼用细集料报告11!$A$2 -> 试验室名称:红河路友建筑工程材料检测有限公司 | G2: 报告编号: | H2: 0
A3: 承包单位 | C3: =[1]砼用细集料报告11!$C$3 -> XX | G3: 委托编号 | H3: 0
A4: 工程部位 | C4: / | G4: 设计强度 | H4: 7.5
A5: 序号 | B5: 材料各类 | C5: 产地 | D5: 规格 | E5: 主要试验项目及指标
E6: 试验项目 | G6: 技术要求 | H6: 检测结果 | I6: 结果判定 | J6: 报告编号
A7: 1 | B7: 水泥 | C7: =[3]水泥报告!$C$10 -> 广西华润 | D7: =[3]水泥报告!$C$11 -> P·C32.5 | E7: 初凝时间（min） | G7: 45 | H7: =[3]水泥报告!$G$15 -> 198 | I7: 合格 | J7: =[3]水泥报告!$H$2 -> 0
E8: 终凝时间（min） | G8: 600 | H8: =[3]水泥报告!$G$16 -> 274 | I8: 合格
E9: 安定性（mm） | G9: 合格 | H9: =[3]水泥报告!$G$18 -> 合格 | I9: 合格
E10: 28d抗折强度（MPa) | G10: =[3]水泥报告!$F$21 -> 5.5 | H10: =[3]水泥报告!$H$22 -> 7.75 | I10: 合格
E11: 28d抗压强度（MPa) | G11: =[3]水泥报告!$F$26 -> 32.5 | H11: =[3]水泥报告!$H$28 -> 38.65 | I11: 合格
A12: 2 | B12: 水 | C12: / | D12: / | E12: pH值 | G12: / | H12: / | I12: / | J12: / | N12: 0～5
E13: 不溶物(mg/L) | G13: ≤2000 | H13: / | I13: /
E14: 氯化物（mg/L） | G14: ≤1000 | H14: / | I14: /
E15: 硫酸盐（mg/L） | G15: ≤2000 | H15: / | I15: /
A16: 3 | B16: 砂 | C16: =[1]砼用细集料报告11!$C$8 -> XX | D16: 0～5 | E16: 天然砂含泥量（%) | G16: ≤5.0 | H16: / | I16: / | J16: =[1]砼用细集料报告11!$J$2 -> 0
E17: 细度模数 | G17: 0.7～3.7 | H17: =[1]砼用细集料报告11!$I$28 -> 2.59 | I17: =[1]砼用细集料报告11!$K$28 -> 中砂 | M17: 0.15～4.75
E18: 人工砂石粉含量（%） | G18: ≤10.0 | H18: =[1]砼用细集料报告11!$I$20 -> 6.6 | I18: 合格 | L18: / | O18: 石粉或含泥量（%） | Q18: ≤10.0
C19: =[1]砼用细集料报告11!$J$8 -> 机制砂 | D19: mm | E19: 泥块含量（%） | G19: ≤2.0 | H19: / | I19: /
E20: 压碎指标（%） | G20: ＜30 | H20: / | I20: /
E21: 砂当量（%） | G21: ≥60 | H21: / | I21: / | L21: C30-60 | M21: ＜25
A22: 4 | B22: 碎石 | C22: / | D22: / | E22: 针片状（%） | G22: / | H22: / | I22: / | J22: / | M22: ＜15
E23: 压碎值（%） | G23: / | H23: / | I23: / | M23: ＜20
E24: 含泥量（%） | G24: / | H24: / | I24: / | M24: ＜1.0
A25: 5 | B25: 外加剂 | C25: / | D25: / | E25: 减水率（%） | G25: / | H25: / | I25: / | J25: /
E26: 泌水率比（%） | G26: / | H26: / | I26: /
E27: 初凝时间差（min） | G27: / | H27: / | I27: /
E28: pH值 | G28: / | H28: / | I28: /
E29: 密度（g/cm3） | G29: / | H29: / | I29: /
A30: 6 | B30: 矿粉 | C30: / | D30: / | E30: 密度（g/cm3) | G30: / | H30: / | I30: / | J30: /
E31: 比表面积（m2/kg） | G31: / | H31: / | I31: /
E32: 28d活性指数(%) | G32: / | H32: / | I32: /
E33: 流动度比（%） | G33: / | H33: / | I33: /
E34: 氯离子含量（%） | G34: / | H34: / | I34: /
A35: 7 | B35: 粉煤灰 | C35: / | D35: / | E35: 细度（%） | G35: / | H35: / | I35: / | J35: /
E36: 需水量比（%） | G36: / | H36: / | I36: /
E37: 烧失量（%） | G37: / | H37: / | I37: /
E38: 三氧化硫（%） | G38: / | H38: / | I38: /
A39: 备注 | C39: 该原材料所检项目结果符合规范要求，判定合格。
A40: 试验: 审核: 签发： 日期： 年 月 日（专用章）

Sheet 水泥砂浆配合比设计报告3
A1: 水泥砂浆配合比设计试验检测报告 | Q1: JB010507
A2: =原材料技术指标报告!A2 -> 试验室名称:红河路友建筑工程材料检测有限公司 | M2: 报告编号： | O2: =原材料技术指标报告!H2 -> 0
A3: 送检单位 | D3: =原材料技术指标报告!C3 -> XX | I3: 工程名称 | J3: =[1]砼用细集料报告11!$C$4 -> XX | M3: 委托编号 | O3: =水泥砂浆稠度、分层度记录A组!I3 -> 0 | T3: GB50203-20l1第12页 | W3: JGJ/T 98-2010《砌筑砂浆配合比设计规程》
A4: 工程部位/用途 | D4: =原材料技术指标报告!C4 -> / | I4: 试验依据 | J4: =砂浆配合比记录1!B4 -> JGJ/T 98-2010、JGJ/T 70-2009、JTG E30-2005 | M4: 报告日期 | O4: =J13 -> 28 | W4: JGJ/T 70-2009《建筑砂浆基本性能试验方法》
A5: 试验条件 | D5: =水泥砂浆稠度、分层度记录A组!B4 -> 室温XX℃ 相对湿度XX% | I5: 判定依据 | J5: GB50203-20l1 | M5: 设计强度等级 | O5: =砂浆配合比记录1!L5 -> 7.5 | T5: JGJ/T98-2010 | W5: GB50203-20l1《砌体结构工程施工质量验收规范》
A6: 主要仪器设备 | D6: =砂浆配合比记录1!B5 -> 水泥砂浆稠度测定仪GL01050016、秒表、容量筒、振动台GL01050003、BC-300电脑恒应力试验机GL01040012、电子天平GL01070012 | M6: 施工稠度（mm） | O6: =砂浆配合比记录1!G6 -> 30～50 | W6: JTG E30-2005《公路工程水泥及水泥混凝土试验规程》
A7: 水泥厂家 | D7: =原材料技术指标报告!C7 -> 广西华润 | I7: 水泥品种、强度等级 | K7: =原材料技术指标报告!D7 -> P·C32.5 | M7: 集料产地种类 | O7: =原材料技术指标报告!C16&原材料技术指标报告!L18&原材料技术指标报告!C19 -> XX/机制砂 | T7: 稠度≥50mm | U7: 稠度＜50mm
A8: 试件尺寸及数量 | D8: 7.07×7.07×7.07cm、18个 | I8: 外加剂厂家 | J8: =原材料技术指标报告!C25 -> / | M8: 外加剂品种、掺量 | O8: =原材料技术指标报告!D25 -> /
A9: 养护方法及条件 | D9: =砂浆配合比记录1!G4 -> 温度XX℃ 相对湿度XX% | I9: 拌和及捣实方法 | J9: =砂浆配合比记录1!N14 -> 机械拌合及机械拌合 | M9: 理论配合比 | O9: =砂浆配合比记录1!G23 -> 1：6.86：0.91 | T9: 人工捣实 | U9: 机械捣实
A10: 试件制作及养护特别记事：
A11: 试验结果 | B11: 组别 | C11: 每m3砂浆各材料用量(Kg） | G11: 制件日期 | I11: 抗压日期 | K11: 抗压强度值(MPa ） | M11: 与28d比值 | O11: 砂浆稠度(mm) | P11: 砂浆保水率(%) | Q11: 表观密度（Kg/m3）
C12: 水泥 | D12: 砂 | E12: 水 | F12: 外加剂 | I12: 7d | J12: 28d | K12: 7d | L12: 28d
B13: =水泥砂浆稠度、分层度记录A组!F4 -> A | C13: =砂浆配合比记录1!B14 -> 208 | D13: =砂浆配合比记录1!C14 -> 1680 | E13: =砂浆配合比记录1!D14 -> 220 | F13: =砂浆配合比记录1!E14 -> / | G13: =砂浆配合比记录2!E8 -> 0 | I13: =G13+7 -> 7 | J13: =G13+28 -> 28 | K13: =砂浆配合比记录2!M8 -> 5.1 | L13: =砂浆配合比记录2!N8 -> 8.9 | M13: =砂浆配合比记录2!O8 -> 0.6 | O13: =砂浆配合比记录1!L14 -> 49 | P13: / | Q13: =砂浆配合比记录1!M14 -> / | S13: 1 | T13: =ROUND(D13/C13,2) -> 8.08 | U13: =ROUND(E13/C13,2) -> 1.06 | V13: 减少10%
B14: =水泥砂浆稠度、分层度记录B组!F4 -> B | C14: =砂浆配合比记录1!B15 -> 245 | D14: =砂浆配合比记录1!C15 -> 1680 | E14: =砂浆配合比记录1!D15 -> 223 | F14: =砂浆配合比记录1!E15 -> / | G14: =G13 -> 0 | I14: =I13 -> 7 | J14: =J13 -> 28 | K14: =砂浆配合比记录2!M14 -> 8.8 | L14: =砂浆配合比记录2!N14 -> 13.6 | M14: =砂浆配合比记录2!O14 -> 0.6 | O14: =砂浆配合比记录1!L15 -> 39 | P14: / | Q14: =砂浆配合比记录1!M15 -> / | S14: 1 | T14: =ROUND(D14/C14,2) -> 6.86 | U14: =ROUND(E14/C14,2) -> 0.91 | V14: 基准
B15: ='水泥砂浆稠度、分层度记录 C组'!F4 -> C | C15: =砂浆配合比记录1!B16 -> 282 | D15: =砂浆配合比记录1!C16 -> 1680 | E15: =砂浆配合比记录1!D16 -> 215 | F15: =砂浆配合比记录1!E16 -> / | G15: =G14 -> 0 | I15: =I13 -> 7 | J15: =J13 -> 28 | K15: =砂浆配合比记录2!M20 -> 11.8 | L15: =砂浆配合比记录2!N20 -> 16.7 | M15: =砂浆配合比记录2!O20 -> 0.7 | O15: =砂浆配合比记录1!L16 -> 35 | P15: / | Q15: =砂浆配合比记录1!M16 -> / | S15: 1 | T15: =ROUND(D15/C15,2) -> 5.96 | U15: =ROUND(E15/C15,2) -> 0.76 | V15: 增加10%
A16: 结论 | B16: =S16&S17&S18&S19&S20&S21 -> 通过A、B、C三组不同水泥用量进行配合比试验，B组砂浆稠度、抗压强度同时满足设计及规范要求，故确定选定B组配合比。其理论配合比为（质量比）水泥：细集料：水：=1：6.86：0.91 | S16: 通过A、B、C三组不同水泥用量进行配合比试验，
S17: B
A18: 备注 | S18: 组砂浆稠度、抗压强度同时满足设计及规范要求，故确定选定
A19: 试验: 审核: 签发： 日期： 年 月 日（专用章） | S19: =S17 -> B
S20: 组配合比。其理论配合比为（质量比）水泥：细集料：水：=
S21: =砂浆配合比记录1!G23 -> 1：6.86：0.91

Sheet 水泥砂浆稠度、分层度记录A组
A1: 水泥砂浆稠度、分层度试验记录表
H2: 记录编号： | O2: JGJ/T 70-2009《建筑砂浆基本性能试验方法》
A3: 工程部位/用途 | B3: =原材料技术指标报告!C4 -> / | E3: 试验依据 | F3: JGJ/T 70-2009 | H3: 委托编号 | O3: GJ 52-2006、JGJ/T98-2010、JGJ/T 70-2009
A4: 试验条件 | B4: 室温XX℃ 相对湿度XX% | E4: 配合比编号 | F4: A | H4: 试验日期 | I4: =砂浆配合比记录1!L4 -> 0
A5: 主要仪器设备 | B5: 水泥砂浆稠度仪GL01050016、秒表、容量筒 | H5: 水泥品种等级 | I5: =原材料技术指标报告!D7 -> P·C32.5
A6: 砂浆稠度测定
A7: 试验次数 | B7: 插捣次数(次) | D7: 秒表读数（s） | G7: 下沉深度（mm） | I7: 平均（mm） | M7: 差值 | N7: 误差 | O7: 评定
A8: 1 | B8: 25 | D8: 10 | G8: 48 | I8: =ROUND((G8+G9)/2,0) -> 49 | M8: =ABS(G8-G9) -> 2 | N8: 10 | O8: =IF(AND(M8<N8),"合格",IF(OR(M8>=N8),"不合格","合格")) -> 合格
A9: 2 | B9: 25 | D9: 10 | G9: 50
A10: / | B10: / | D10: / | G10: / | I10: /
A11: / | B11: / | D11: / | G11: /
A12: 砂浆分层度测定
A13: 试验次数 | B13: 砂浆稠度值（mm） | D13: 分层后测得的砂浆稠度值（mm） | G13: 分层度值（cm） | I13: 平均（cm）
A14: / | B14: / | D14: / | G14: / | I14: /
A15: / | B15: / | D15: / | G15: /
A16: / | B16: / | D16: / | G16: / | I16: /
A17: / | B17: / | D17: / | G17: /
A18: 备注：
A19: 试验: 复核:

Sheet 水泥砂浆稠度、分层度记录B组
A1: 水泥砂浆稠度、分层度试验记录表
H2: 记录编号： | O2: JGJ/T 70-2009《建筑砂浆基本性能试验方法》
A3: 工程部位/用途 | B3: =原材料技术指标报告!C4 -> / | E3: 试验依据 | F3: JGJ/T 70-2009 | H3: 委托编号 | I3: =水泥砂浆稠度、分层度记录A组!I3 -> 0 | O3: GJ 52-2006、JGJ/T98-2010、JGJ/T 70-2009
A4: 试验条件 | B4: =水泥砂浆稠度、分层度记录A组!B4:D4 -> 室温XX℃ 相对湿度XX% | E4: 配合比编号 | F4: B | H4: 试验日期 | I4: =水泥砂浆稠度、分层度记录A组!I4:K4 -> 0
A5: 主要仪器设备 | B5: =水泥砂浆稠度、分层度记录A组!B5:G5 -> 水泥砂浆稠度仪GL01050016、秒表、容量筒 | H5: 水泥品种等级 | I5: =水泥砂浆稠度、分层度记录A组!I5:K5 -> P·C32.5
A6: 砂浆稠度测定
A7: 试验次数 | B7: 插捣次数(次) | D7: 秒表读数（s） | G7: 下沉深度（mm） | I7: 平均（mm） | M7: 差值 | N7: 误差 | O7: 评定
A8: 1 | B8: 25 | D8: 10 | G8: 38 | I8: =ROUND((G8+G9)/2,0) -> 39 | M8: =ABS(G8-G9) -> 1 | N8: 10 | O8: =IF(AND(M8<N8),"合格",IF(OR(M8>=N8),"不合格","合格")) -> 合格
A9: 2 | B9: 25 | D9: 10 | G9: 39
A10: / | B10: / | D10: / | G10: / | I10: /
A11: / | B11: / | D11: / | G11: /
A12: 砂浆分层度测定
A13: 试验次数 | B13: 砂浆稠度值（mm） | D13: 分层后测得的砂浆稠度值（mm） | G13: 分层度值（cm） | I13: 平均（cm）
A14: / | B14: / | D14: / | G14: / | I14: /
A15: / | B15: / | D15: / | G15: /
A16: / | B16: / | D16: / | G16: / | I16: /
A17: / | B17: / | D17: / | G17: /
A18: 备注：
A19: 试验: 复核:

Sheet 水泥砂浆稠度、分层度记录 C组
A1: 水泥砂浆稠度、分层度试验记录表
H2: 记录编号： | O2: JGJ/T 70-2009《建筑砂浆基本性能试验方法》
A3: 工程部位/用途 | B3: =原材料技术指标报告!C4 -> / | E3: 试验依据 | F3: JGJ/T 70-2009 | H3: 委托编号 | I3: =水泥砂浆稠度、分层度记录A组!I3 -> 0 | O3: GJ 52-2006、JGJ/T98-2010、JGJ/T 70-2009
A4: 试验条件 | B4: =水泥砂浆稠度、分层度记录A组!B4:D4 -> 室温XX℃ 相对湿度XX% | E4: 配合比编号 | F4: C | H4: 试验日期 | I4: =水泥砂浆稠度、分层度记录A组!I4:K4 -> 0
A5: 主要仪器设备 | B5: =水泥砂浆稠度、分层度记录A组!B5:G5 -> 水泥砂浆稠度仪GL01050016、秒表、容量筒 | H5: 水泥品种等级 | I5: =水泥砂浆稠度、分层度记录A组!I5:K5 -> P·C32.5
A6: 砂浆稠度测定
A7: 试验次数 | B7: 插捣次数(次) | D7: 秒表读数（s） | G7: 下沉深度（mm） | I7: 平均（mm） | M7: 差值 | N7: 误差 | O7: 评定
A8: 1 | B8: 25 | D8: 10 | G8: 33 | I8: =ROUND((G8+G9)/2,0) -> 35 | M8: =ABS(G8-G9) -> 3 | N8: 10 | O8: =IF(AND(M8<N8),"合格",IF(OR(M8>=N8),"不合格","合格")) -> 合格
A9: 2 | B9: 25 | D9: 10 | G9: 36
A10: / | B10: / | D10: / | G10: / | I10: /
A11: / | B11: / | D11: / | G11: /
A12: 砂浆分层度测定
A13: 试验次数 | B13: 砂浆稠度值（mm） | D13: 分层后测得的砂浆稠度值（mm） | G13: 分层度值（cm） | I13: 平均（cm）
A14: / | B14: / | D14: / | G14: / | I14: /
A15: / | B15: / | D15: / | G15: /
A16: / | B16: / | D16: / | G16: / | I16: /
A17: / | B17: / | D17: / | G17: /
A18: 备注：
A19: 试验: 复核:

Sheet 砂浆配合比记录1
A1: 水泥砂浆配合比设计试验记录表（1） | S1: JGJ/T 98-2010《砌筑砂浆配合比设计规程》
K2: 记录编号： | S2: JGJ/T 70-2009《建筑砂浆基本性能试验方法》
A3: 工程部位/用途 | B3: =原材料技术指标报告!C4 -> / | F3: 试验条件 | G3: =水泥砂浆稠度、分层度记录A组!B4 -> 室温XX℃ 相对湿度XX% | K3: 委托编号 | L3: ='水泥砂浆稠度、分层度记录 C组'!I3 -> 0 | S3: JTG E30-2005《公路工程水泥及水泥混凝土试验规程》
A4: 试验依据 | B4: JGJ/T 98-2010、JGJ/T 70-2009、JTG E30-2005 | F4: 养护方法 | G4: 温度XX℃ 相对湿度XX% | K4: 试验日期 | L4: 0
A5: 主要仪器设备 | B5: 水泥砂浆稠度测定仪GL01050016、秒表、容量筒、振动台GL01050003、BC-300电脑恒应力试验机GL01040012、电子天平GL01070012 | K5: 设计强度 | L5: =原材料技术指标报告!H4 -> 7.5 | P5: 试配强度（MPa）
A6: 砂浆种类 | B6: 水泥砂浆 | F6: 施工稠度（mm） | G6: 30～50 | K6: 试配强度 （MPa） | L6: 9.0 | P6: =L5*1.2 -> 9
A7: 材料 | B7: 产地 | F7: 品种等级 | H7: 堆积密度 （Kg/m3） | I7: 表观密度 (Kg/m3) | J7: 空隙率 （%） | K7: 最大粒径 (mm) | M7: 细度模数
A8: 水泥 | B8: =原材料技术指标报告!C7 -> 广西华润 | F8: =原材料技术指标报告!D7 -> P·C32.5 | H8: / | I8: / | J8: / | K8: / | M8: / | Q8: 稠度≥50mm | R8: 稠度＜50mm
A9: 细集料 | B9: =原材料技术指标报告!C16 -> XX | F9: =[4]砼用细集料报告11!$K$28 -> 中砂 | H9: =[1]砼用细集料报告11!$I$25 -> 1680 | I9: =[1]砼用细集料报告11!$I$24 -> 2680 | J9: =[1]砼用细集料报告11!$I$26 -> 37.3 | K9: 4.75 | M9: =[1]砼用细集料报告11!$I$28 -> 2.59
A10: 外加剂 | B10: =原材料技术指标报告!C25 -> / | F10: =原材料技术指标报告!D25 -> / | H10: / | I10: / | J10: / | K10: / | M10: / | Q10: 人工捣实 | R10: 机械捣实
A11: 每m3砂浆各材料用量(Kg） | F11: 试拌砂浆 0.006 m3，各种材料用量
A12: 组别 | B12: 水泥 | C12: 细集料 | D12: 水 | E12: 外加剂 | F12: 组别 | H12: 水泥 | I12: 细集料 | J12: 水 | K12: 外加剂 | L12: 砂浆稠度 (mm) | M12: 砂浆保水率 (%) | N12: 拌和及捣实方法 | P12: 345
A14: A | B14: =ROUND(B15*0.85,0) -> 208 | C14: =C15 -> 1680 | D14: 220 | E14: / | F14: A | H14: =ROUND(B14*$P$14,3) -> 1.248 | I14: =ROUND(C14*$P$14,3) -> 10.08 | J14: =ROUND(D14*$P$14,3) -> 1.32 | K14: / | L14: =水泥砂浆稠度、分层度记录A组!I8 -> 49 | M14: / | N14: 机械拌合及机械拌合 | P14: 0.006
A15: B | B15: 245 | C15: =H9 -> 1680 | D15: 223 | E15: / | F15: B | H15: =ROUND(B15*$P$14,3) -> 1.47 | I15: =ROUND(C15*$P$14,3) -> 10.08 | J15: =ROUND(D15*$P$14,3) -> 1.338 | K15: / | L15: =水泥砂浆稠度、分层度记录B组!I8 -> 39 | M15: / | N15: =N14 -> 机械拌合及机械拌合
A16: C | B16: =ROUND(B15*1.15,0) -> 282 | C16: =C15 -> 1680 | D16: 215 | E16: / | F16: C | H16: =ROUND(B16*$P$14,3) -> 1.692 | I16: =ROUND(C16*$P$14,3) -> 10.08 | J16: =ROUND(D16*$P$14,3) -> 1.29 | K16: / | L16: ='水泥砂浆稠度、分层度记录 C组'!I8 -> 35 | M16: / | N16: =N15 -> 机械拌合及机械拌合 | O16: 理论 | P16: 差值 | Q16: 设计配合比
A17: 材料 | B17: 按强度试验结果确定每m3材料用量 （Kg） | F17: 按实测表观密度值校正（各材料用量×校正系数） | K17: 说明：1、 砂浆试配强度fm,0=kf2 2、实测表观密度值与理论表观密度值之差的绝对值不超过理论值的2%时，不需要校正； 3、对选定的配合比进行表观密度值校正。 | O17: =B14+C14+D14 -> 2108 | P17: =M14-O17 -> #VALUE! | Q17: 1 | S17: ： | T17: 水泥 | U17: ：
F18: 校正后每m3材料用量（Kg） | O18: =B15+C15+D15 -> 2148 | P18: =M15-O18 -> #VALUE! | Q18: =ROUND(F20/$F$19,2) -> 6.86 | S18: ： | T18: 细集料 | U18: ：
A19: 水泥 | B19: =B15 -> 245 | F19: =B19 -> 245 | O19: =B16+C16+D16 -> 2177 | P19: =M16-O19 -> #VALUE! | Q19: =ROUND(F21/$F$19,2) -> 0.91 | T19: 水 | U19: ： | V19: =F19 -> 245
A20: 细集料 | B20: =C16 -> 1680 | F20: =B20 -> 1680 | T20: 外加剂 | U20: ： | V20: =F20 -> 1680
A21: 水 | B21: =D15 -> 223 | F21: =B21 -> 223 | V21: =F21 -> 223
A22: 外加剂 | B22: =E16 -> / | F22: =B22 -> /
A23: 砂浆设计配合比 | C23: 水泥：细集料：水：外加剂= | G23: =Q17&S17&Q18&S18&Q19&S19&Q20 -> 1：6.86：0.91
A24: 备注： | Q24: =V19&U17&V20&U18&V21&U19&V22 -> 245：1680：223：
A25: 试验: 复核:
H27: =ROUND(B20/B19,2) -> 6.86 | J27: =C16/B16 -> 5.9574468
H28: =ROUND(B21/B19,2) -> 0.91 | J28: =D16/B16 -> 0.76241135

Sheet 砂浆配合比记录2
A1: 水泥砂浆配合比设计试验记录表（2）
L2: 记录编号： | M2: =水泥砂浆稠度、分层度记录A组!I2 -> 0 | O2: =砂浆配合比记录1!N2+1 -> 1 | Q2: 极限荷载为0.05的倍数 | U2: JGJ/T 98-2010《砌筑砂浆配合比设计规程》
A3: 工程部位/用途 | D3: =原材料技术指标报告!C4 -> / | G3: 试验条件 | I3: =水泥砂浆稠度、分层度记录A组!B4 -> 室温XX℃ 相对湿度XX% | L3: 委托编号 | M3: =砂浆配合比记录1!L3 -> 0 | U3: JGJ/T 70-2009《建筑砂浆基本性能试验方法》
A4: 试验依据 | D4: JTG E30-2005 | G4: 养护方法 | I4: =砂浆配合比记录1!G4 -> 温度XX℃ 相对湿度XX% | L4: 试验日期 | M4: =F8 -> 7 | U4: JTG E30-2005《公路工程水泥及水泥混凝土试验规程》
A5: 主要仪器设备 | D5: BC-300电脑恒应力试验机GL01040012 | L5: 砂浆设计强度（MPa） | N5: =砂浆配合比记录1!L5 -> 7.5
A6: 试验结果 | B6: 组别 | C6: 每m3砂浆水泥用量(Kg） | D6: 试件编号 | E6: 制件日期 | F6: 试压日期 | H6: 试件面积（mm2 ) | I6: 极限荷载（KN） | K6: 抗压强度(MPa ） | M6: 平均值(MPa ） | O6: 与28d 比值 (%)
F7: 7d | G7: 28d | I7: 7d | J7: 28d | K7: 7d | L7: 28d | M7: 7d | N7: 28d
B8: A | C8: =砂浆配合比记录1!B14 -> 208 | D8: 1 | E8: 0 | F8: =E8+7 -> 7 | G8: =E8+28 -> 28 | H8: =ROUND(70.7*70.7,0) -> 4998 | I8: 26.05 | J8: 44.25 | K8: =ROUND(I8/$H$8*1000,1) -> 5.2 | L8: =ROUND(J8/$H$8*1000,1) -> 8.9 | M8: =ROUND(AVERAGE(K8:K13),1) -> 5.1 | N8: =ROUND(AVERAGE(L8:L13),1) -> 8.9 | O8: =ROUND(M8/N8,1) -> 0.6 | S8: 抗压试验
I9: 25.1 | J9: 40.3 | K9: =ROUND(I9/$H$8*1000,1) -> 5 | L9: =ROUND(J9/$H$8*1000,1) -> 8.1 | U9: 差值 | V9: 平均值15% | W9: 评定
I10: 24.75 | J10: 47.8 | K10: =ROUND(I10/$H$8*1000,1) -> 5 | L10: =ROUND(J10/$H$8*1000,1) -> 9.6 | S10: 最大值 | T10: =MAX(L8:L13) -> 9.6 | U10: =T10-N8 -> 0.7 | V10: =ROUND(N8*0.15,1) -> 1.3 | W10: =IF(AND(U10<V10),"合格",IF(OR(U10>=V10),"不合格","合格")) -> 合格
I11: 24.9 | J11: 45.65 | K11: =ROUND(I11/$H$8*1000,1) -> 5 | L11: =ROUND(J11/$H$8*1000,1) -> 9.1
I12: 26.4 | J12: 43.1 | K12: =ROUND(I12/$H$8*1000,1) -> 5.3 | L12: =ROUND(J12/$H$8*1000,1) -> 8.6 | S12: 最小值 | T12: =MIN(L8:L13) -> 8.1 | U12: =T12-N8 -> -0.8 | V12: =V10 -> 1.3 | W12: =IF(AND(U12<V12),"合格",IF(OR(U12>=V12),"不合格","合格")) -> 合格
I13: 24.55 | J13: 45.25 | K13: =ROUND(I13/$H$8*1000,1) -> 4.9 | L13: =ROUND(J13/$H$8*1000,1) -> 9.1
B14: B | C14: =砂浆配合比记录1!B15 -> 245 | D14: 2 | E14: =E8 -> 0 | F14: =E14+7 -> 7 | G14: =E14+28 -> 28 | H14: =H8 -> 4998 | I14: 42.5 | J14: 73.85 | K14: =ROUND(I14/$H$14*1000,1) -> 8.5 | L14: =ROUND(J14/$H$8*1000,1) -> 14.8 | M14: =ROUND(AVERAGE(K14:K19),1) -> 8.8 | N14: =ROUND(AVERAGE(L14:L19),1) -> 13.6 | O14: =ROUND(M14/N14,1) -> 0.6 | S14: 抗压试验
I15: 41.95 | J15: 70.75 | K15: =ROUND(I15/$H$14*1000,1) -> 8.4 | L15: =ROUND(J15/$H$8*1000,1) -> 14.2 | U15: 差值 | V15: 平均值15% | W15: 评定
I16: 42.5 | J16: 67.95 | K16: =ROUND(I16/$H$14*1000,1) -> 8.5 | L16: =ROUND(J16/$H$8*1000,1) -> 13.6 | S16: 最大值 | T16: =MAX(L14:L19) -> 14.8 | U16: =T16-N14 -> 1.2 | V16: =ROUND(N14*0.15,1) -> 2 | W16: =IF(AND(U16<V16),"合格",IF(OR(U16>=V16),"不合格","合格")) -> 合格
I17: 42.25 | J17: 68.85 | K17: =ROUND(I17/$H$14*1000,1) -> 8.5 | L17: =ROUND(J17/$H$8*1000,1) -> 13.8
I18: 44.55 | J18: 62.65 | K18: =ROUND(I18/$H$14*1000,1) -> 8.9 | L18: =ROUND(J18/$H$8*1000,1) -> 12.5 | S18: 最小值 | T18: =MIN(L14:L19) -> 12.5 | U18: =T18-N14 -> -1.1 | V18: =V16 -> 2 | W18: =IF(AND(U18<V18),"合格",IF(OR(U18>=V18),"不合格","合格")) -> 合格
I19: 50.5 | J19: 63.7 | K19: =ROUND(I19/$H$14*1000,1) -> 10.1 | L19: =ROUND(J19/$H$8*1000,1) -> 12.7
B20: C | C20: =砂浆配合比记录1!B16 -> 282 | D20: 3 | E20: =E14 -> 0 | F20: =E20+7 -> 7 | G20: =E20+28 -> 28 | H20: =H8 -> 4998 | I20: 61.75 | J20: 85.45 | K20: =ROUND(I20/$H$20*1000,1) -> 12.4 | L20: =ROUND(J20/$H$8*1000,1) -> 17.1 | M20: =ROUND(AVERAGE(K20:K25),1) -> 11.8 | N20: =ROUND(AVERAGE(L20:L25),1) -> 16.7 | O20: =ROUND(M20/N20,1) -> 0.7 | S20: 抗压试验
I21: 55.4 | J21: 85.2 | K21: =ROUND(I21/$H$20*1000,1) -> 11.1 | L21: =ROUND(J21/$H$8*1000,1) -> 17 | U21: 差值 | V21: 平均值15% | W21: 评定
I22: 61.6 | J22: 74.4 | K22: =ROUND(I22/$H$20*1000,1) -> 12.3 | L22: =ROUND(J22/$H$8*1000,1) -> 14.9 | S22: 最大值 | T22: =MAX(L20:L25) -> 18.3 | U22: =T22-N20 -> 1.6 | V22: =ROUND(N20*0.15,1) -> 2.5 | W22: =IF(AND(U22<V22),"合格",IF(OR(U22>=V22),"不合格","合格")) -> 合格
I23: 52 | J23: 82.9 | K23: =ROUND(I23/$H$20*1000,1) -> 10.4 | L23: =ROUND(J23/$H$8*1000,1) -> 16.6
I24: 64.05 | J24: 91.35 | K24: =ROUND(I24/$H$20*1000,1) -> 12.8 | L24: =ROUND(J24/$H$8*1000,1) -> 18.3 | S24: 最小值 | T24: =MIN(L20:L25) -> 14.9 | U24: =T24-N20 -> -1.8 | V24: =V22 -> 2.5 | W24: =IF(AND(U24<V24),"合格",IF(OR(U24>=V24),"不合格","合格")) -> 合格
I25: 57.95 | J25: 80.85 | K25: =ROUND(I25/$H$20*1000,1) -> 11.6 | L25: =ROUND(J25/$H$8*1000,1) -> 16.2
A26: 备注
A27: 试验: 复核:
R28: JGJ/T 98-2010、JGJ/T 70-2009
