Workbook

Sheet 土类判定
B2: 公路工程土类自动判定表 | I2: 判断过程 | M2: 土名对照表
B3: 请输入土的试验数据 | I3: 粗粒土含量 | J3: 砾含量 | K3: 砂含量 | L3: 细粒土含量 | M3: 土样代号 | N3: 土样名称 | O3: 土样代号 | P3: 土样名称
B4: 液限 （%） | C4: 塑限 （%） | D4: 2mm筛通过率 （%） | E4: 0.074mm筛通过率 （%） | F4: 是否有机质土？ （输入“是”或“否”） | I4: =100-E5 -> 73.490603 | J4: =100-D5 -> 0 | K4: =D5-E5 -> 73.490603 | L4: =E5 -> 26.509397 | M4: GF | N4: 细粒土砾 | O4: SF | P4: 细粒土砂
B5: =液塑限!K18 -> 28.3 | C5: =液塑限!K19 -> 18.995098 | D5: =颗粒分析!J16 -> 100 | E5: =颗粒分析!J20 -> 26.509397 | F5: 否 | I5: 液限 | J5: 塑限 | K5: IP | L5: IP_线上 | M5: GW | N5: 级配良好砾 | O5: MHS | P5: 含砂高液限粉土
B6: 土的工程分类 | I6: =B5 -> 28.3 | J6: =C5 -> 18.995098 | K6: =I6-J6 -> 9.3049016 | L6: =0.73*(I6-20) -> 6.059 | M6: GP | N6: 级配不良砾 | O6: MLS | P6: 含砂低液限粉土
B7: 土样名称 | C7: =IF(F7=M5,N5,IF(F7=M6,N6,IF(F7=M7,N7,IF(F7=M8,N8,IF(F7=M9,N9,IF(F7=M10,N10,IF(F7=M11,N11,IF(F7=M12,N12,J12)))))))) -> 粘土质砂 | E7: 土样代号 | F7: =IF(I4>50,I8,K8) -> SC | I7: 粗粒土鉴别 | K7: 细粒土鉴别 | M7: GM | N7: 粉土质砾 | O7: CH | P7: 高液限粘土
I8: =IF(L4>=50,"——",IF(J4>50,J9,J10)) -> SC | K8: =IF(L4<50,"——",IF(F5="是",L11,IF(L4>=75,L10,L9))) -> —— | M8: GC | N8: 粘土质砾 | O8: CL | P8: 低液限粘土
I9: 砾类土 | J9: =IF(OR(L4>=50,J4<=50),"——",IF(L4<5,"GW or GP",IF(L4>15,IF(K6>L6,"GC","GM"),"GF"))) -> —— | K9: 含粗粒的细粒土 | L9: =IF(OR(L4<50,L4>75),"——",IF(K6>L6,IF(I6>=50,IF(J4>K4,"CHG","CHS"),IF(K6>=10,IF(J4>K4,"CLG","CLS"),"Ip=10、A、B线三角区内，不能判定！")),IF(I6>=50,IF(J4>K4,"MHG","MHS"),IF(K6>=10,IF(J4>K4,"MLG","MLS"),"在Ip=10、A、B线三角区内，不能判定！")))) -> —— | M9: SW | N9: 级配良好砂 | O9: CHG | P9: 含砾高液限粘土
B10: 使用 说明 | C10: 注意：1、只需在蓝色区域输入试验数据即可直接得出土的工程分类！ 2、本表适用于除特殊土和巨粒土以外的土类。 | I10: 砂类土 | J10: =IF(OR(L4>=50,J4>50),"——",IF(L4<5,"SW or SP",IF(L4>15,IF(K6>L6,"SC","SM"),"SF"))) -> SC | K10: 细粒土 | L10: =IF(OR(L4<50,L4<75),"——",IF(K6>L6,IF(I6>=50,"CH",IF(K6>=10,"CL","Ip=10、A、B线三角区内，不能判定！")),IF(I6>=50,"MH",IF(K6>=10,"ML","Ip=10、A、B线三角区内，不能判定！")))) -> —— | M10: SP | N10: 级配不良砂 | O10: CLG | P10: 含砾低液限粘土
K11: 有机质土 | L11: =IF(OR(L4<50,F5="否"),"——",IF(K6>L6,IF(I6>=50,"CHO",IF(K6>=10,"CLO","Ip=10、A、B线三角区内，不能判定！")),IF(I6>=50,"MHO",IF(K6>=10,"MLO","Ip=10、A、B线三角区内，不能判定！")))) -> —— | M11: SM | N11: 粉土质砂 | O11: CHS | P11: 含砂高液限粘土
C12: 1、本表由 XXXXXX市公路工程试验检测中心 nolimy 设计 (版本号:TLPD_V2004.02)。 2、如有疑问或错误请致电： E-mail: nolimy@163.com QQ：61788799。 3、感谢“筑路人论坛: http://www.17grow.com/”各位网友提供的宝贵意见！ 4、本表完全免费供大家使用！ | I12: 缓冲公式 | J12: =IF(F7=M13,N13,IF(F7=M14,N14,IF(F7=M15,N15,IF(F7=M16,N16,IF(F7=O5,P5,IF(F7=O6,P6,IF(F7=O7,P7,IF(F7=O8,P8,K12)))))))) -> 不能判定！ | K12: =IF(F7=O9,P9,IF(F7=O10,P10,IF(F7=O11,P11,IF(F7=O12,P12,IF(F7=O13,P13,IF(F7=O14,P14,IF(F7=O15,P15,IF(F7=O16,P16,L12)))))))) -> 不能判定！ | L12: =IF(F7=M17,N17,IF(F7=O17,P17,IF(F7=M4,N4,IF(F7=O4,P4,"不能判定！")))) -> 不能判定！ | M12: SC | N12: 粘土质砂 | O12: CLS | P12: 含砂低液限粘土
M13: MH | N13: 高液限粉土 | O13: CHO | P13: 有机质高液限粘土
M14: ML | N14: 低液限粉土 | O14: CLO | P14: 有机质低液限粘土
M15: MHG | N15: 含砾高液限粉土 | O15: MHO | P15: 有机质高液限粉土
M16: MLG | N16: 含砾低液限粉土 | O16: MLO | P16: 有机质低液限粉土
M17: GW or GP | N17: 级配良好(或不良)砾 | O17: SW or SP | P17: 级配良好(或不良)砂

Sheet 报告
A1: 土 壤 试 验 分 析 报 告
D2: 编号：C—3—2— | E2: J02- 0039
A3: 施工单位 | B3: =IF(E3=G3,H3,IF(E3=G4,H4,IF(E3=G5,H5,IF(E3=G6,H6,IF(E3=G7,H7,0))))) -> 中铁六局呼铁局建设有限公司 | D3: 合 同 号 | E3: 02 | G3: 01 | H3: 中国第二冶金建设有限公司
A4: 监理单位 | B4: 内蒙古广誉建设监理有限责任公司 | G4: 02 | H4: 中铁六局呼铁局建设有限公司
A5: 试样名称 | B5: 土 | D5: 试验规程 | E5: JTJ 051-93 | G5: 03 | H5: 龙建路桥股份有限公司
A6: 试样来源 | B6: K3+600挖方段 | D6: 试验日期 | E6: 2007.11.1 | G6: 04 | H6: 核工业华东建设工程集团公司
A7: 试 验 人 | D7: 审 核 人 | G7: 05 | H7: 陕西中航南方机械化工程公司
A9: 筛 分
A10: 筛孔尺寸（mm） | C10: 累计筛余（％） | D10: 筛孔尺寸（mm） | E10: 累计筛余（％）
D11: 2 | E11: =颗粒分析!L16 -> 0
A12: 60 | D12: 1 | E12: =颗粒分析!L17 -> 3.9091436
A13: 40 | D13: 0.5 | E13: =颗粒分析!L18 -> 20.224264
A14: 20 | D14: 0.25 | E14: =颗粒分析!L19 -> 39.527324
A15: 10 | D15: 0.074 | E15: =颗粒分析!L20 -> 73.490603
A16: 5 | D16: < 0.074 | E16: =颗粒分析!L21 -> 100
A17: 2
A18: 液 限 | C18: =液塑限!K18 -> 28.3 | D18: 塑性指数 | E18: =液塑限!K20 -> 9.3
A19: 最佳含水量(％) | C19: 11 | D19: 最大干密度(g/cm3) | E19: 1.89
A20: 对应于 ％压实度的ＣＢＲ（l=2.5mm）为 ％ | D20: 对应于 ％压实度的ＣＢＲ（l=2.5mm）为 ％
A21: 土壤定名 | B21: =土类判定!C7 -> 粘土质砂
B22: 负责人： 日期：
A24: 结
B26: 监理工程师： 日期：
A27: 论

Sheet 颗粒分析
A1: 颗粒分析试验记录（筛分法）
G2: 编号：C-3-1- | I2: =报告!E2 -> J02- 0039
A3: 施工单位 | B3: =报告!B3 -> 中铁六局呼铁局建设有限公司 | G3: 合 同 号 | I3: =报告!E3 -> 02
A4: 监理单位 | B4: =报告!B4 -> 内蒙古广誉建设监理有限责任公司
A5: 试样名称 | B5: =报告!B5 -> 土 | G5: 试验规程 | I5: =报告!E5 -> JTJ 051-93
A6: 试样来源 | B6: =报告!B6 -> K3+600挖方段 | G6: 试验日期 | I6: =报告!E6 -> 2007.11.1
A7: 试 验 人 | G7: 审 核 人
A9: 筛前总土质量= | C9: 1000 | D9: g | G9: 小于2mm土取试样质量= | I9: 500 | J9: g | T9: 筛前总土质量= 500 g 小于2mm取试样质量= 500 g
A10: 小于2mm土质量= | C10: 1000 | D10: g | E10: 小于2mm土占试样总质量的 | I10: 100 | J10: % | T10: 小于2mm土质量= 500 g 小于2mm土占总土质量= 100 %
A11: 粗筛分析 | F11: 细筛分析
A12: 筛孔尺寸（mm） | B12: 累积留筛土质量（g） | C12: 通过该 | D12: 通过该 | E12: 筛孔尺寸（mm） | G12: 累积留筛土质量（g） | H12: 通过该孔径的土质量（g） | I12: 通过该 | J12: 占总土质量百分比（%） | L12: 孔径的土累计百分率%
C13: 孔径的 | D13: 孔土质 | I13: 孔径土
C14: 土质量 | D14: 量百分 | I14: 质量百
C15: （g） | D15: 比（%） | I15: 分比（%）
E16: 2 | G16: 0 | H16: =I9-G16 -> 500 | I16: =H16/I9*100 -> 100 | J16: =I16*I10*0.01 -> 100 | L16: =100-I16 -> 0
A17: 60 | B17: 0 | C17: =C9-B17 -> 1000 | D17: =C17/C9*100 -> 100 | E17: 1 | G17: =RAND()*11.1+I9*0.022 -> 19.545718 | H17: =I9-G17 -> 480.45428 | I17: =H17/I9*100 -> 96.090856 | J17: =I17*I10/100 -> 96.090856 | L17: =100-I17 -> 3.9091436
A18: 40 | B18: =C9*(ROUND(RAND()*0.08+0.07,3))+ROUND(RAND(),1) -> 149.3 | C18: =C9-B18 -> 850.7 | D18: =C18/C9*100 -> 85.07 | E18: 0.5 | G18: =RAND()*11.1+I9*0.198 -> 101.12132 | H18: =I9-G18 -> 398.87868 | I18: =H18/I9*100 -> 79.775736 | J18: =I18*I10*0.01 -> 79.775736 | L18: =100-I18 -> 20.224264
A19: 20 | B19: =C9*(ROUND(RAND()*0.08+0.07,3))+ROUND(RAND(),1)+B18 -> 283.9 | C19: =C9-B19 -> 716.1 | D19: =C19/C9*100 -> 71.61 | E19: 0.25 | G19: =RAND()*22.2+I9*0.388 -> 197.63662 | H19: =I9-G19 -> 302.36338 | I19: =H19/I9*100 -> 60.472676 | J19: =I19*I10*0.01 -> 60.472676 | L19: =100-I19 -> 39.527324
A20: 10 | B20: =C9*(ROUND(RAND()*0.08+0.07,3))+ROUND(RAND(),1)+B19 -> 375.3 | C20: =C9-B20 -> 624.7 | D20: =C20/C9*100 -> 62.47 | E20: 0.074 | G20: =RAND()*9+I9*0.724 -> 367.45302 | H20: =I9-G20 -> 132.54698 | I20: =H20/I9*100 -> 26.509397 | J20: =I20*I10*0.01 -> 26.509397 | L20: =100-I20 -> 73.490603
A21: 5 | B21: =C9*(ROUND(RAND()*0.08+0.07,3))+ROUND(RAND(),1)+B20 -> 470 | C21: =C9-B21 -> 530 | D21: =C21/C9*100 -> 53 | E21: <0.074 | G21: 500 | H21: 0 | I21: 0 | J21: 0 | L21: =100-I21 -> 100
A22: 2 | B22: =C9*(ROUND(RAND()*0.08+0.07,3))+ROUND(RAND(),1)+B21 -> 577.5 | C22: =C9-B22 -> 422.5 | D22: =C22/C9*100 -> 42.25
B23: 负责人： 日期：
A26: 结
B29: 监理工程师： 日期：
A31: 论

Sheet 含水量
A1: 含 水 量 试 验 | J1: 盒重控制区（以下位置请勿动）
F2: 编号：C—1— | H2: =报告!E2 -> J02- 0039
A3: 施工单位 | B3: =报告!B3 -> 中铁六局呼铁局建设有限公司 | E3: 合 同 号 | G3: =报告!E3 -> 02
A4: 监理单位 | B4: =报告!B4 -> 内蒙古广誉建设监理有限责任公司
A5: 试样名称 | B5: =报告!B5 -> 土 | E5: 试验规程 | G5: =报告!E5 -> JTJ 051-93
A6: 试样来源 | B6: =报告!B6 -> K3+600挖方段 | E6: 试验日期 | G6: =报告!E6 -> 2007.11.1
A7: 试 验 人 | E7: 审 核 人
A9: 桩号或部位 | B9: =B6 -> K3+600挖方段
A10: 盒 号 | B10: =C30 -> 15 | C10: =C31 -> 4
A11: 盒+湿土质量（g） | B11: =B12+B14 -> 195.7815 | C11: =C12+C14 -> 178.57086
A12: 盒+干土质量（g） | B12: =B15+B14 -> 186.08062 | C12: =C15+C14 -> 168.86246
A13: 盒质量（g） | B13: =D30 -> 17 | C13: =D31 -> 16.7
A14: 水份质量（g） | B14: =0.01*B16*B15 -> 9.7008852 | C14: =0.01*C16*C15 -> 9.7083978
A15: 干土质量（g） | B15: =RAND()*11+167 -> 176.37973 | C15: =RAND()*11+158.62 -> 159.15406
A16: 含水量（%） | B16: =IF(D16<=0.3,B17-D16,B17+D16) -> 5.5 | C16: =IF(D16<=0.3,B17+D16,B17-D16) -> 6.1 | D16: =ROUND(RAND()*0.5,1) -> 0.3
A17: 平均含水量（%） | B17: =ROUND(RAND()+RAND()*10/10+5.5,1) -> 5.8
A18: 结 论 | B18: 负责人： 日期：
B21: 监理工程师： 日期：
A24: 盒重控制区（以下位置请勿动）
A29: 盒号 | B29: 质量 | C29: 选择 | D29: 实际质量
A30: 1 | B30: =铝盒!B3 -> 18.4 | C30: =INT(RAND()*30)+1 -> 15 | D30: =INDIRECT(ADDRESS(29+C30,2)) -> 17
A31: 2 | B31: =铝盒!B4 -> 18.6 | C31: =INT(RAND()*30)+1 -> 4 | D31: =INDIRECT(ADDRESS(29+C31,2)) -> 16.7
A32: 3 | B32: =铝盒!B5 -> 16.5 | C32: =INT(RAND()*30)+1 -> 26 | D32: =INDIRECT(ADDRESS(29+C32,2)) -> 20.5
A33: 4 | B33: =铝盒!B6 -> 16.7 | C33: =INT(RAND()*30)+1 -> 18 | D33: =INDIRECT(ADDRESS(29+C33,2)) -> 18.2
A34: 5 | B34: =铝盒!B7 -> 16 | C34: =INT(RAND()*30)+1 -> 22 | D34: =INDIRECT(ADDRESS(29+C34,2)) -> 17.5
A35: 6 | B35: =铝盒!B8 -> 16.2 | C35: =INT(RAND()*30)+1 -> 7 | D35: =INDIRECT(ADDRESS(29+C35,2)) -> 18.2
A36: 7 | B36: =铝盒!B9 -> 18.2 | C36: =INT(RAND()*30)+1 -> 15 | D36: =INDIRECT(ADDRESS(29+C36,2)) -> 17
A37: 8 | B37: =铝盒!B10 -> 19.9 | C37: =INT(RAND()*30)+1 -> 8 | D37: =INDIRECT(ADDRESS(29+C37,2)) -> 19.9
A38: 9 | B38: =铝盒!B11 -> 16.6 | C38: =INT(RAND()*30)+1 -> 2 | D38: =INDIRECT(ADDRESS(29+C38,2)) -> 18.6
A39: 10 | B39: =铝盒!B12 -> 21.1 | C39: =INT(RAND()*30)+1 -> 23 | D39: =INDIRECT(ADDRESS(29+C39,2)) -> 16.8
A40: 11 | B40: =铝盒!B13 -> 16.7 | C40: =INT(RAND()*30)+1 -> 24 | D40: =INDIRECT(ADDRESS(29+C40,2)) -> 20.1
A41: 12 | B41: =铝盒!B14 -> 17.6 | C41: =INT(RAND()*30)+1 -> 19 | D41: =INDIRECT(ADDRESS(29+C41,2)) -> 23.5
... A59: 30 | B59: =铝盒!B32 -> 17.4 | C59: =INT(RAND()*30)+1 -> 22 | D59: =INDIRECT(ADDRESS(29+C59,2)) -> 17.5

Sheet 击实
A6: 击 实 试 验 记 录 表
I7: 编号：C-6- | K7: =报告!E2 -> J02- 0039
A8: 施工单位 | B8: =报告!B3 -> 中铁六局呼铁局建设有限公司 | H8: 合同号 | J8: =报告!E3 -> 02
A9: 监理单位 | B9: =报告!B4 -> 内蒙古广誉建设监理有限责任公司 | N9: 4155
A10: 样品名称 | B10: =报告!B5 -> 土 | H10: 试验规程 | J10: =报告!E5 -> JTJ 051-93 | N10: =C27 -> 7.1214729 | O10: =C28 -> 1.78
A11: 样品来源 | B11: =报告!B6 -> K3+600挖方段 | H11: 试验日期 | J11: =报告!E6 -> 2007.11.1 | N11: =E27 -> 9.294025 | O11: =E28 -> 1.84
A12: 试验人 | H12: 审核人 | N12: =G27 -> 11 | O12: =G28 -> 1.89
A13: 击 实 方 法 | C13: 重型II法 | F13: 筒容积: | H13: 2177 | J13: >5mm颗粒含量 | L13: 0 | N13: =I27 -> 13.069972 | O13: =I28 -> 1.86
A14: 预加含水量 (%) | C14: =INT(C27) -> 7 | E14: =C14+2 -> 9 | G14: =E14+2 -> 11 | I14: =G14+2 -> 13 | K14: =I14+2 -> 15 | N14: =K27 -> 15.212274 | O14: =K28 -> 1.82
A15: 筒 号 | M15: 0 | N15: =J29 -> 11 | O15: =J29 -> 11
A16: 筒+湿土质量 (g) | C16: =C17+C18 -> 8306.0213 | E16: =E17+E18 -> 8532.9689 | G16: =G17+G18 -> 8722.1283 | I16: =I17+I18 -> 8733.4519 | K16: =K17+K18 -> 8719.8716 | M16: =C29 -> 1.89 | N16: =C29 -> 1.89 | O16: 0
A17: 筒质量 (g) | C17: =N9 -> 4155 | E17: =C17 -> 4155 | G17: =E17 -> 4155 | I17: =G17 -> 4155 | K17: =I17 -> 4155
A18: 湿土质量 (g) | C18: =H13*C19 -> 4151.0213 | E18: =H13*E19 -> 4377.9689 | G18: =H13*G19 -> 4567.1283 | I18: =H13*I19 -> 4578.4519 | K18: =H13*K19 -> 4564.8716
A19: 湿 密 度 (g/cm3) | C19: =C28*(1+C27*0.01) -> 1.9067622 | E19: =E28*(1+E27*0.01) -> 2.0110101 | G19: =G28*(1+G27*0.01) -> 2.0979 | I19: =I28*(1+I27*0.01) -> 2.1031015 | K19: =K28*(1+K27*0.01) -> 2.0968634
A20: 盒 号 | C20: =含水量!C32 -> 26 | D20: =含水量!C33 -> 18 | E20: =含水量!C34 -> 22 | F20: =含水量!C35 -> 7 | G20: =含水量!C36 -> 15 | H20: =含水量!C37 -> 8 | I20: =含水量!C38 -> 2 | J20: =含水量!C39 -> 23 | K20: =含水量!C40 -> 24 | L20: =含水量!C41 -> 19
A21: 盒+湿土质量 (g) | C21: =C22+C24 -> 59.654643 | D21: =D22+D24 -> 57.23282 | E21: =E22+E24 -> 52.7878 | F21: =F22+F24 -> 54.537204 | G21: =G22+G24 -> 57.22343 | H21: =H22+H24 -> 61.7847 | I21: =I22+I24 -> 66.197175 | J21: =J22+J24 -> 61.929302 | ... L21: =L22+L24 -> 64.966294
A22: 盒+干土质量 (g) | C22: =C23+C25 -> 57.12 | D22: =D23+D25 -> 54.57 | E22: =E23+E25 -> 49.64 | F22: =F23+F25 -> 51.6 | G22: =G23+G25 -> 53.27 | H22: =H23+H25 -> 57.6 | I22: =I23+I25 -> 60.51 | J22: =J23+J25 -> 56.89 | ... L22: =L23+L25 -> 59.46
A23: 盒 质 量 (g) | C23: =含水量!D32 -> 20.5 | D23: =含水量!D33 -> 18.2 | E23: =含水量!D34 -> 17.5 | F23: =含水量!D35 -> 18.2 | G23: =含水量!D36 -> 17 | H23: =含水量!D37 -> 19.9 | I23: =含水量!D38 -> 18.6 | J23: =含水量!D39 -> 16.8 | K23: =含水量!D40 -> 20.1 | L23: =含水量!D41 -> 23.5
A24: 水 份 质 量 (g) | C24: =C26*0.01*C25 -> 2.5346434 | D24: =D26*0.01*D25 -> 2.6628197 | E24: =E26*0.01*E25 -> 3.1477996 | F24: =F26*0.01*F25 -> 2.9372043 | G24: =G26*0.01*G25 -> 3.95343 | H24: =H26*0.01*H25 -> 4.1847 | I24: =I26*0.01*I25 -> 5.6871752 | J24: =J26*0.01*J25 -> 5.0393017 | ... L24: =L26*0.01*L25 -> 5.5062936
A25: 干 土 质 量 (g) | C25: =ROUND(RAND()+35.92,2) -> 36.62 | D25: =ROUND(RAND()+36.28,2) -> 36.37 | E25: =ROUND(RAND()+31.44,2) -> 32.14 | F25: =ROUND(RAND()+32.88,2) -> 33.4 | G25: =ROUND(RAND()+35.92,2) -> 36.27 | H25: =ROUND(RAND()+37.14,2) -> 37.7 | I25: =ROUND(RAND()+40.92,2) -> 41.91 | J25: =ROUND(RAND()+40,2) -> 40.09 | K25: =ROUND(RAND()+35.92,2) -> 36.91 | L25: =ROUND(RAND()+35.92,2) -> 35.96
A26: 含 水 量 (%) | C26: =IF(M26<0.3,(C27-M26),(C27+M26)) -> 6.9214729 | D26: =IF(M26<0.3,(C27+M26),(C27-M26)) -> 7.3214729 | E26: =IF(O26<0.3,(E27-O26),(E27+O26)) -> 9.794025 | F26: =IF(O26<0.3,(E27+O26),(E27-O26)) -> 8.794025 | G26: =IF(Q26<0.3,(G27-Q26),(G27+Q26)) -> 10.9 | H26: =IF(Q26<0.3,(G27+Q26),(G27-Q26)) -> 11.1 | I26: =IF(S26<0.3,(I27-S26),(I27+S26)) -> 13.569972 | J26: =IF(S26<0.3,(I27+S26),(I27-S26)) -> 12.569972 | K26: =IF(U26<0.3,(K27-U26),(K27+U26)) -> 15.112274 | L26: =IF(U26<0.3,(K27+U26),(K27-U26)) -> 15.312274 | M26: =ROUND(RAND()*0.5,1) -> 0.2 | N26: =ROUND(RAND()*0.5,1) -> 0.5 | O26: =ROUND(RAND()*0.5,1) -> 0.5 | P26: =ROUND(RAND()*0.5,1) -> 0.3 | Q26: =ROUND(RAND()*0.5,1) -> 0.1 | R26: =ROUND(RAND()*0.5,1) -> 0.2 | S26: =ROUND(RAND()*0.5,1) -> 0.5 | T26: =ROUND(RAND()*0.5,1) -> 0.5 | U26: =ROUND(RAND()*0.5,1) -> 0.1
A27: 平均含水量 （%） | C27: =RAND()+(G27-4.1) -> 7.1214729 | E27: =RAND()+(G27-2.1) -> 9.294025 | G27: =J29 -> 11 | I27: =RAND()+(G27+1.9) -> 13.069972 | K27: =RAND()+(G27+3.9) -> 15.212274
A28: 干 密 度 (g/cm3) | C28: =G28-M28*2-0.01 -> 1.78 | E28: =G28-M28 -> 1.84 | G28: =C29 -> 1.89 | I28: =G28-N28 -> 1.86 | K28: =G28-N28*2-0.01 -> 1.82 | M28: =ROUND(RAND()*0.02+0.03,2) -> 0.05 | N28: =ROUND(RAND()*0.02+0.03,2) -> 0.03
A29: 最大干密度(g/cm3) | C29: =报告!E19 -> 1.89 | G29: 最佳含水量(%) | J29: =报告!C19 -> 11
A30: 击实曲线图
P35: 29 | Q35: 17.3
P36: 30 | Q36: 17.4
A49: 结论 | B49: 负责人： 日期：
B52: 监理工程师： 日期：

Sheet 液塑限
A1: 土的界限含水量试验 (液塑限联合测定)
I2: 编号: | J2: C-4- | K2: =报告!E2 -> J02- 0039
A3: 施 工 单 位 | C3: =报告!B3 -> 中铁六局呼铁局建设有限公司 | G3: 合 同 号 | J3: =报告!E3 -> 02 | N3: =C20 -> 15.9 | O3: =G20 -> 27.9 | P3: =EXP(LN(O3)-(LN(O4)-LN(P4))*(LN(N3)-LN(O3))/(LN(N4)-LN(O4))) -> 18.450872 | Q3: =EXP(LN(O3)-(LN(O4)-LN(1))*(LN(N3)-LN(O3))/(LN(N4)-LN(O4))) -> 8.5699196 | S3: =K18 -> 28.3 | T3: 0 | V3: =K19 -> 18.995098 | W3: =0 -> 0
A4: 监 理 单 位 | C4: =报告!B4 -> 内蒙古广誉建设监理有限责任公司 | N4: =C12 -> 4.8 | O4: =G12 -> 20 | P4: =N33 -> 7.0023513 | Q4: 1 | S4: =20 -> 20 | T4: 20 | V4: =N33 -> 7.0023513 | W4: =N33 -> 7.0023513
A5: 样 品 名 称 | C5: =报告!B5 -> 土 | G5: 试 验 规 程 | J5: =报告!E5 -> JTJ 051-93 | N5: =E20 -> 22.2 | O5: =G20 -> 27.9 | P5: =EXP(LN(O5)-(LN(O6)-LN(P6))*(LN(N5)-LN(O5))/(LN(N6)-LN(O6))) -> 19.539325 | Q5: =EXP(LN(O5)-(LN(O6)-LN(1))*(LN(N5)-LN(O5))/(LN(N6)-LN(O6))) -> 10.093277 | S5: =K18 -> 28.3 | T5: =K18 -> 28.3 | V5: =K19 -> 18.995098 | W5: =K19 -> 18.995098
A6: 样 品 来 源 | C6: =报告!B6 -> K3+600挖方段 | G6: 试 验 日 期 | J6: =报告!E6 -> 2007.11.1 | N6: =E12 -> 10.2 | O6: =G12 -> 20 | P6: =N33 -> 7.0023513 | Q6: 1 | S6: =20 -> 20 | T6: 0 | V6: =N33 -> 7.0023513 | W6: 0
A7: 试 验 人 | G7: 审 核 人
C9: 1 | E9: 2 | G9: 3
A10: 入土深度 (mm) | B10: h1 | C10: =IF(C25<=0.3,C12-C25,C12+C25) -> 4.6 | E10: =IF(E25<=0.3,E12-E25,E12+E25) -> 10.1 | G10: 20.2
B11: h2 | C11: =IF(C25<=0.3,C12+C25,C12-C25) -> 5 | E11: =IF(E25<=0.3,E12+E25,E12-E25) -> 10.3 | G11: 19.8
B12: 1/2（h1+h2） | C12: 4.8 | E12: 10.2 | G12: =IF(ABS(G10-G11)<=0.5,ROUND((G10+G11)/2,1),"误差大于0.5") -> 20
A13: 含 水 量 (%) | B13: 盒 号 | C13: =INT(RAND()*29)+1 -> 25 | D13: =INT(RAND()*29)+1 -> 11 | E13: =INT(RAND()*29)+1 -> 5 | F13: =INT(RAND()*29)+1 -> 24 | G13: =INT(RAND()*29)+1 -> 20 | H13: =INT(RAND()*29)+1 -> 14
B14: 盒+湿土质量(g) | C14: =C15+C17 -> 32.373196 | D14: =D15+D17 -> 36.298792 | E14: =E15+E17 -> 35.644796 | F14: =F15+F17 -> 46.448623 | G14: =G15+G17 -> 41.079946 | H14: =H15+H17 -> 44.64393
B15: 盒+干土质量(g) | C15: =C16+C18 -> 30.283196 | D15: =D16+D18 -> 33.578792 | E15: =E16+E18 -> 32.114796 | F15: =F16+F18 -> 41.608623 | G15: =G16+G18 -> 36.529946 | H15: =H16+H18 -> 38.89393
B16: 盒 质 量(g) | C16: =INDEX($B$26:$B$65535,C13,1) -> 17 | D16: =INDEX($B$26:$B$65535,D13,1) -> 16.7 | E16: =INDEX($B$26:$B$65535,E13,1) -> 16 | F16: =INDEX($B$26:$B$65535,F13,1) -> 20.1 | G16: =INDEX($B$26:$B$65535,G13,1) -> 20.5 | H16: =INDEX($B$26:$B$65535,H13,1) -> 17.9 | M16: 土类 | N16: 沙土
B17: 水分质量(g) | C17: =ROUND(C19*0.01*C18,2) -> 2.09 | D17: =ROUND(D19*0.01*D18,2) -> 2.72 | E17: =ROUND(E19*0.01*E18,2) -> 3.53 | F17: =ROUND(F19*0.01*F18,2) -> 4.84 | G17: =ROUND(G19*0.01*G18,2) -> 4.55 | H17: =ROUND(H19*0.01*H18,2) -> 5.75 | M17: 系数 | N17: -5.42
B18: 干土质量(g) | C18: =RAND()*10+12.5 -> 13.283196 | D18: =RAND()*10+12.5 -> 16.878792 | E18: =RAND()*10+12.5 -> 16.114796 | F18: =RAND()*10+12.5 -> 21.508623 | G18: =RAND()*10+12.5 -> 16.029946 | H18: =RAND()*10+12.5 -> 20.99393 | I18: 液限W1= | K18: =ROUND(N32,1) -> 28.3 | M18: =EXP(LN(C20)+(LN(20)-LN(C12))*(LN(C20)-LN(M19))/(LN(C12)-LN(P6))) -> 29.350573
B19: 含 水 量(%) | C19: =IF(C24<=0.3,(C20-C24),(C20+C24)) -> 15.7 | D19: =IF(C24<=0.3,(C20+C24),(C20-C24)) -> 16.1 | E19: =IF(E24<=0.3,(E20-E24),(E20+E24)) -> 21.9 | F19: =IF(E24<=0.3,(E20+E24),(E20-E24)) -> 22.5 | G19: =IF(G24<=0.3,(G20-G24),(G20+G24)) -> 28.4 | H19: =IF(G24<=0.3,(G20+G24),(G20-G24)) -> 27.4 | I19: 塑限W2= | K19: =AVERAGEA(P5,P3) -> 18.995098 | M19: =ROUND(N36,1) -> 18.7
B20: 平均含水量(%) | C20: 15.9 | E20: 22.2 | G20: 27.9 | I20: 塑性指数IP= | K20: =ROUND((K18-K19),1) -> 9.3 | M20: =ROUND((M18-M19),1) -> 10.7
A21: 结 论 | C21: 负责人: 日期:
C22: 监理工程师: 日期:
C24: =ROUND(RAND()*0.5,1) -> 0.2 | D24: =ROUND(RAND()*0.5,1) -> 0.1 | E24: =ROUND(RAND()*0.5,1) -> 0.3 | F24: =ROUND(RAND()*0.5,1) -> 0.2 | G24: =ROUND(RAND()*0.5,1) -> 0.5 | H24: =ROUND(RAND()*0.5,1) -> 0.5 | O24: c | P24: b | Q24: a
A25: 盒号 | B25: 质量(g) | C25: =ROUND(RAND()*0.25,1) -> 0.2 | E25: =ROUND(RAND()*0.25,1) -> 0.1 | G25: =ROUND(RAND()*0.25,1) -> 0.1 | N25: 入土深对数 | O25: =LN(C12) -> 1.5686159 | P25: =LN(E12) -> 2.3223877 | Q25: =LN(G12) -> 2.9957323
A26: 1 | B26: 18.4 | N26: 含水量对数 | O26: =LN(C20) -> 2.7663191 | P26: =LN(E20) -> 3.1000923 | Q26: =LN(G20) -> 3.3286267
A27: 2 | B27: 18.6 | N27: A= | O27: =LINEST(O25:Q25,O26:Q26,TRUE) -> 2.5174934 | P27: 填写
A28: 3 | B28: 16.5
A29: 4 | B29: 16.7 | N29: B= | O29: =N17 -> -5.42 | P29: 填写
A30: 5 | B30: 16 | N30: Y= | O30: =O27 -> 2.5174934 | P30: X | Q30: =O29 -> -5.42
A31: 6 | B31: 16.2 | M31: 液限的对数 | N31: =(LN(20)-O29)/O27 -> 3.3429014
A32: 7 | B32: 18.2 | M32: 液限 | N32: =EXP(N31) -> 28.30112
A33: 8 | B33: 19.9 | M33: hP | N33: =IF(N16="沙土",29.6-1.22*N32+0.017*N32*N32-0.0000744*N32*N32*N32,C19/(0.524*N32-7.606)) -> 7.0023513
A34: 9 | B34: 16.6 | M34: hP的对数 | N34: =LN(N33) -> 1.946246
A35: 10 | B35: 21.1 | M35: 塑限的对数 | N35: =(N34-O29)/O27 -> 2.9260239
A36: 11 | B36: 16.7 | M36: 塑限 | N36: =EXP(N35) -> 18.653315
A37: 12 | B37: 17.6
A38: 13 | B38: 17
A39: 14 | B39: 17.9
A40: 15 | B40: 17
A41: 16 | B41: 20.5
A42: 17 | B42: 21.1
...

Sheet 累计曲线
A1: 颗粒分析试验记录（筛分法）
H2: 编号：C—3—1— | I2: =报告!E2 -> J02- 0039
A3: 施工单位 | B3: =报告!B3 -> 中铁六局呼铁局建设有限公司 | G3: 合 同 号 | I3: =报告!E3 -> 02
A4: 监理单位 | B4: =报告!B4 -> 内蒙古广誉建设监理有限责任公司
A5: 试样名称 | B5: =报告!B5 -> 土 | G5: 试验规程 | I5: =报告!E5 -> JTJ 051-93
A6: 试样来源 | B6: =报告!B6 -> K3+600挖方段 | G6: 试验日期 | I6: =报告!E6 -> 2007.11.1
A7: 试 验 人 | G7: 审 核 人
A9: 筛前总土质量= | C9: 1000 | D9: g | G9: 小于2mm土取试样质量= | I9: 500 | J9: g
A10: 小于2mm土质量= | C10: =C21 -> 1000 | D10: g | E10: 小于2mm土占试样总质量的 | I10: =D21 -> 100 | J10: %
A11: 粗筛分析 | F11: 细筛分析
A12: 筛孔尺寸（mm） | B12: 累积留筛土质量（g） | C12: 通过该 | D12: 通过该 | E12: 筛孔尺寸（mm） | G12: 累积留筛土质量（g） | H12: 通过该孔径的土质量（g） | I12: 通过该 | J12: 占总土质量百分比（%） | M12: =A16 -> 60 | N12: =100-D16 -> 0
C13: 孔径的 | D13: 孔土质 | I13: 孔径土 | M13: =A17 -> 40 | N13: =100-D17 -> 0
C14: 土质量 | D14: 量百分 | I14: 质量百 | M14: =A18 -> 20 | N14: =100-D18 -> 0
C15: （g） | D15: 比（%） | I15: 分比（%） | M15: =A19 -> 10 | N15: =100-D19 -> 0
A16: 60 | C16: =C9-B16 -> 1000 | D16: =C16/C9*100 -> 100 | E16: 2 | G16: 0 | H16: =I9-G16 -> 500 | I16: =H16/I9*100 -> 100 | J16: =I16*I10*0.01 -> 100 | L16: =100-I16 -> 0 | M16: =A20 -> 5 | N16: =100-D20 -> 0
A17: 40 | C17: =C9-B17 -> 1000 | D17: =C17/C9*100 -> 100 | E17: 1 | G17: 14 | H17: =I9-G17 -> 486 | I17: =H17/I9*100 -> 97.2 | J17: =I17*I10/100 -> 97.2 | L17: =100-I17 -> 2.8 | M17: =A21 -> 2 | N17: =100-D21 -> 0
A18: 20 | C18: =C9-B18 -> 1000 | D18: =C18/C9*100 -> 100 | E18: 0.5 | G18: 63 | H18: =I9-G18 -> 437 | I18: =H18/I9*100 -> 87.4 | J18: =I18*I10*0.01 -> 87.4 | L18: =100-I18 -> 12.6 | M18: =E17 -> 1 | N18: =100-J17 -> 2.8
A19: 10 | C19: =C9-B19 -> 1000 | D19: =C19/C9*100 -> 100 | E19: 0.25 | G19: 95.4 | H19: =I9-G19 -> 404.6 | I19: =H19/I9*100 -> 80.92 | J19: =I19*I10*0.01 -> 80.92 | L19: =100-I19 -> 19.08 | M19: =E18 -> 0.5 | N19: =100-J18 -> 12.6
A20: 5 | C20: =C9-B20 -> 1000 | D20: =C20/C9*100 -> 100 | E20: 0.074 | G20: 353.5 | H20: =I9-G20 -> 146.5 | I20: =H20/I9*100 -> 29.3 | J20: =I20*I10*0.01 -> 29.3 | L20: =100-I20 -> 70.7 | M20: =E19 -> 0.25 | N20: =100-J19 -> 19.08
A21: 2 | C21: =C9-B21 -> 1000 | D21: =C21/C9*100 -> 100 | E21: <0.074 | G21: 497.5 | H21: 0 | I21: 0 | J21: 0 | L21: =100-I21 -> 100 | M21: =E20 -> 0.074 | N21: =100-J20 -> 70.7
M22: =E21 -> <0.074 | N22: =100-J21 -> 100
A26: 结 论 | B26: 负责人： 日期：
B27: 监理工程师： 日期：

Sheet 膨胀率
A1: 自由膨胀率试验记录
A2: 编号: C-3-1- - -
A3: 施工单位 | D3: =报告!B3 -> 中铁六局呼铁局建设有限公司 | G3: 合 同 号 | I3: =报告!E3
A4: 监理单位 | D4: =报告!B4 -> 内蒙古广誉建设监理有限责任公司
A5: 样品名称 | D5: =报告!B5 -> 土 | G5: 试 验 规 程 | I5: =报告!E5 -> JTJ 051-93
A6: 样品来源 | D6: =报告!B6 -> K3+600挖方段 | G6: 试 验 日 期 | I6: =报告!E6 -> 2007.11.1
A7: 试 验 人 | G7: 审 核 人
A9: 土样 编号 | B9: 干土质量 (g) | C9: 量筒 编号 | D9: 不同时间(h)体积读数(cm3) | I9: 自由膨胀率(%)
D10: 2 | E10: 4 | F10: 6 | G10: 8 | H10: 10 | I10: Fs | J10: 平均值
A11: 1 | B11: 9.04 | C11: 1 | D11: 11.7 | E11: 11.7 | F11: 11.7 | G11: 11.7 | H11: 11.7 | I11: =(H11-10)*100/10 -> 17 | J11: =(I11+I12)/2 -> 16
B12: 9.07 | C12: 2 | D12: 11.5 | E12: 11.5 | F12: 11.5 | G12: 11.5 | H12: 11.5 | I12: =(H12-10)*100/10 -> 15
A13: 2
A15: 3
A17: 4
A19: 结 论 | C19: 负责人： 日期:
C20: 监理工程师： 日期:

Sheet 环刀压实度
A1: 压实度检测记录表（环刀法）
A2: 施工单位： | B2: =报告!B3 -> 中铁六局呼铁局建设有限公司 | E2: 合 同 号： | I2: 请勿修改
A3: 监理单位： | B3: =报告!B4 -> 内蒙古广誉建设监理有限责任公司 | E3: 土场位置：
A4: 距路基顶面： | E4: 最大干容重(g/cm3)： | G4: 2
A5: 检测范围： | E5: 最佳含水量（%）：
A6: 检查日期： | E6: 试验规程： JTJ 051-93 | I6: 请勿修改
D7: 编号：C-2-1-□□□-□□□□
I9: 请勿修改
A10: 环刀号 | B10: =D32 -> 11 | D10: =D33 -> 16 | F10: =D34 -> 1
A11: 环刀容积（cm3） | B11: =E32 -> 199.21574 | D11: =E33 -> 202.39068 | F11: =E34 -> 198.76992
A12: 环刀重量（g） | B12: =F32 -> 168.5 | D12: =F33 -> 166.2 | F12: =F34 -> 170.2 | I12: 请勿修改
A13: 土+环刀重（g） | B13: =B14+B12 -> 539.48478 | D13: =D14+D12 -> 542.66297 | F13: =F14+F12 -> 535.47696
A14: 土重（g） | B14: =B15*B11 -> 370.98478 | D14: =D15*D11 -> 376.46297 | F14: =F15*F11 -> 365.27696
A15: 湿容重（g/cm3） | B15: =B24*(1+0.01*B23) -> 1.8622262 | D15: =D24*(1+0.01*D23) -> 1.8600806 | F15: =F24*(1+0.01*F23) -> 1.8376873 | I15: 请勿修改
A16: 盒 号 | B16: =含水量!C42 -> 24 | C16: =含水量!C43 -> 25 | D16: =含水量!C44 -> 28 | E16: =含水量!C45 -> 25 | F16: =含水量!C46 -> 21 | G16: =含水量!C47 -> 10
A17: 盒+湿土重（g） | B17: =B18+B19 -> 70.56073 | C17: =C18+C19 -> 62.717026 | D17: =D18+D19 -> 75.331555 | E17: =E18+E19 -> 65.372031 | F17: =F18+F19 -> 66.39979 | G17: =G18+G19 -> 68.236482
A18: 盒+干土重（g） | B18: =B21+B20 -> 70.259771 | C18: =C21+C20 -> 62.44436 | D18: =D21+D20 -> 75.180713 | E18: =E21+E20 -> 65.323707 | F18: =F21+F20 -> 66.548436 | G18: =G21+G20 -> 68.378317 | I18: 请勿修改
A19: 水重（g） | B19: =B22*0.01*B21 -> 0.30095863 | C19: =C22*0.01*C21 -> 0.27266616 | D19: =D22*0.01*D21 -> 0.15084214 | E19: =E22*0.01*E21 -> 0.048323707 | F19: =F22*0.01*F21 -> -0.14864531 | G19: =G22*0.01*G21 -> -0.14183495
A20: 盒重（g） | B20: =含水量!D42 -> 20.1 | C20: =含水量!D43 -> 17 | D20: =含水量!D44 -> 24.9 | E20: =含水量!D45 -> 17 | F20: =含水量!D46 -> 17 | G20: =含水量!D47 -> 21.1
A21: 干土重（g） | B21: =RAND()*10+46.87 -> 50.159771 | C21: =RAND()*10+41.87 -> 45.44436 | D21: =RAND()*10+46.87 -> 50.280713 | E21: =RAND()*10+41.87 -> 48.323707 | F21: =RAND()*10+46.87 -> 49.548436 | G21: =RAND()*10+41.87 -> 47.278317 | I21: 请勿修改
A22: 含水量（%） | B22: =G6+ROUND(RAND()/2,1)*2-0.2 -> 0.6 | C22: =G6+ROUND(RAND()/2,1)*2-0.2 -> 0.6 | D22: =G6+ROUND(RAND()/2,1)*2-0.3 -> 0.3 | E22: =G6+ROUND(RAND()/2,1)*2-0.3 -> 0.1 | F22: =G6+ROUND(RAND()/2,1)*2-0.5 -> -0.3 | G22: =G6+ROUND(RAND()/2,1)*2-0.5 -> -0.3
A23: 平均含水量（%） | B23: =IF(ABS(B22-C22)<=1,ROUND((B22+C22)/2,1),"混蛋") -> 0.6 | D23: =IF(ABS(D22-E22)<=1,ROUND((D22+E22)/2,1),"混蛋") -> 0.2 | F23: =IF(ABS(F22-G22)<=1,ROUND((F22+G22)/2,1),"混蛋") -> -0.3
A24: 干容重（g/cm3） | B24: =B25*0.01*G4 -> 1.8511195 | D24: =D25*0.01*G4 -> 1.8563678 | F24: =F25*0.01*G4 -> 1.843217 | I24: 请勿修改
A25: 压实度（%） | B25: =RAND()+92.1 -> 92.555976 | D25: =RAND()+92.1 -> 92.818391 | F25: =RAND()+92.1 -> 92.160848
A26: 结论 | B26: 负责人： 日期：
B27: 监理工程师： 日期： | I27: 请勿修改
A28: 试验： | B28: 记录（计算）： | E28: 复核：
A30: 请勿修改 | C30: 请勿修改 | E30: 请勿修改 | H30: 请勿修改
A31: 环刀号 | B31: 容积 | C31: 质量
A32: 1 | B32: =环刀!N3 -> 198.76992 | C32: =环刀!O3 -> 170.2 | D32: =INT(RAND()*27+1) -> 11 | E32: =INDIRECT(ADDRESS(31+D32,2)) -> 199.21574 | F32: =INDIRECT(ADDRESS(31+D32,3)) -> 168.5
A33: 2 | B33: =环刀!N4 -> 199.37694 | C33: =环刀!O4 -> 144.4 | D33: =INT(RAND()*27+1) -> 16 | E33: =INDIRECT(ADDRESS(31+D33,2)) -> 202.39068 | F33: =INDIRECT(ADDRESS(31+D33,3)) -> 166.2
A34: 3 | B34: =环刀!N5 -> 199.20568 | C34: =环刀!O5 -> 167.5 | D34: =INT(RAND()*27+1) -> 1 | E34: =INDIRECT(ADDRESS(31+D34,2)) -> 198.76992 | F34: =INDIRECT(ADDRESS(31+D34,3)) -> 170.2
A35: 4 | B35: =环刀!N6 -> 197.80262 | C35: =环刀!O6 -> 190.1 | D35: =INT(RAND()*27+1) -> 8 | E35: =INDIRECT(ADDRESS(31+D35,2)) -> 199.824 | F35: =INDIRECT(ADDRESS(31+D35,3)) -> 174
A36: 5 | B36: =环刀!N7 -> 198.40785 | C36: =环刀!O7 -> 171.8 | D36: =INT(RAND()*27+1) -> 1 | E36: =INDIRECT(ADDRESS(31+D36,2)) -> 198.76992 | F36: =INDIRECT(ADDRESS(31+D36,3)) -> 170.2
A37: 6 | B37: =环刀!N8 -> 202.13897 | C37: =环刀!O8 -> 171.8 | D37: =INT(RAND()*27+1) -> 5 | E37: =INDIRECT(ADDRESS(31+D37,2)) -> 198.40785 | F37: =INDIRECT(ADDRESS(31+D37,3)) -> 171.8
A38: 7 | B38: =环刀!N9 -> 197.05353 | C38: =环刀!O9 -> 171.9 | D38: =INT(RAND()*27+1) -> 22 | E38: =INDIRECT(ADDRESS(31+D38,2)) -> 201.89982 | F38: =INDIRECT(ADDRESS(31+D38,3)) -> 171.7
A39: 8 | B39: =环刀!N10 -> 199.824 | C39: =环刀!O10 -> 174 | D39: =INT(RAND()*27+1) -> 17 | E39: =INDIRECT(ADDRESS(31+D39,2)) -> 199.40538 | F39: =INDIRECT(ADDRESS(31+D39,3)) -> 168.2
A40: 9 | B40: =环刀!N11 -> 198.74956 | C40: =环刀!O11 -> 227.7 | D40: =INT(RAND()*27+1) -> 7 | E40: =INDIRECT(ADDRESS(31+D40,2)) -> 197.05353 | F40: =INDIRECT(ADDRESS(31+D40,3)) -> 171.9
A41: 10 | B41: =环刀!N12 -> 198.1625 | C41: =环刀!O12 -> 175 | D41: =INT(RAND()*27+1) -> 15 | E41: =INDIRECT(ADDRESS(31+D41,2)) -> 205.36908 | F41: =INDIRECT(ADDRESS(31+D41,3)) -> 170.4
A42: 11 | B42: =环刀!N13 -> 199.21574 | C42: =环刀!O13 -> 168.5 | D42: =INT(RAND()*27+1) -> 8 | E42: =INDIRECT(ADDRESS(31+D42,2)) -> 199.824 | F42: =INDIRECT(ADDRESS(31+D42,3)) -> 174
...

Sheet 灌砂压实度 (2)
A1: 压实度检测记录表（灌砂法）
E2: 编号：C-2-1-S01-
A3: 施工单位: | B3: 中国第二冶金建设有限公司 | E3: 合 同 号： 01
A4: 监理单位： | B4: 内蒙古广誉建设监理有限责任公司 | E4: 试 验 规 程 ： JTJ 051-93
A5: 要求K值∶ | B5: 93 | C5: 区第五层 | E5: 距路基顶面高差 ∶ | G5: m
A6: 检查日期： | E6: 最大干容重(g/cm3)： | G6: 1.91
A7: 检测范围： | E7: 最佳含水量 （%）： | G7: 9.6
A8: 锥体砂重： | B8: 736 | D8: (g) | E8: 砂单位重 (g/cm3)： | G8: 1.4
B9: K8+150左 | D9: K8+170左 | F9: K8+190左
A10: 灌前筒+砂重（g） | B10: 9000 | D10: 9000 | F10: 9000
A11: 灌后筒+砂重（g） | B11: =ROUND(RAND()*1111+4253,0) -> 4641 | D11: =ROUND(RAND()*1111+4253,0) -> 4940 | F11: =ROUND(RAND()*1111+4253,0) -> 4376
A12: 坑内砂重（g） | B12: =B10-B11-B8 -> 3623 | D12: =D10-D11-B8 -> 3324 | F12: =F10-F11-B8 -> 3888
A13: 试坑体积（cm3) | B13: =B12/G8 -> 2587.8571 | D13: =D12/G8 -> 2374.2857 | F13: =F12/G8 -> 2777.1429
A14: 坑内土重（g） | B14: =B15*B13 -> 5157.1076 | D14: =D15*D13 -> 4792.4482 | F14: =F15*F13 -> 5519.2382
A15: 湿容重（g/cm3） | B15: =B24*(1+0.01*B23) -> 1.99281 | D15: =D24*(1+0.01*D23) -> 2.01848 | F15: =F24*(1+0.01*F23) -> 1.98738
A16: 盒 号 | B16: =含水量!C30 -> 15 | C16: =含水量!C31 -> 4 | D16: =含水量!C32 -> 26 | E16: =含水量!C33 -> 18 | F16: =含水量!C34 -> 22 | G16: =含水量!C35 -> 7
A17: 盒+湿土重（g） | B17: =B18+B19 -> 70.64828 | C17: =C18+C19 -> 56.95184 | D17: =D18+D19 -> 72.58556 | E17: =E18+E19 -> 74.37737 | F17: =F18+F19 -> 69.14676 | G17: =G18+G19 -> 64.89651
A18: 盒+干土重（g） | B18: =B20+B21 -> 65.86 | C18: =C20+C21 -> 53.16 | D18: =D20+D21 -> 67.98 | E18: =E20+E21 -> 69.41 | F18: =F20+F21 -> 64.58 | G18: =G20+G21 -> 60.69
A19: 水重（g） | B19: =B22*B21/100 -> 4.78828 | C19: =C22*C21/100 -> 3.79184 | D19: =D22*D21/100 -> 4.60556 | E19: =E22*E21/100 -> 4.96737 | F19: =F22*F21/100 -> 4.56676 | G19: =G22*G21/100 -> 4.20651
A20: 盒重（g） | B20: =含水量!D30 -> 17 | C20: =含水量!D31 -> 16.7 | D20: =含水量!D32 -> 20.5 | E20: =含水量!D33 -> 18.2 | F20: =含水量!D34 -> 17.5 | G20: =含水量!D35 -> 18.2
A21: 干土重（g） | B21: =ROUND(RAND()*22+35,2) -> 48.86 | C21: =ROUND(RAND()*22+35,2) -> 36.46 | D21: =ROUND(RAND()*22+35,2) -> 47.48 | E21: =ROUND(RAND()*22+35,2) -> 51.21 | F21: =ROUND(RAND()*22+35,2) -> 47.08 | G21: =ROUND(RAND()*22+35,2) -> 42.49
A22: 含水量（%） | B22: =G7+ROUND(RAND()/2,1)*2-0.2 -> 9.8 | C22: =G7+ROUND(RAND()/2,1)*2-0.2 -> 10.4 | D22: =G7+ROUND(RAND()/2,1)*2-0.3 -> 9.7 | E22: =G7+ROUND(RAND()/2,1)*2-0.3 -> 9.7 | F22: =G7+ROUND(RAND()/2,1)*2-0.5 -> 9.7 | G22: =G7+ROUND(RAND()/2,1)*2-0.5 -> 9.9
A23: 平均含水量（%） | B23: =(B22+C22)/2 -> 10.1 | D23: =(D22+E22)/2 -> 9.7 | F23: =(F22+G22)/2 -> 9.8
A24: 干容重（g/cm3） | B24: =ROUND(B5*0.01*G6+RAND()*0.06,2)+0.01 -> 1.81 | D24: =ROUND(B5*0.01*G6+RAND()*0.06,2)+0.01 -> 1.84 | F24: =ROUND(B5*0.01*G6+RAND()*0.06,2)+0.01 -> 1.81
A25: 压实度（%） | B25: =ROUND(B24*100/G6,1) -> 94.8 | D25: =ROUND(D24*100/G6,1) -> 96.3 | F25: =ROUND(F24*100/G6,1) -> 94.8
A26: 结论 | B26: 负责人： 日期：
B27: 监理工程师： 日期：
A29: 试验： | B29: 记录（计算）： | E29: 复核：

Sheet 灌砂
A1: 盐池至中宁高速公路 | Q1: 1 | S1: 2 | U1: 3 | W1: 4 | Y1: 5
A2: 压实度试验(灌砂法)记录 | Q2: =RAND()+15 -> 15.691143 | S2: =RAND()+15 -> 15.359291 | U2: =RAND()+15 -> 15.000789 | W2: =RAND()+15 -> 15.742664 | Y2: =RAND()+15 -> 15.453195
A3: 合同段：LQ02 试验编号: | Q3: =D10 -> 9000 | S3: =G10 -> 9000 | U3: =I10 -> 9000 | W3: =L10 -> 9000 | Y3: =O10 -> 9000
A4: 工程名称 | C4: 盐中高速公路 | H4: 试验单位 | L4: 黑龙江北方有色建设有限责任公司 | Q4: =Q3-Q5-Q6 -> 4886.8734 | S4: =S3-S5-S6 -> 4957.5772 | U4: =U3-U5-U6 -> 5033.959 | W4: =W3-W5-W6 -> 4875.8963 | Y4: =Y3-Y5-Y6 -> 4937.57
A5: 试验规程 | C5: JTJ059-(T0921-95) | H5: 试验日期 | L5: 2007.3.23 | Q5: =D12 -> 770 | S5: =G12 -> 770 | U5: =I12 -> 770 | W5: =L12 -> 770 | Y5: =O12 -> 770
A6: 起讫桩号 | C6: YK3+680~YK3+860右幅 | Q6: =Q9*1.38 -> 3343.1266 | S6: =S9*1.38 -> 3272.4228 | U6: =U9*1.38 -> 3196.041 | W6: =W9*1.38 -> 3354.1037 | Y6: =Y9*1.38 -> 3292.43
A7: 结构层次 | C7: 填前碾压 | G7: 最佳含水量% | I7: 11.1 | L7: 要求压实度% | O7: 90 | Q7: 1.38 | S7: 1.38 | U7: 1.38 | W7: 1.38 | Y7: 1.38
A8: 取样位置 | D8: YK3+860左 | G8: YK3+840右 | I8: YK3+820左 | L8: YK3+780左 | O8: YK3+760右 | Q8: =Q9*Q10 -> 4580.6925 | S8: =S9*S10 -> 4499.7441 | U8: =U9*U10 -> 4429.0413 | W8: =W9*W10 -> 4560.0078 | Y8: =Y9*Y10 -> 4523.9751
A9: 试洞深度（cm） | D9: =Q2 -> 15.691143 | G9: =S2 -> 15.359291 | I9: =U2 -> 15.000789 | L9: =W2 -> 15.742664 | O9: =Y2 -> 15.453195 | Q9: =Q2*154.39 -> 2422.5555 | S9: =S2*154.39 -> 2371.3209 | U9: =U2*154.39 -> 2315.9718 | W9: =W2*154.39 -> 2430.5099 | Y9: =Y2*154.39 -> 2385.8188
A10: 灌砂前筒+砂重（g） | D10: 9000 | G10: 9000 | I10: 9000 | L10: 9000 | O10: 9000 | Q10: =Q19*(1+Q18*0.01) -> 1.8908514 | S10: =S19*(1+S18*0.01) -> 1.8975686 | U10: =U19*(1+U18*0.01) -> 1.91239 | W10: =W19*(1+W18*0.01) -> 1.8761527 | Y10: =Y19*(1+Y18*0.01) -> 1.8961939
A11: 灌砂后筒+砂重（g） | D11: =Q4 -> 4886.8734 | G11: =S4 -> 4957.5772 | I11: =U4 -> 5033.959 | L11: =W4 -> 4875.8963 | O11: =Y4 -> 4937.57 | Q11: =D18 -> 1 | R11: =F18 -> 2 | S11: =G18 -> 3 | T11: =H18 -> 4 | U11: =I18 -> 5 | V11: =J18 -> 6 | W11: =L18 -> 7 | X11: =M18 -> 8 | Y11: =O18 -> 9 | Z11: =P18 -> 10
A12: 锥体砂重（g） | D12: 770 | G12: =D12 -> 770 | I12: =D12 -> 770 | L12: =D12 -> 770 | O12: =D12 -> 770 | Q12: =D19 -> 50 | R12: =F19 -> 50 | S12: =G19 -> 50 | T12: =H19 -> 50 | U12: =I19 -> 50 | V12: =J19 -> 50 | W12: =L19 -> 50 | X12: =M19 -> 50 | Y12: =O19 -> 50 | Z12: =P19 -> 50
A13: 灌入试洞内砂重（g） | D13: =Q6 -> 3343.1266 | G13: =S6 -> 3272.4228 | I13: =U6 -> 3196.041 | L13: =W6 -> 3354.1037 | O13: =Y6 -> 3292.43 | Q13: =Q14+Q15 -> 156.636 | R13: =R14+R15 -> 155.39099 | S13: =S14+S15 -> 150.31922 | T13: =T14+T15 -> 152.83583 | U13: =U14+U15 -> 152.01174 | V13: =V14+V15 -> 156.5765 | W13: =W14+W15 -> 151.86144 | X13: =X14+X15 -> 156.53918 | ... Z13: =Z14+Z15 -> 156.5146
A14: 标准砂密度（g/cm3） | D14: 1.38 | G14: 1.38 | I14: 1.38 | L14: 1.38 | O14: 1.38 | Q14: =Q16+Q12 -> 146.42374 | R14: =R16+R12 -> 145.11829 | S14: =S16+R12 -> 141.19195 | T14: =T16+S12 -> 143.38762 | U14: =U16+T12 -> 142.30602 | V14: =V16+U12 -> 146.26417 | W14: =W16+V12 -> 142.10458 | X14: =X16+W12 -> 146.23086 | Y14: =Y16+W12 -> 142.96102 | Z14: =Z16+X12 -> 146.04489
A15: 试样质量（g） | D15: =Q8 -> 4580.6925 | G15: =S8 -> 4499.7441 | I15: =U8 -> 4429.0413 | L15: =W8 -> 4560.0078 | O15: =Y8 -> 4523.9751 | Q15: =Q16*Q17/100 -> 10.212262 | R15: =R16*R17/100 -> 10.272697 | S15: =S16*S17/100 -> 9.1272675 | T15: =T16*T17/100 -> 9.4482186 | U15: =U16*U17/100 -> 9.7057168 | V15: =V16*V17/100 -> 10.312329 | W15: =W16*W17/100 -> 9.7568525 | X15: =X16*X17/100 -> 10.308327 | ... Z15: =Z16*Z17/100 -> 10.469717
A16: 试洞体积（cm3） | D16: =Q9 -> 2422.5555 | G16: =S9 -> 2371.3209 | I16: =U9 -> 2315.9718 | L16: =W9 -> 2430.5099 | O16: =Y9 -> 2385.8188 | Q16: =RAND()*7.31+90.6 -> 96.423736 | R16: =RAND()*7.31+90.6 -> 95.118289 | S16: =RAND()*7.31+90.6 -> 91.191951 | T16: =RAND()*7.31+90.6 -> 93.387616 | U16: =RAND()*7.31+90.6 -> 92.306023 | V16: =RAND()*7.31+90.6 -> 96.264171 | W16: =RAND()*7.31+90.6 -> 92.104583 | X16: =RAND()*7.31+90.6 -> 96.230858 | ... Z16: =RAND()*7.31+90.6 -> 96.044888
A17: 湿密度（g/cm3） | D17: =Q10 -> 1.8908514 | G17: =S10 -> 1.8975686 | I17: =U10 -> 1.91239 | L17: =W10 -> 1.8761527 | O17: =Y10 -> 1.8961939 | Q17: =RAND()*1+10 -> 10.591025 | R17: =RAND()*1+10 -> 10.799917 | S17: =RAND()*1+10 -> 10.008852 | T17: =RAND()*1+10 -> 10.117207 | U17: =RAND()*1+10 -> 10.514717 | V17: =RAND()*1+10 -> 10.712531 | W17: =RAND()*1+10 -> 10.593232 | X17: =RAND()*1+10 -> 10.71208 | ... Z17: =RAND()*1+10 -> 10.900858
A18: 盒号 | D18: 1 | F18: 2 | G18: 3 | H18: 4 | I18: 5 | J18: 6 | L18: 7 | M18: 8 | O18: 9 | P18: 10 | Q18: =(Q17+R17)/2 -> 10.695471 | S18: =(S17+T17)/2 -> 10.06303 | U18: =(U17+V17)/2 -> 10.613624 | W18: =(W17+X17)/2 -> 10.652656 | Y18: =(Y17+Z17)/2 -> 10.823015
A19: 盒重（g） | D19: 50 | F19: 50 | G19: 50 | H19: 50 | I19: 50 | J19: 50 | L19: 50 | M19: 50 | O19: 50 | P19: 50 | Q19: =Q20*Q21/100 -> 1.7081561 | S19: =S20*S21/100 -> 1.7240745 | U19: =U20*U21/100 -> 1.7288919 | W19: =W20*W21/100 -> 1.6955334 | Y19: =Y20*Y21/100 -> 1.7110109
A20: 盒+湿样重（g） | D20: =Q13 -> 156.636 | F20: =R13 -> 155.39099 | G20: =S13 -> 150.31922 | H20: =T13 -> 152.83583 | I20: =U13 -> 152.01174 | J20: =V13 -> 156.5765 | L20: =W13 -> 151.86144 | M20: =X13 -> 156.53918 | O20: =Y13 -> 152.94984 | P20: =Z13 -> 156.5146 | Q20: 1.86 | S20: 1.86 | U20: 1.86 | W20: 1.86 | Y20: 1.86
A21: 盒+干样重（g） | D21: =Q14 -> 146.42374 | F21: =R14 -> 145.11829 | G21: =S14 -> 141.19195 | H21: =T14 -> 143.38762 | I21: =U14 -> 142.30602 | J21: =V14 -> 146.26417 | L21: =W14 -> 142.10458 | M21: =X14 -> 146.23086 | O21: =Y14 -> 142.96102 | P21: =Z14 -> 146.04489 | Q21: =D28 -> 91.836348 | S21: =G28 -> 92.692178 | U21: =I28 -> 92.951179 | W21: =L28 -> 91.157708 | Y21: =O28 -> 91.989836
A22: 水分重（g） | D22: =Q15 -> 10.212262 | F22: =R15 -> 10.272697 | G22: =S15 -> 9.1272675 | H22: =T15 -> 9.4482186 | I22: =U15 -> 9.7057168 | J22: =V15 -> 10.312329 | L22: =W15 -> 9.7568525 | M22: =X15 -> 10.308327 | O22: =Y15 -> 9.9888214 | P22: =Z15 -> 10.469717
A23: 干样重（g） | D23: =Q16 -> 96.423736 | F23: =R16 -> 95.118289 | G23: =S16 -> 91.191951 | H23: =T16 -> 93.387616 | I23: =U16 -> 92.306023 | J23: =V16 -> 96.264171 | L23: =W16 -> 92.104583 | M23: =X16 -> 96.230858 | O23: =Y16 -> 92.961016 | P23: =Z16 -> 96.044888
A24: 含水量（%） | D24: =Q17 -> 10.591025 | F24: =R17 -> 10.799917 | G24: =S17 -> 10.008852 | H24: =T17 -> 10.117207 | I24: =U17 -> 10.514717 | J24: =V17 -> 10.712531 | L24: =W17 -> 10.593232 | M24: =X17 -> 10.71208 | O24: =Y17 -> 10.745172 | P24: =Z17 -> 10.900858
A25: 平均含水量（%） | D25: =Q18 -> 10.695471 | G25: =S18 -> 10.06303 | I25: =U18 -> 10.613624 | L25: =W18 -> 10.652656 | O25: =Y18 -> 10.823015
A26: 干密度（g/cm3） | D26: =Q19 -> 1.7081561 | G26: =S19 -> 1.7240745 | I26: =U19 -> 1.7288919 | L26: =W19 -> 1.6955334 | O26: =Y19 -> 1.7110109
A27: 最大干密度（g/cm3） | D27: =Q20 -> 1.86 | G27: =S20 -> 1.86 | I27: =U20 -> 1.86 | L27: =W20 -> 1.86 | O27: =Y20 -> 1.86
A28: 压实度（%） | D28: =RAND()*2.2+91 -> 91.836348 | G28: =RAND()*2.2+91 -> 92.692178 | I28: =RAND()*2.2+91 -> 92.951179 | L28: =RAND()*2.2+91 -> 91.157708 | O28: =RAND()*2.2+91 -> 91.989836
A29: 主 管 | F29: 复 核 | K29: 试 验
A30: 结论：
A34: 签名： 年 月 日
A35: 监理意见：
A39: 签名： 年 月 日

Sheet 铝盒
A1: 铝盒盒号及对应质量
A2: 盒号 | B2: 质量(g) | D2: 盒号 | E2: 质量(g) | G2: 大盒号 | H2: 质量(g)
A3: 1 | B3: 18.4 | D3: 07 | E3: 16.9 | G3: 1 | H3: 51.3
A4: 2 | B4: 18.6 | D4: 41 | E4: 27.3 | G4: 2 | H4: 51.7
A5: 3 | B5: 16.5 | D5: 42 | E5: 20.9 | G5: 3 | H5: 52.1
A6: 4 | B6: 16.7 | D6: 81 | E6: 20.2 | G6: 4 | H6: 51.4
A7: 5 | B7: 16 | D7: 110 | E7: 17.9 | G7: 5 | H7: 52.7
A8: 6 | B8: 16.2 | D8: 013 | E8: 18.2 | G8: 6 | H8: 51.7
A9: 7 | B9: 18.2 | D9: 025 | E9: 16 | G9: 7 | H9: 51.3
A10: 8 | B10: 19.9 | D10: 05 | E10: 18.8 | G10: 8 | H10: 55.1
A11: 9 | B11: 16.6 | D11: 31 | E11: 17.9 | G11: 9 | H11: 50.5
A12: 10 | B12: 21.1 | D12: 61 | E12: 20.5 | G12: 10 | H12: 51.9
A13: 11 | B13: 16.7 | D13: 110 | E13: 24
A14: 12 | B14: 17.6 | D14: 190 | E14: 16
A15: 13 | B15: 17 | D15: 012 | E15: 21.4
A16: 14 | B16: 17.9 | D16: 019 | E16: 16.8
A17: 15 | B17: 17 | D17: 02 | E17: 19.8 | G17: 方盒号 | H17: 质量(g)
A18: 16 | B18: 20.5 | D18: 03 | E18: 22.9 | G18: 1 | H18: 124
A19: 17 | B19: 21.1 | D19: 062 | E19: 17.6 | G19: 2 | H19: 114.3
A20: 18 | B20: 18.2 | D20: 08 | E20: 19.7 | G20: 3 | H20: 141.3
A21: 19 | B21: 23.5 | D21: 09 | E21: 21 | G21: 4 | H21: 116
A22: 20 | B22: 20.5 | D22: 112 | E22: 16 | G22: 5 | H22: 122
A23: 21 | B23: 17 | G23: 6 | H23: 130
A24: 22 | B24: 17.5
A25: 23 | B25: 16.8
A26: 24 | B26: 20.1
A27: 25 | B27: 17
A28: 26 | B28: 20.5
A29: 27 | B29: 16.4
A30: 28 | B30: 24.9
A31: 29 | B31: 17.3
A32: 30 | B32: 17.4

Sheet 环刀
A1: 环刀编号及容积(mm,mm2)
A2: 环刀号 | B2: 上内径1 | C2: 上内径2 | D2: 平均内径 | E2: 上口面积 | F2: 下内径1 | G2: 下内径2 | H2: 平均内径 | I2: 下口面积 | J2: 平均面积 | K2: 高1 | L2: 高2 | M2: 平均高 | N2: 容积(cm3) | O2: 环刀质量(g)
A3: 1 | B3: 69.62 | C3: 69.66 | D3: =(B3+C3)/2 -> 69.64 | E3: =D3*D3/4*3.1415926 -> 3808.9687 | F3: 69.82 | G3: 69.82 | H3: =(F3+G3)/2 -> 69.82 | I3: =H3*H3/4*3.1415926 -> 3828.6843 | J3: =(E3+I3)/2 -> 3818.8265 | K3: 52 | L3: 52.1 | M3: =(K3+L3)/2 -> 52.05 | N3: =J3*M3*0.001 -> 198.76992 | O3: 170.2
A4: 2 | B4: 69.86 | C4: 69.78 | D4: =(B4+C4)/2 -> 69.82 | E4: =D4*D4/4*3.1415926 -> 3828.6843 | F4: 69.88 | G4: 69.96 | H4: =(F4+G4)/2 -> 69.92 | I4: =H4*H4/4*3.1415926 -> 3839.6595 | J4: =(E4+I4)/2 -> 3834.1719 | K4: 52 | L4: 52 | M4: =(K4+L4)/2 -> 52 | N4: =J4*M4*0.001 -> 199.37694 | O4: 144.4
A5: 3 | B5: 69.8 | C5: 69.92 | D5: =(B5+C5)/2 -> 69.86 | E5: =D5*D5/4*3.1415926 -> 3833.0725 | F5: 70 | G5: 69.64 | H5: =(F5+G5)/2 -> 69.82 | I5: =H5*H5/4*3.1415926 -> 3828.6843 | J5: =(E5+I5)/2 -> 3830.8784 | K5: 52 | L5: 52 | M5: =(K5+L5)/2 -> 52 | N5: =J5*M5*0.001 -> 199.20568 | O5: 167.5
A6: 4 | B6: 69.64 | C6: 69.9 | D6: =(B6+C6)/2 -> 69.77 | E6: =D6*D6/4*3.1415926 -> 3823.2027 | F6: 69.68 | G6: 69.88 | H6: =(F6+G6)/2 -> 69.78 | I6: =H6*H6/4*3.1415926 -> 3824.2987 | J6: =(E6+I6)/2 -> 3823.7507 | K6: 51.78 | L6: 51.68 | M6: =(K6+L6)/2 -> 51.73 | N6: =J6*M6*0.001 -> 197.80262 | O6: 190.1
A7: 5 | B7: 69.52 | C7: 69.82 | D7: =(B7+C7)/2 -> 69.67 | E7: =D7*D7/4*3.1415926 -> 3812.2511 | F7: 69.7 | G7: 69.76 | H7: =(F7+G7)/2 -> 69.73 | I7: =H7*H7/4*3.1415926 -> 3818.8201 | J7: =(E7+I7)/2 -> 3815.5356 | K7: 52 | L7: 52 | M7: =(K7+L7)/2 -> 52 | N7: =J7*M7*0.001 -> 198.40785 | O7: 171.8
A8: 6 | B8: 70.2 | C8: 70.32 | D8: =(B8+C8)/2 -> 70.26 | E8: =D8*D8/4*3.1415926 -> 3877.0925 | F8: 70.26 | G8: 70.44 | H8: =(F8+G8)/2 -> 70.35 | I8: =H8*H8/4*3.1415926 -> 3887.0317 | J8: =(E8+I8)/2 -> 3882.0621 | K8: 52.02 | L8: 52.12 | M8: =(K8+L8)/2 -> 52.07 | N8: =J8*M8*0.001 -> 202.13897 | O8: 171.8
A9: 7 | B9: 69.52 | C9: 69.24 | D9: =(B9+C9)/2 -> 69.38 | E9: =D9*D9/4*3.1415926 -> 3780.5803 | F9: 69.62 | G9: 69.28 | H9: =(F9+G9)/2 -> 69.45 | I9: =H9*H9/4*3.1415926 -> 3788.2129 | J9: =(E9+I9)/2 -> 3784.3966 | K9: 52.08 | L9: 52.06 | M9: =(K9+L9)/2 -> 52.07 | N9: =J9*M9*0.001 -> 197.05353 | O9: 171.9
A10: 8 | B10: 69.86 | C10: 69.24 | D10: =(B10+C10)/2 -> 69.55 | E10: =D10*D10/4*3.1415926 -> 3799.1299 | F10: 69.22 | G10: 69.82 | H10: =(F10+G10)/2 -> 69.52 | I10: =H10*H10/4*3.1415926 -> 3795.8531 | J10: =(E10+I10)/2 -> 3797.4915 | K10: 52.62 | L10: 52.62 | M10: =(K10+L10)/2 -> 52.62 | N10: =J10*M10*0.001 -> 199.824 | O10: 174
A11: 9 | B11: 69.88 | C11: 69.62 | D11: =(B11+C11)/2 -> 69.75 | E11: =D11*D11/4*3.1415926 -> 3821.0111 | F11: 69.54 | G11: 70 | H11: =(F11+G11)/2 -> 69.77 | I11: =H11*H11/4*3.1415926 -> 3823.2027 | J11: =(E11+I11)/2 -> 3822.1069 | K11: 52 | L11: 52 | M11: =(K11+L11)/2 -> 52 | N11: =J11*M11*0.001 -> 198.74956 | O11: 227.7
A12: 10 | B12: 69.26 | C12: 69.68 | D12: =(B12+C12)/2 -> 69.47 | E12: =D12*D12/4*3.1415926 -> 3790.395 | F12: 69.52 | G12: 69.58 | H12: =(F12+G12)/2 -> 69.55 | I12: =H12*H12/4*3.1415926 -> 3799.1299 | J12: =(E12+I12)/2 -> 3794.7625 | K12: 52.22 | L12: 52.22 | M12: =(K12+L12)/2 -> 52.22 | N12: =J12*M12*0.001 -> 198.1625 | O12: 175
A13: 11 | B13: 69.62 | C13: 69.88 | D13: =(B13+C13)/2 -> 69.75 | E13: =D13*D13/4*3.1415926 -> 3821.0111 | F13: 69.92 | G13: 69.92 | H13: =(F13+G13)/2 -> 69.92 | I13: =H13*H13/4*3.1415926 -> 3839.6595 | J13: =(E13+I13)/2 -> 3830.3353 | K13: 52 | L13: 52.02 | M13: =(K13+L13)/2 -> 52.01 | N13: =J13*M13*0.001 -> 199.21574 | O13: 168.5
A14: 12 | B14: 70.72 | C14: 70.68 | D14: =(B14+C14)/2 -> 70.7 | E14: =D14*D14/4*3.1415926 -> 3925.8048 | F14: 70.82 | G14: 70.72 | H14: =(F14+G14)/2 -> 70.77 | I14: =H14*H14/4*3.1415926 -> 3933.5825 | J14: =(E14+I14)/2 -> 3929.6937 | K14: 52.12 | L14: 52.92 | M14: =(K14+L14)/2 -> 52.52 | N14: =J14*M14*0.001 -> 206.38751 | O14: 168.5
... A29: 27 | B29: 70.12 | C29: 70.22 | D29: =(B29+C29)/2 -> 70.17 | E29: =D29*D29/4*3.1415926 -> 3867.1661 | F29: 70.22 | G29: 70.12 | H29: =(F29+G29)/2 -> 70.17 | I29: =H29*H29/4*3.1415926 -> 3867.1661 | J29: =(E29+I29)/2 -> 3867.1661 | K29: 52.82 | L29: 52.82 | M29: =(K29+L29)/2 -> 52.82 | N29: =J29*M29*0.001 -> 204.26371 | O29: 169.4
