Workbook

Sheet 洛氏硬度报告
A1: 金属硬度试验检测报告 QB010504
A4: 试验室名称： | H4: 四川公路工程咨询监理公司 | AH4: 报告编号：
A7: 委托单位 | H7: 西藏天和工程建设有限公司 | AH7: 委托编号
A9: 工程名称 | H9: 国道317线岗托至江达公路整治改建工程病害整治工程 | AH9: 样品编号
A11: 工程部位/用途 | H11: 防护工程 | AH11: 盲样编号
A13: 见证单位 | H13: 甘肃鉄科建设工程咨询有限公司 | AH13: 样品名称 | AP13: 锚具
A15: 厂家产地 | H15: 成都市宏桥预应力有限公司 | AH15: 代表数量 | AP15: 68套
A17: 试验依据 | H17: GB/T 230.1-2009 | AH17: 送样日期 | AP17: 42502
A19: 判断依据 | H19: 委托方产品质量证明书 | AH19: 见证人 | AP19: 段正强、编号：401234
A21: 主要仪器 设备及编号 | H21: 洛氏硬度计372 | AH21: 样品描述 | AP21: 无锈蚀
A24: 技术要求 | H24: HRC17～35 | AP24: 规格型号 | AV24: YM15-8
A26: 试样编号 | H26: 外观 | N26: 洛氏硬度（ HRC ）实测值 | AP26: 单组评定 | AV26: 备注
N28: 1 | R28: 2 | V28: 3 | Z28: 4 | AD28: 5 | AH28: 6 | AL28: 平均
A30: 1 | H30: 无锈蚀 | N30: 22.5 | R30: 21.5 | V30: 23 | Z30: 21.5 | AD30: / | AH30: / | AL30: =AVERAGE(N30:AC31) -> 22.125 | AP30: 合格 | AV30: /
A32: / | H32: / | N32: / | R32: / | V32: / | Z32: / | AD32: / | AH32: / | AL32: / | AP32: / | AV32: /
A34: / | H34: / | N34: / | R34: / | V34: / | Z34: / | AD34: / | AH34: / | AL34: / | AP34: / | AV34: /
A36: / | H36: / | N36: / | R36: / | V36: / | Z36: / | AD36: / | AH36: / | AL36: / | AP36: / | AV36: /
A38: / | H38: / | N38: / | R38: / | V38: / | Z38: / | AD38: / | AH38: / | AL38: / | AP38: / | AV38: /
A40: / | H40: / | N40: / | R40: / | V40: / | Z40: / | AD40: / | AH40: / | AL40: / | AP40: / | AV40: /
A42: / | H42: / | N42: / | R42: / | V42: / | Z42: / | AD42: / | AH42: / | AL42: / | AP42: / | AV42: /
A44: / | H44: / | N44: / | R44: / | V44: / | Z44: / | AD44: / | AH44: / | AL44: / | AP44: / | AV44: /
A46: / | H46: / | N46: / | R46: / | V46: / | Z46: / | AD46: / | AH46: / | AL46: / | AP46: / | AV46: /
A48: / | H48: / | N48: / | R48: / | V48: / | Z48: / | AD48: / | AH48: / | AL48: / | AP48: / | AV48: /
A50: / | H50: / | N50: / | R50: / | V50: / | Z50: / | AD50: / | AH50: / | AL50: / | AP50: / | AV50: /
A52: / | H52: / | N52: / | R52: / | V52: / | Z52: / | AD52: / | AH52: / | AL52: / | AP52: / | AV52: /
A54: / | H54: / | N54: / | R54: / | V54: / | Z54: / | AD54: / | AH54: / | AL54: / | AP54: / | AV54: /
... A68: / | H68: / | N68: / | R68: / | V68: / | Z68: / | AD68: / | AH68: / | AL68: / | AP68: / | AV68: /
A70: 检测 结论 | E70: 该样品所检指标符合委托方产品质量证明书的技术要求。
A74: 备注 | E74: 批号：5101012016041201。
A77: 说明 | E77: 1.报告无试验人，审核人，签发人签字及未盖鲜章无效；2.报告涂改，换页及复印件未经我公司重新盖鲜章无效；3.本报告所涉及内容和结果仅对来样负责，若有意见或疑问应于收到报告之日起十日内向本公司提出，逾期未提出的，视为无异议。
A81: 地址：四川省成都市新津县工业区兴园8路397号 电话：82551093 传真：82551093 邮编：611430
A84: 试验： | L84: 审核： | X84: 签发： | AJ84: 日期： 年 月 日

Sheet 记录表
M1: 第 | P1: 页，共 | V1: 页
A2: QJ0508
A3: 金属洛氏硬度试验检测记录表
A4: 试验室名称： | D4: 四川金石工程试验检测有限公司 | I4: 记录编号:
A5: 工程部位/用途 | D5: 防护工程 | I5: 委托/任务编号
A6: 样品名称 | D6: 锚具 | I6: 样品编号
A7: 试验依据 | D7: GB/T 230.1-2009 | I7: 样品描述 | L7: 无锈蚀
A8: 试验条件 | D8: 21 | I8: 试验日期
A9: 主要仪器 设备及编号 | D9: 洛氏硬度计372
A10: 技术要求 | D10: HRC17-35 | M10: 规格型号 | S10: YM15-8
A11: 试件编号 | D11: 外观 | E11: 洛氏硬度( HRC ) | K11: 平均值 | M11: 单组评定 | S11: 备注
A12: 1 | D12: 无锈蚀 | E12: 30 | F12: 22.5 | G12: 21.5 | H12: 23 | I12: 21.5 | J12: / | K12: =AVERAGE(F12:I12) -> 22.125 | M12: 合格 | S12: /
A13: / | D13: / | E13: / | F13: / | G13: / | H13: / | I13: / | J13: / | K13: / | M13: / | S13: /
A14: / | D14: / | E14: / | F14: / | G14: / | H14: / | I14: / | J14: / | K14: / | M14: / | S14: /
A15: / | D15: / | E15: / | F15: / | G15: / | H15: / | I15: / | J15: / | K15: / | M15: / | S15: /
A16: / | D16: / | E16: / | F16: / | G16: / | H16: / | I16: / | J16: / | K16: / | M16: / | S16: /
A17: / | D17: / | E17: / | F17: / | G17: / | H17: / | I17: / | J17: / | K17: / | M17: / | S17: /
A18: / | D18: / | E18: / | F18: / | G18: / | H18: / | I18: / | J18: / | K18: / | M18: / | S18: /
A19: / | D19: / | E19: / | F19: / | G19: / | H19: / | I19: / | J19: / | K19: / | M19: / | S19: /
A20: / | D20: / | E20: / | F20: / | G20: / | H20: / | I20: / | J20: / | K20: / | M20: / | S20: /
A21: / | D21: / | E21: / | F21: / | G21: / | H21: / | I21: / | J21: / | K21: / | M21: / | S21: /
A22: / | D22: / | E22: / | F22: / | G22: / | H22: / | I22: / | J22: / | K22: / | M22: / | S22: /
A23: / | D23: / | E23: / | F23: / | G23: / | H23: / | I23: / | J23: / | K23: / | M23: / | S23: /
A24: / | D24: / | E24: / | F24: / | G24: / | H24: / | I24: / | J24: / | K24: / | M24: / | S24: /
... A28: / | D28: / | E28: / | F28: / | G28: / | H28: / | I28: / | J28: / | K28: / | M28: / | S28: /
A29: 备注:
A31: 试验： | E31: 复核： | J31: 日期： | O31: 年 | R31: 月 | U31: 日

Sheet 洛氏硬度报告 (2)
A1: 金属硬度试验检测报告 QB010504
A4: 试验室名称： | H4: 四川公路工程咨询监理公司 | AH4: 报告编号：
A7: 委托单位 | H7: 西藏天和工程建设有限公司 | AH7: 委托编号
A9: 工程名称 | H9: 国道317线岗托至江达公路整治改建工程病害整治工程 | AH9: 样品编号
A11: 工程部位/用途 | H11: 防护工程 | AH11: 盲样编号
A13: 见证单位 | H13: 甘肃鉄科建设工程咨询有限公司 | AH13: 样品名称 | AP13: 夹片
A15: 厂家产地 | H15: 成都市宏桥预应力有限公司 | AH15: 代表数量 | AP15: /
A17: 试验依据 | H17: GB/T 230.1-2009 | AH17: 送样日期 | AP17: 42502
A19: 判断依据 | H19: 委托方产品质量证明书 | AH19: 见证人 | AP19: 段正强、编号：401234
A21: 主要仪器 设备及编号 | H21: 洛氏硬度计372 | AH21: 样品描述 | AP21: 无锈蚀
A24: 技术要求 | H24: HRC57～65 | AP24: 规格型号 | AV24: 20CrMnTi
A26: 试样编号 | H26: 外观 | N26: 洛氏硬度（ HRC ）实测值 | AP26: 单组评定 | AV26: 备注
N28: 1 | R28: 2 | V28: 3 | Z28: 4 | AD28: 5 | AH28: 6 | AL28: 平均
A30: ='记录表 2'!A12:C12 -> 1 | H30: 无锈蚀 | N30: 59 | R30: 60 | V30: 60 | Z30: 63 | AD30: / | AH30: / | AL30: =AVERAGE(N30:AK31) -> 60.5 | AP30: 合格 | AV30: /
A32: ='记录表 2'!A13:C13 -> 2 | H32: 无锈蚀 | N32: 61.5 | R32: 60.5 | V32: 60 | Z32: 59.5 | AD32: / | AH32: / | AL32: =AVERAGE(N32:AK33) -> 60.375 | AP32: 合格 | AV32: /
A34: ='记录表 2'!A14:C14 -> 3 | H34: 无锈蚀 | N34: 60 | R34: 60 | V34: 63.5 | Z34: 63.5 | AD34: / | AH34: / | AL34: =AVERAGE(N34:AK35) -> 61.75 | AP34: 合格 | AV34: /
A36: ='记录表 2'!A15:C15 -> 4 | H36: 无锈蚀 | N36: 62.5 | R36: 64 | V36: 62.5 | Z36: 62 | AD36: / | AH36: / | AL36: =AVERAGE(N36:AK37) -> 62.75 | AP36: 合格 | AV36: /
A38: ='记录表 2'!A16:C16 -> 5 | H38: 无锈蚀 | N38: 60 | R38: 61.5 | V38: 59 | Z38: 64 | AD38: / | AH38: / | AL38: =AVERAGE(N38:AK39) -> 61.125 | AP38: 合格 | AV38: /
A40: ='记录表 2'!A17:C17 -> 6 | H40: 无锈蚀 | N40: 58.5 | R40: 61 | V40: 64 | Z40: 59.5 | AD40: / | AH40: / | AL40: =AVERAGE(N40:AK41) -> 60.75 | AP40: 合格 | AV40: /
A42: ='记录表 2'!A18:C18 -> 7 | H42: 无锈蚀 | N42: 63 | R42: 60 | V42: 60 | Z42: 57 | AD42: / | AH42: / | AL42: =AVERAGE(N42:AK43) -> 60 | AP42: 合格 | AV42: /
A44: ='记录表 2'!A19:C19 -> 8 | H44: 无锈蚀 | N44: 59 | R44: 59.5 | V44: 59.5 | Z44: 60 | AD44: / | AH44: / | AL44: =AVERAGE(N44:AK45) -> 59.5 | AP44: 合格 | AV44: /
A46: / | H46: / | N46: / | R46: / | V46: / | Z46: / | AD46: / | AH46: / | AL46: / | AP46: / | AV46: /
A48: / | H48: / | N48: / | R48: / | V48: / | Z48: / | AD48: / | AH48: / | AL48: / | AP48: / | AV48: /
A50: / | H50: / | N50: / | R50: / | V50: / | Z50: / | AD50: / | AH50: / | AL50: / | AP50: / | AV50: /
A52: / | H52: / | N52: / | R52: / | V52: / | Z52: / | AD52: / | AH52: / | AL52: / | AP52: / | AV52: /
A54: / | H54: / | N54: / | R54: / | V54: / | Z54: / | AD54: / | AH54: / | AL54: / | AP54: / | AV54: /
A56: / | H56: / | N56: / | R56: / | V56: / | Z56: / | AD56: / | AH56: / | AL56: / | AP56: / | AV56: /
A58: / | H58: / | N58: / | R58: / | V58: / | Z58: / | AD58: / | AH58: / | AL58: / | AP58: / | AV58: /
A60: / | H60: / | N60: / | R60: / | V60: / | Z60: / | AD60: / | AH60: / | AL60: / | AP60: / | AV60: /
A62: / | H62: / | N62: / | R62: / | V62: / | Z62: / | AD62: / | AH62: / | AL62: / | AP62: / | AV62: /
A64: / | H64: / | N64: / | R64: / | V64: / | Z64: / | AD64: / | AH64: / | AL64: / | AP64: / | AV64: /
A66: / | H66: / | N66: / | R66: / | V66: / | Z66: / | AD66: / | AH66: / | AL66: / | AP66: / | AV66: /
A68: / | H68: / | N68: / | R68: / | V68: / | Z68: / | AD68: / | AH68: / | AL68: / | AP68: / | AV68: /
A70: 检测 结论 | E70: 该样品所检指标符合委托方产品质量证明书的技术要求。
A74: 备注 | E74: /
A77: 说明 | E77: 1.报告无试验人，审核人，签发人签字及未盖鲜章无效；2.报告涂改，换页及复印件未经我公司重新盖鲜章无效；3.本报告所涉及内容和结果仅对来样负责，若有意见或疑问应于收到报告之日起十日内向本公司提出，逾期未提出的，视为无异议。
A81: 地址：四川省成都市新津县工业区兴园8路397号 电话：82551093 传真：82551093 邮编：611430
A84: 试验： | L84: 审核： | X84: 签发： | AJ84: 日期： 年 月 日

Sheet 洛氏硬度报告空白
A1: 金属硬度试验检测报告 QB010504
A4: 试验室名称： | H4: 四川公路工程咨询监理公司 | AH4: 报告编号：
A7: 委托单位 | AH7: 委托编号
A9: 工程名称 | AH9: 样品编号
A11: 工程部位/用途 | AH11: 盲样编号
A13: 见证单位 | AH13: 样品名称 | AP13: 锚具
A15: 厂家产地 | AH15: 代表数量
A17: 试验依据 | H17: GB/T 230.1-2009 | AH17: 送样日期
A19: 判断依据 | H19: 委托方产品质量证明书 | AH19: 见证人
A21: 主要仪器 设备及编号 | H21: 洛氏硬度计372 | AH21: 样品描述 | AP21: 无锈蚀
A24: 技术要求 | AP24: 规格型号
A26: 试样编号 | H26: 外观 | N26: 洛氏硬度（ ）实测值 | AP26: 单组评定 | AV26: 备注
N28: 1 | R28: 2 | V28: 3 | Z28: 4 | AD28: 5 | AH28: 6 | AL28: 平均
A44: / | H44: / | N44: / | R44: / | V44: / | Z44: / | AD44: / | AH44: / | AL44: / | AP44: / | AV44: /
A46: / | H46: / | N46: / | R46: / | V46: / | Z46: / | AD46: / | AH46: / | AL46: / | AP46: / | AV46: /
A48: / | H48: / | N48: / | R48: / | V48: / | Z48: / | AD48: / | AH48: / | AL48: / | AP48: / | AV48: /
A50: / | H50: / | N50: / | R50: / | V50: / | Z50: / | AD50: / | AH50: / | AL50: / | AP50: / | AV50: /
A52: / | H52: / | N52: / | R52: / | V52: / | Z52: / | AD52: / | AH52: / | AL52: / | AP52: / | AV52: /
A54: / | H54: / | N54: / | R54: / | V54: / | Z54: / | AD54: / | AH54: / | AL54: / | AP54: / | AV54: /
A56: / | H56: / | N56: / | R56: / | V56: / | Z56: / | AD56: / | AH56: / | AL56: / | AP56: / | AV56: /
A58: / | H58: / | N58: / | R58: / | V58: / | Z58: / | AD58: / | AH58: / | AL58: / | AP58: / | AV58: /
A60: / | H60: / | N60: / | R60: / | V60: / | Z60: / | AD60: / | AH60: / | AL60: / | AP60: / | AV60: /
A62: / | H62: / | N62: / | R62: / | V62: / | Z62: / | AD62: / | AH62: / | AL62: / | AP62: / | AV62: /
A64: / | H64: / | N64: / | R64: / | V64: / | Z64: / | AD64: / | AH64: / | AL64: / | AP64: / | AV64: /
A66: / | H66: / | N66: / | R66: / | V66: / | Z66: / | AD66: / | AH66: / | AL66: / | AP66: / | AV66: /
A68: / | H68: / | N68: / | R68: / | V68: / | Z68: / | AD68: / | AH68: / | AL68: / | AP68: / | AV68: /
A70: 检测 结论 | E70: 该样品所检指标符合委托方产品质量证明书的技术要求。
A74: 备注 | E74: 批号：5101012016041201。
A77: 说明 | E77: 1.报告无试验人，审核人，签发人签字及未盖鲜章无效；2.报告涂改，换页及复印件未经我公司重新盖鲜章无效；3.本报告所涉及内容和结果仅对来样负责，若有意见或疑问应于收到报告之日起十日内向本公司提出，逾期未提出的，视为无异议。
A81: 地址：四川省成都市新津县工业区兴园8路397号 电话：82551093 传真：82551093 邮编：611430
A84: 试验： | L84: 审核： | X84: 签发： | AJ84: 日期： 年 月 日

Sheet 记录表空白
M1: 第 | P1: 页，共 | V1: 页
A2: QJ0508
A3: 金属洛氏硬度试验检测记录表
A4: 试验室名称： | I4: 记录编号:
A5: 工程部位/用途 | I5: 委托/任务编号
A6: 样品名称 | I6: 样品编号
A7: 试验依据 | I7: 样品描述 | L7: 无锈蚀
A8: 试验条件 | I8: 试验日期
A9: 主要仪器 设备及编号
A10: 技术要求 | M10: 规格型号
A11: 试件编号 | D11: 外观 | E11: 洛氏硬度( HRC ) | K11: 平均值 | M11: 单组评定 | S11: 备注
A29: 备注:
A31: 试验： | E31: 复核： | J31: 日期： | O31: 年 | R31: 月 | U31: 日

Sheet 记录表 2
M1: 第 | P1: 页，共 | V1: 页
A2: QJ0508
A3: 金属洛氏硬度试验检测记录表
A4: 试验室名称： | I4: 记录编号:
A5: 工程部位/用途 | I5: 委托/任务编号
A6: 样品名称 | I6: 样品编号
A7: 试验依据 | I7: 样品描述
A8: 试验条件 | I8: 试验日期
A9: 主要仪器 设备及编号
A10: 技术要求 | M10: 规格型号
A11: 试件编号 | D11: 外观 | E11: 洛氏硬度( ) | K11: 平均值 | M11: 单组评定 | S11: 备注
A12: =记录夹片公式!A2 -> 1 | D12: 无锈蚀 | E12: =记录夹片公式!B2 -> 61 | F12: =记录夹片公式!C2 -> 62.5 | G12: =记录夹片公式!D2 -> 57.5 | H12: =记录夹片公式!E2 -> 60 | I12: =记录夹片公式!F2 -> 58 | J12: =记录夹片公式!G2 -> / | K12: =AVERAGE(F12:I12) -> 59.5 | M12: 合格 | S12: /
A13: =记录夹片公式!A4 -> 2 | D13: 无锈蚀 | E13: =记录夹片公式!B4 -> 64 | F13: =记录夹片公式!C4 -> 62 | G13: =记录夹片公式!D4 -> 63 | H13: =记录夹片公式!E4 -> 57.5 | I13: =记录夹片公式!F4 -> 58 | J13: =记录夹片公式!G4 -> / | K13: =AVERAGE(F13:I13) -> 60.125 | M13: 合格 | S13: /
A14: =记录夹片公式!A6 -> 3 | D14: 无锈蚀 | E14: =记录夹片公式!B6 -> 61.5 | F14: =记录夹片公式!C6 -> 59 | G14: =记录夹片公式!D6 -> 62.5 | H14: =记录夹片公式!E6 -> 58.5 | I14: =记录夹片公式!F6 -> 63.5 | J14: =记录夹片公式!G6 -> / | K14: =AVERAGE(F14:I14) -> 60.875 | M14: 合格 | S14: /
A15: =记录夹片公式!A8 -> 4 | D15: 无锈蚀 | E15: =记录夹片公式!B8 -> 57 | F15: =记录夹片公式!C8 -> 62.5 | G15: =记录夹片公式!D8 -> 62 | H15: =记录夹片公式!E8 -> 59.5 | I15: =记录夹片公式!F8 -> 59.5 | J15: =记录夹片公式!G8 -> / | K15: =AVERAGE(F15:I15) -> 60.875 | M15: 合格 | S15: /
A16: =记录夹片公式!A10 -> 5 | D16: 无锈蚀 | E16: =记录夹片公式!B10 -> 63 | F16: =记录夹片公式!C10 -> 57.5 | G16: =记录夹片公式!D10 -> 60 | H16: =记录夹片公式!E10 -> 63.5 | I16: =记录夹片公式!F10 -> 61 | J16: =记录夹片公式!G10 -> / | K16: =AVERAGE(F16:I16) -> 60.5 | M16: 合格 | S16: /
A17: =记录夹片公式!A12 -> 6 | D17: 无锈蚀 | E17: =记录夹片公式!B12 -> 58 | F17: =记录夹片公式!C12 -> 63 | G17: =记录夹片公式!D12 -> 60.5 | H17: =记录夹片公式!E12 -> 63.5 | I17: =记录夹片公式!F12 -> 60.5 | J17: =记录夹片公式!G12 -> / | K17: =AVERAGE(F17:I17) -> 61.875 | M17: 合格 | S17: /
A18: =记录夹片公式!A14 -> 7 | D18: 无锈蚀 | E18: =记录夹片公式!B14 -> 60 | F18: =记录夹片公式!C14 -> 60.5 | G18: =记录夹片公式!D14 -> 58 | H18: =记录夹片公式!E14 -> 61 | I18: =记录夹片公式!F14 -> 57 | J18: =记录夹片公式!G14 -> / | K18: =AVERAGE(F18:I18) -> 59.125 | M18: 合格 | S18: /
A19: =记录夹片公式!A16 -> 8 | D19: 无锈蚀 | E19: =记录夹片公式!B16 -> 63 | F19: =记录夹片公式!C16 -> 59.5 | G19: =记录夹片公式!D16 -> 63 | H19: =记录夹片公式!E16 -> 57.5 | I19: =记录夹片公式!F16 -> 64 | J19: =记录夹片公式!G16 -> / | K19: =AVERAGE(F19:I19) -> 61 | M19: 合格 | S19: /
A20: =记录夹片公式!A18 -> 9 | D20: 无锈蚀 | E20: =记录夹片公式!B18 -> 59 | F20: =记录夹片公式!C18 -> 61.5 | G20: =记录夹片公式!D18 -> 62.5 | H20: =记录夹片公式!E18 -> 57.5 | I20: =记录夹片公式!F18 -> 63 | J20: =记录夹片公式!G18 -> / | K20: =AVERAGE(F20:I20) -> 61.125 | M20: 合格 | S20: /
A21: =记录夹片公式!A20 -> 10 | D21: 无锈蚀 | E21: =记录夹片公式!B20 -> 61.5 | F21: =记录夹片公式!C20 -> 63.5 | G21: =记录夹片公式!D20 -> 57.5 | H21: =记录夹片公式!E20 -> 62 | I21: =记录夹片公式!F20 -> 61 | J21: =记录夹片公式!G20 -> / | K21: =AVERAGE(F21:I21) -> 61 | M21: 合格 | S21: /
A22: =记录夹片公式!A22 -> 11 | D22: 无锈蚀 | E22: =记录夹片公式!B22 -> 62 | F22: =记录夹片公式!C22 -> 61 | G22: =记录夹片公式!D22 -> 63 | H22: =记录夹片公式!E22 -> 60.5 | I22: =记录夹片公式!F22 -> 57 | J22: =记录夹片公式!G22 -> / | K22: =AVERAGE(F22:I22) -> 60.375 | M22: 合格 | S22: /
A23: =记录夹片公式!A24 -> 12 | D23: 无锈蚀 | E23: =记录夹片公式!B24 -> 62.5 | F23: =记录夹片公式!C24 -> 61.5 | G23: =记录夹片公式!D24 -> 63.5 | H23: =记录夹片公式!E24 -> 61.5 | I23: =记录夹片公式!F24 -> 61.5 | J23: =记录夹片公式!G24 -> / | K23: =AVERAGE(F23:I23) -> 62 | M23: 合格 | S23: /
A24: =记录夹片公式!A26 -> 13 | D24: 无锈蚀 | E24: =记录夹片公式!B26 -> 60 | F24: =记录夹片公式!C26 -> 61.5 | G24: =记录夹片公式!D26 -> 63.5 | H24: =记录夹片公式!E26 -> 57.5 | I24: =记录夹片公式!F26 -> 62.5 | J24: =记录夹片公式!G26 -> / | K24: =AVERAGE(F24:I24) -> 61.25 | M24: 合格 | S24: /
A25: =记录夹片公式!A28 -> 14 | D25: 无锈蚀 | E25: =记录夹片公式!B28 -> 63.5 | F25: =记录夹片公式!C28 -> 63.5 | G25: =记录夹片公式!D28 -> 63.5 | H25: =记录夹片公式!E28 -> 61 | I25: =记录夹片公式!F28 -> 62 | J25: =记录夹片公式!G28 -> / | K25: =AVERAGE(F25:I25) -> 62.5 | M25: 合格 | S25: /
A26: =记录夹片公式!A30 -> 15 | D26: 无锈蚀 | E26: =记录夹片公式!B30 -> 59.5 | F26: =记录夹片公式!C30 -> 58 | G26: =记录夹片公式!D30 -> 60 | H26: =记录夹片公式!E30 -> 59.5 | I26: =记录夹片公式!F30 -> 59.5 | J26: =记录夹片公式!G30 -> / | K26: =AVERAGE(F26:I26) -> 59.25 | M26: 合格 | S26: /
A27: =记录夹片公式!A32 -> 16 | D27: 无锈蚀 | E27: =记录夹片公式!B32 -> 60.5 | F27: =记录夹片公式!C32 -> 59.5 | G27: =记录夹片公式!D32 -> 60 | H27: =记录夹片公式!E32 -> 59.5 | I27: =记录夹片公式!F32 -> 57.5 | J27: =记录夹片公式!G32 -> / | K27: =AVERAGE(F27:I27) -> 59.125 | M27: 合格 | S27: /
A28: =记录夹片公式!A34 -> 17 | D28: 无锈蚀 | E28: =记录夹片公式!B34 -> 61 | F28: =记录夹片公式!C34 -> 63.5 | G28: =记录夹片公式!D34 -> 59.5 | H28: =记录夹片公式!E34 -> 63.5 | I28: =记录夹片公式!F34 -> 57.5 | J28: =记录夹片公式!G34 -> / | K28: =AVERAGE(F28:I28) -> 61 | M28: 合格 | S28: /
A29: 备注:
A31: 试验： | E31: 复核： | J31: 日期： | O31: 年 | R31: 月 | U31: 日

Sheet 记录夹片公式
B1: =ROUND(RAND()*(64-57)+57,1) -> 61.1 | C1: =ROUND(RAND()*(64-57)+57,1) -> 62.7 | D1: =ROUND(RAND()*(64-57)+57,1) -> 57.3 | E1: =ROUND(RAND()*(64-57)+57,1) -> 60.2 | F1: =ROUND(RAND()*(64-57)+57,1) -> 57.8 | J1: 56~66 | K1: 加几就是上线
A2: 1 | B2: =ROUND(B1*2,)/2 -> 61 | C2: =ROUND(C1*2,)/2 -> 62.5 | D2: =ROUND(D1*2,)/2 -> 57.5 | E2: =ROUND(E1*2,)/2 -> 60 | F2: =ROUND(F1*2,)/2 -> 58 | G2: / | I2: =AVERAGE(B2:E2) -> 60.25 | J2: =56+FLOOR(RAND()*10,0.5) -> 56.5 | L2: =56+FLOOR(RAND()*10,0.5) -> 57 | M2: =5+FLOOR(RAND()*2,0.2) -> 5.6
B3: =ROUND(RAND()*(64-57)+57,1) -> 63.9 | C3: =ROUND(RAND()*(64-57)+57,1) -> 61.9 | D3: =ROUND(RAND()*(64-57)+57,1) -> 63 | E3: =ROUND(RAND()*(64-57)+57,1) -> 57.4 | F3: =ROUND(RAND()*(64-57)+57,1) -> 58.2 | G3: / | J3: =56+FLOOR(RAND()*10,0.5) -> 60.5 | L3: =56+FLOOR(RAND()*10,0.5) -> 59 | M3: =5+FLOOR(RAND()*2,0.2) -> 6.6
A4: 2 | B4: =ROUND(B3*2,)/2 -> 64 | C4: =ROUND(C3*2,)/2 -> 62 | D4: =ROUND(D3*2,)/2 -> 63 | E4: =ROUND(E3*2,)/2 -> 57.5 | F4: =ROUND(F3*2,)/2 -> 58 | G4: / | I4: =AVERAGE(B4:E4) -> 61.625 | J4: =56+FLOOR(RAND()*10,0.5) -> 58 | L4: =56+FLOOR(RAND()*10,0.5) -> 64 | M4: =5+FLOOR(RAND()*2,0.2) -> 6.8
B5: =ROUND(RAND()*(64-57)+57,1) -> 61.7 | C5: =ROUND(RAND()*(64-57)+57,1) -> 58.9 | D5: =ROUND(RAND()*(64-57)+57,1) -> 62.6 | E5: =ROUND(RAND()*(64-57)+57,1) -> 58.4 | F5: =ROUND(RAND()*(64-57)+57,1) -> 63.7 | G5: / | J5: =56+FLOOR(RAND()*10,0.5) -> 56.5 | L5: =56+FLOOR(RAND()*10,0.5) -> 58.5 | M5: =5+FLOOR(RAND()*2,0.2) -> 6.2
A6: 3 | B6: =ROUND(B5*2,)/2 -> 61.5 | C6: =ROUND(C5*2,)/2 -> 59 | D6: =ROUND(D5*2,)/2 -> 62.5 | E6: =ROUND(E5*2,)/2 -> 58.5 | F6: =ROUND(F5*2,)/2 -> 63.5 | G6: / | I6: =AVERAGE(B6:E6) -> 60.375 | J6: =56+FLOOR(RAND()*10,0.5) -> 59 | L6: =56+FLOOR(RAND()*10,0.5) -> 65.5 | M6: =5+FLOOR(RAND()*2,0.2) -> 5.8
B7: =ROUND(RAND()*(64-57)+57,1) -> 57 | C7: =ROUND(RAND()*(64-57)+57,1) -> 62.4 | D7: =ROUND(RAND()*(64-57)+57,1) -> 62.1 | E7: =ROUND(RAND()*(64-57)+57,1) -> 59.7 | F7: =ROUND(RAND()*(64-57)+57,1) -> 59.6 | G7: / | J7: =56+FLOOR(RAND()*10,0.5) -> 64 | L7: =56+FLOOR(RAND()*10,0.5) -> 61 | M7: =5+FLOOR(RAND()*2,0.2) -> 5.2
A8: 4 | B8: =ROUND(B7*2,)/2 -> 57 | C8: =ROUND(C7*2,)/2 -> 62.5 | D8: =ROUND(D7*2,)/2 -> 62 | E8: =ROUND(E7*2,)/2 -> 59.5 | F8: =ROUND(F7*2,)/2 -> 59.5 | G8: / | I8: =AVERAGE(B8:E8) -> 60.25 | J8: =56+FLOOR(RAND()*10,0.5) -> 65 | L8: =56+FLOOR(RAND()*10,0.5) -> 64 | M8: =5+FLOOR(RAND()*2,0.2) -> 6.4
B9: =ROUND(RAND()*(64-57)+57,1) -> 62.8 | C9: =ROUND(RAND()*(64-57)+57,1) -> 57.6 | D9: =ROUND(RAND()*(64-57)+57,1) -> 59.8 | E9: =ROUND(RAND()*(64-57)+57,1) -> 63.5 | F9: =ROUND(RAND()*(64-57)+57,1) -> 60.9 | G9: / | J9: =56+FLOOR(RAND()*10,0.5) -> 64.5 | L9: =56+FLOOR(RAND()*10,0.5) -> 59.5 | M9: =5+FLOOR(RAND()*2,0.2) -> 5.6
A10: 5 | B10: =ROUND(B9*2,)/2 -> 63 | C10: =ROUND(C9*2,)/2 -> 57.5 | D10: =ROUND(D9*2,)/2 -> 60 | E10: =ROUND(E9*2,)/2 -> 63.5 | F10: =ROUND(F9*2,)/2 -> 61 | G10: / | I10: =AVERAGE(B10:E10) -> 61 | J10: =56+FLOOR(RAND()*10,0.5) -> 57.5 | L10: =56+FLOOR(RAND()*10,0.5) -> 65.5 | M10: =5+FLOOR(RAND()*2,0.2) -> 5.2
B11: =ROUND(RAND()*(64-57)+57,1) -> 58 | C11: =ROUND(RAND()*(64-57)+57,1) -> 63 | D11: =ROUND(RAND()*(64-57)+57,1) -> 60.6 | E11: =ROUND(RAND()*(64-57)+57,1) -> 63.6 | F11: =ROUND(RAND()*(64-57)+57,1) -> 60.7 | G11: / | J11: =56+FLOOR(RAND()*10,0.5) -> 61.5 | L11: =56+FLOOR(RAND()*10,0.5) -> 60.5 | M11: =5+FLOOR(RAND()*2,0.2) -> 6.6
A12: 6 | B12: =ROUND(B11*2,)/2 -> 58 | C12: =ROUND(C11*2,)/2 -> 63 | D12: =ROUND(D11*2,)/2 -> 60.5 | E12: =ROUND(E11*2,)/2 -> 63.5 | F12: =ROUND(F11*2,)/2 -> 60.5 | G12: / | I12: =AVERAGE(B12:E12) -> 61.25 | J12: =56+FLOOR(RAND()*10,0.5) -> 64.5 | L12: =56+FLOOR(RAND()*10,0.5) -> 64.5 | M12: =5+FLOOR(RAND()*2,0.2) -> 5.6
B13: =ROUND(RAND()*(64-57)+57,1) -> 60 | C13: =ROUND(RAND()*(64-57)+57,1) -> 60.4 | D13: =ROUND(RAND()*(64-57)+57,1) -> 58 | E13: =ROUND(RAND()*(64-57)+57,1) -> 60.9 | F13: =ROUND(RAND()*(64-57)+57,1) -> 57 | G13: / | J13: =56+FLOOR(RAND()*10,0.5) -> 56 | L13: =56+FLOOR(RAND()*10,0.5) -> 65.5 | M13: =5+FLOOR(RAND()*2,0.2) -> 5.4
A14: 7 | B14: =ROUND(B13*2,)/2 -> 60 | C14: =ROUND(C13*2,)/2 -> 60.5 | D14: =ROUND(D13*2,)/2 -> 58 | E14: =ROUND(E13*2,)/2 -> 61 | F14: =ROUND(F13*2,)/2 -> 57 | G14: / | I14: =AVERAGE(B14:E14) -> 59.875 | J14: =56+FLOOR(RAND()*10,0.5) -> 63.5 | L14: =56+FLOOR(RAND()*10,0.5) -> 60.5 | M14: =5+FLOOR(RAND()*2,0.2) -> 5.2
B15: =ROUND(RAND()*(64-57)+57,1) -> 62.8 | C15: =ROUND(RAND()*(64-57)+57,1) -> 59.7 | D15: =ROUND(RAND()*(64-57)+57,1) -> 63 | E15: =ROUND(RAND()*(64-57)+57,1) -> 57.7 | F15: =ROUND(RAND()*(64-57)+57,1) -> 64 | G15: / | J15: =56+FLOOR(RAND()*10,0.5) -> 63 | L15: =56+FLOOR(RAND()*10,0.5) -> 60.5 | M15: =5+FLOOR(RAND()*2,0.2) -> 6.8
A16: 8 | B16: =ROUND(B15*2,)/2 -> 63 | C16: =ROUND(C15*2,)/2 -> 59.5 | D16: =ROUND(D15*2,)/2 -> 63 | E16: =ROUND(E15*2,)/2 -> 57.5 | F16: =ROUND(F15*2,)/2 -> 64 | G16: / | I16: =AVERAGE(B16:E16) -> 60.75 | J16: =56+FLOOR(RAND()*10,0.5) -> 58.5 | L16: =56+FLOOR(RAND()*10,0.5) -> 61 | M16: =5+FLOOR(RAND()*2,0.2) -> 5.6
B17: =ROUND(RAND()*(64-57)+57,1) -> 58.9 | C17: =ROUND(RAND()*(64-57)+57,1) -> 61.6 | D17: =ROUND(RAND()*(64-57)+57,1) -> 62.5 | E17: =ROUND(RAND()*(64-57)+57,1) -> 57.5 | F17: =ROUND(RAND()*(64-57)+57,1) -> 63 | G17: / | J17: =56+FLOOR(RAND()*10,0.5) -> 63 | L17: =56+FLOOR(RAND()*10,0.5) -> 64 | M17: =5+FLOOR(RAND()*2,0.2) -> 5.6
A18: 9 | B18: =ROUND(B17*2,)/2 -> 59 | C18: =ROUND(C17*2,)/2 -> 61.5 | D18: =ROUND(D17*2,)/2 -> 62.5 | E18: =ROUND(E17*2,)/2 -> 57.5 | F18: =ROUND(F17*2,)/2 -> 63 | G18: / | I18: =AVERAGE(B18:E18) -> 60.125 | J18: =56+FLOOR(RAND()*10,0.5) -> 56 | L18: =56+FLOOR(RAND()*10,0.5) -> 57.5 | M18: =5+FLOOR(RAND()*2,0.2) -> 5.8
B19: =ROUND(RAND()*(64-57)+57,1) -> 61.3 | C19: =ROUND(RAND()*(64-57)+57,1) -> 63.4 | D19: =ROUND(RAND()*(64-57)+57,1) -> 57.5 | E19: =ROUND(RAND()*(64-57)+57,1) -> 62 | F19: =ROUND(RAND()*(64-57)+57,1) -> 61.1 | G19: / | J19: =56+FLOOR(RAND()*10,0.5) -> 60.5 | L19: =56+FLOOR(RAND()*10,0.5) -> 61.5 | M19: =5+FLOOR(RAND()*2,0.2) -> 5.6
A20: 10 | B20: =ROUND(B19*2,)/2 -> 61.5 | C20: =ROUND(C19*2,)/2 -> 63.5 | D20: =ROUND(D19*2,)/2 -> 57.5 | E20: =ROUND(E19*2,)/2 -> 62 | F20: =ROUND(F19*2,)/2 -> 61 | G20: / | I20: =AVERAGE(B20:E20) -> 61.125 | J20: =56+FLOOR(RAND()*10,0.5) -> 61.5 | L20: =56+FLOOR(RAND()*10,0.5) -> 58.5 | M20: =5+FLOOR(RAND()*2,0.2) -> 5.2
B21: =ROUND(RAND()*(64-57)+57,1) -> 61.9 | C21: =ROUND(RAND()*(64-57)+57,1) -> 60.9 | D21: =ROUND(RAND()*(64-57)+57,1) -> 63.1 | E21: =ROUND(RAND()*(64-57)+57,1) -> 60.6 | F21: =ROUND(RAND()*(64-57)+57,1) -> 57.2 | G21: / | J21: =56+FLOOR(RAND()*10,0.5) -> 57.5 | L21: =56+FLOOR(RAND()*10,0.5) -> 56 | M21: =5+FLOOR(RAND()*2,0.2) -> 5.6
A22: 11 | B22: =ROUND(B21*2,)/2 -> 62 | C22: =ROUND(C21*2,)/2 -> 61 | D22: =ROUND(D21*2,)/2 -> 63 | E22: =ROUND(E21*2,)/2 -> 60.5 | F22: =ROUND(F21*2,)/2 -> 57 | G22: / | I22: =AVERAGE(B22:E22) -> 61.625 | J22: =56+FLOOR(RAND()*10,0.5) -> 64 | L22: =56+FLOOR(RAND()*10,0.5) -> 57 | M22: =5+FLOOR(RAND()*2,0.2) -> 5.6
B23: =ROUND(RAND()*(64-57)+57,1) -> 62.7 | C23: =ROUND(RAND()*(64-57)+57,1) -> 61.7 | D23: =ROUND(RAND()*(64-57)+57,1) -> 63.7 | E23: =ROUND(RAND()*(64-57)+57,1) -> 61.3 | F23: =ROUND(RAND()*(64-57)+57,1) -> 61.6 | G23: / | J23: =56+FLOOR(RAND()*10,0.5) -> 59 | L23: =56+FLOOR(RAND()*10,0.5) -> 65 | M23: =5+FLOOR(RAND()*2,0.2) -> 5
A24: 12 | B24: =ROUND(B23*2,)/2 -> 62.5 | C24: =ROUND(C23*2,)/2 -> 61.5 | D24: =ROUND(D23*2,)/2 -> 63.5 | E24: =ROUND(E23*2,)/2 -> 61.5 | F24: =ROUND(F23*2,)/2 -> 61.5 | G24: / | I24: =AVERAGE(B24:E24) -> 62.25 | J24: =56+FLOOR(RAND()*10,0.5) -> 56 | L24: =56+FLOOR(RAND()*10,0.5) -> 56 | M24: =5+FLOOR(RAND()*2,0.2) -> 5.4
B25: =ROUND(RAND()*(64-57)+57,1) -> 59.8 | C25: =ROUND(RAND()*(64-57)+57,1) -> 61.4 | D25: =ROUND(RAND()*(64-57)+57,1) -> 63.4 | E25: =ROUND(RAND()*(64-57)+57,1) -> 57.3 | F25: =ROUND(RAND()*(64-57)+57,1) -> 62.6 | G25: / | J25: =56+FLOOR(RAND()*10,0.5) -> 65
A26: 13 | B26: =ROUND(B25*2,)/2 -> 60 | C26: =ROUND(C25*2,)/2 -> 61.5 | D26: =ROUND(D25*2,)/2 -> 63.5 | E26: =ROUND(E25*2,)/2 -> 57.5 | F26: =ROUND(F25*2,)/2 -> 62.5 | G26: / | I26: =AVERAGE(B26:E26) -> 60.625
B27: =ROUND(RAND()*(64-57)+57,1) -> 63.7 | C27: =ROUND(RAND()*(64-57)+57,1) -> 63.7 | D27: =ROUND(RAND()*(64-57)+57,1) -> 63.7 | E27: =ROUND(RAND()*(64-57)+57,1) -> 61.2 | F27: =ROUND(RAND()*(64-57)+57,1) -> 61.9 | G27: /
A28: 14 | B28: =ROUND(B27*2,)/2 -> 63.5 | C28: =ROUND(C27*2,)/2 -> 63.5 | D28: =ROUND(D27*2,)/2 -> 63.5 | E28: =ROUND(E27*2,)/2 -> 61 | F28: =ROUND(F27*2,)/2 -> 62 | G28: / | I28: =AVERAGE(B28:E28) -> 62.875
B29: =ROUND(RAND()*(64-57)+57,1) -> 59.3 | C29: =ROUND(RAND()*(64-57)+57,1) -> 58.2 | D29: =ROUND(RAND()*(64-57)+57,1) -> 60.1 | E29: =ROUND(RAND()*(64-57)+57,1) -> 59.3 | F29: =ROUND(RAND()*(64-57)+57,1) -> 59.6 | G29: /
A30: 15 | B30: =ROUND(B29*2,)/2 -> 59.5 | C30: =ROUND(C29*2,)/2 -> 58 | D30: =ROUND(D29*2,)/2 -> 60 | E30: =ROUND(E29*2,)/2 -> 59.5 | F30: =ROUND(F29*2,)/2 -> 59.5 | G30: / | I30: =AVERAGE(B30:E30) -> 59.25
B31: =ROUND(RAND()*(64-57)+57,1) -> 60.6 | C31: =ROUND(RAND()*(64-57)+57,1) -> 59.6 | D31: =ROUND(RAND()*(64-57)+57,1) -> 60.1 | E31: =ROUND(RAND()*(64-57)+57,1) -> 59.3 | F31: =ROUND(RAND()*(64-57)+57,1) -> 57.7 | G31: /
A32: 16 | B32: =ROUND(B31*2,)/2 -> 60.5 | C32: =ROUND(C31*2,)/2 -> 59.5 | D32: =ROUND(D31*2,)/2 -> 60 | E32: =ROUND(E31*2,)/2 -> 59.5 | F32: =ROUND(F31*2,)/2 -> 57.5 | G32: / | I32: =AVERAGE(B32:E32) -> 59.875
B33: =ROUND(RAND()*(64-57)+57,1) -> 61 | C33: =ROUND(RAND()*(64-57)+57,1) -> 63.5 | D33: =ROUND(RAND()*(64-57)+57,1) -> 59.4 | E33: =ROUND(RAND()*(64-57)+57,1) -> 63.4 | F33: =ROUND(RAND()*(64-57)+57,1) -> 57.6 | G33: /
A34: 17 | B34: =ROUND(B33*2,)/2 -> 61 | C34: =ROUND(C33*2,)/2 -> 63.5 | D34: =ROUND(D33*2,)/2 -> 59.5 | E34: =ROUND(E33*2,)/2 -> 63.5 | F34: =ROUND(F33*2,)/2 -> 57.5 | G34: / | I34: =AVERAGE(B34:E34) -> 61.875
B35: =ROUND(RAND()*(64-57)+57,1) -> 62.3 | C35: =ROUND(RAND()*(64-57)+57,1) -> 58.2 | D35: =ROUND(RAND()*(64-57)+57,1) -> 61.4 | E35: =ROUND(RAND()*(64-57)+57,1) -> 58.4 | F35: =ROUND(RAND()*(64-57)+57,1) -> 59 | G35: /
A36: 18 | B36: =ROUND(B35*2,)/2 -> 62.5 | C36: =ROUND(C35*2,)/2 -> 58 | D36: =ROUND(D35*2,)/2 -> 61.5 | E36: =ROUND(E35*2,)/2 -> 58.5 | F36: =ROUND(F35*2,)/2 -> 59 | G36: / | I36: =AVERAGE(B36:E36) -> 60.125
B37: =ROUND(RAND()*(64-57)+57,1) -> 58.8 | C37: =ROUND(RAND()*(64-57)+57,1) -> 59.6 | D37: =ROUND(RAND()*(64-57)+57,1) -> 58.2 | E37: =ROUND(RAND()*(64-57)+57,1) -> 63 | F37: =ROUND(RAND()*(64-57)+57,1) -> 61.8 | G37: /
A38: 19 | B38: =ROUND(B37*2,)/2 -> 59 | C38: =ROUND(C37*2,)/2 -> 59.5 | D38: =ROUND(D37*2,)/2 -> 58 | E38: =ROUND(E37*2,)/2 -> 63 | F38: =ROUND(F37*2,)/2 -> 62 | G38: / | I38: =AVERAGE(B38:E38) -> 59.875
B39: =ROUND(RAND()*(64-57)+57,1) -> 63.2 | C39: =ROUND(RAND()*(64-57)+57,1) -> 63.3 | D39: =ROUND(RAND()*(64-57)+57,1) -> 60.3 | E39: =ROUND(RAND()*(64-57)+57,1) -> 59.9 | F39: =ROUND(RAND()*(64-57)+57,1) -> 57.9 | G39: /
A40: 20 | B40: =ROUND(B39*2,)/2 -> 63 | C40: =ROUND(C39*2,)/2 -> 63.5 | D40: =ROUND(D39*2,)/2 -> 60.5 | E40: =ROUND(E39*2,)/2 -> 60 | F40: =ROUND(F39*2,)/2 -> 58 | G40: / | I40: =AVERAGE(B40:E40) -> 61.75
...

Sheet 记录表 2 (2)
M1: 第 | P1: 页，共 | V1: 页
A2: QJ0508
A3: 金属洛氏硬度试验检测记录表
A4: 试验室名称： | I4: 记录编号:
A5: 工程部位/用途 | I5: 委托/任务编号
A6: 样品名称 | I6: 样品编号
A7: 试验依据 | I7: 样品描述
A8: 试验条件 | I8: 试验日期
A9: 主要仪器 设备及编号
A10: 技术要求 | M10: 规格型号
A11: 试件编号 | D11: 外观 | E11: 洛氏硬度( ) | K11: 平均值 | M11: 单组评定 | S11: 备注
A12: ='记录夹片公式 (2)'!A2 -> 1 | D12: 无锈蚀 | E12: ='记录夹片公式 (2)'!B2 -> 58.5 | F12: ='记录夹片公式 (2)'!C2 -> 59.5 | G12: ='记录夹片公式 (2)'!D2 -> 59.5 | H12: ='记录夹片公式 (2)'!E2 -> 58 | I12: ='记录夹片公式 (2)'!F2 -> 57 | J12: ='记录夹片公式 (2)'!G2 -> / | K12: =AVERAGE(F12:I12) -> 58.5 | M12: 合格 | S12: /
A13: ='记录夹片公式 (2)'!A4 -> 2 | D13: 无锈蚀 | E13: ='记录夹片公式 (2)'!B4 -> 58.5 | F13: ='记录夹片公式 (2)'!C4 -> 58 | G13: ='记录夹片公式 (2)'!D4 -> 59 | H13: ='记录夹片公式 (2)'!E4 -> 59 | I13: ='记录夹片公式 (2)'!F4 -> 58 | J13: ='记录夹片公式 (2)'!G4 -> / | K13: =AVERAGE(F13:I13) -> 58.5 | M13: 合格 | S13: /
A14: ='记录夹片公式 (2)'!A6 -> 3 | D14: 无锈蚀 | E14: ='记录夹片公式 (2)'!B6 -> 59 | F14: ='记录夹片公式 (2)'!C6 -> 59.5 | G14: ='记录夹片公式 (2)'!D6 -> 58 | H14: ='记录夹片公式 (2)'!E6 -> 57.5 | I14: ='记录夹片公式 (2)'!F6 -> 60.5 | J14: ='记录夹片公式 (2)'!G6 -> / | K14: =AVERAGE(F14:I14) -> 58.875 | M14: 合格 | S14: /
A15: ='记录夹片公式 (2)'!A8 -> 4 | D15: 无锈蚀 | E15: ='记录夹片公式 (2)'!B8 -> 60.5 | F15: ='记录夹片公式 (2)'!C8 -> 64 | G15: ='记录夹片公式 (2)'!D8 -> 61 | H15: ='记录夹片公式 (2)'!E8 -> 59.5 | I15: ='记录夹片公式 (2)'!F8 -> 61 | J15: ='记录夹片公式 (2)'!G8 -> / | K15: =AVERAGE(F15:I15) -> 61.375 | M15: 合格 | S15: /
A16: ='记录夹片公式 (2)'!A10 -> 5 | D16: 无锈蚀 | E16: ='记录夹片公式 (2)'!B10 -> 58.5 | F16: ='记录夹片公式 (2)'!C10 -> 58 | G16: ='记录夹片公式 (2)'!D10 -> 59.5 | H16: ='记录夹片公式 (2)'!E10 -> 64 | I16: ='记录夹片公式 (2)'!F10 -> 58.5 | J16: ='记录夹片公式 (2)'!G10 -> / | K16: =AVERAGE(F16:I16) -> 60 | M16: 合格 | S16: /
A17: ='记录夹片公式 (2)'!A12 -> 6 | D17: 无锈蚀 | E17: ='记录夹片公式 (2)'!B12 -> 63.5 | F17: ='记录夹片公式 (2)'!C12 -> 59.5 | G17: ='记录夹片公式 (2)'!D12 -> 57.5 | H17: ='记录夹片公式 (2)'!E12 -> 58.5 | I17: ='记录夹片公式 (2)'!F12 -> 58.5 | J17: ='记录夹片公式 (2)'!G12 -> / | K17: =AVERAGE(F17:I17) -> 58.5 | M17: 合格 | S17: /
A18: ='记录夹片公式 (2)'!A14 -> 7 | D18: 无锈蚀 | E18: ='记录夹片公式 (2)'!B14 -> 61.5 | F18: ='记录夹片公式 (2)'!C14 -> 60.5 | G18: ='记录夹片公式 (2)'!D14 -> 61 | H18: ='记录夹片公式 (2)'!E14 -> 58.5 | I18: ='记录夹片公式 (2)'!F14 -> 61.5 | J18: ='记录夹片公式 (2)'!G14 -> / | K18: =AVERAGE(F18:I18) -> 60.375 | M18: 合格 | S18: /
A19: ='记录夹片公式 (2)'!A16 -> 8 | D19: 无锈蚀 | E19: ='记录夹片公式 (2)'!B16 -> 60 | F19: ='记录夹片公式 (2)'!C16 -> 59.5 | G19: ='记录夹片公式 (2)'!D16 -> 63 | H19: ='记录夹片公式 (2)'!E16 -> 61.5 | I19: ='记录夹片公式 (2)'!F16 -> 61 | J19: ='记录夹片公式 (2)'!G16 -> / | K19: =AVERAGE(F19:I19) -> 61.25 | M19: 合格 | S19: /
A20: ='记录夹片公式 (2)'!A18 -> 9 | D20: 无锈蚀 | E20: ='记录夹片公式 (2)'!B18 -> 61.5 | F20: ='记录夹片公式 (2)'!C18 -> 59 | G20: ='记录夹片公式 (2)'!D18 -> 57.5 | H20: ='记录夹片公式 (2)'!E18 -> 60.5 | I20: ='记录夹片公式 (2)'!F18 -> 63.5 | J20: ='记录夹片公式 (2)'!G18 -> / | K20: =AVERAGE(F20:I20) -> 60.125 | M20: 合格 | S20: /
A21: ='记录夹片公式 (2)'!A20 -> 10 | D21: 无锈蚀 | E21: ='记录夹片公式 (2)'!B20 -> 60 | F21: ='记录夹片公式 (2)'!C20 -> 62 | G21: ='记录夹片公式 (2)'!D20 -> 58 | H21: ='记录夹片公式 (2)'!E20 -> 58.5 | I21: ='记录夹片公式 (2)'!F20 -> 59.5 | J21: ='记录夹片公式 (2)'!G20 -> / | K21: =AVERAGE(F21:I21) -> 59.5 | M21: 合格 | S21: /
A22: ='记录夹片公式 (2)'!A22 -> 11 | D22: 无锈蚀 | E22: ='记录夹片公式 (2)'!B22 -> 63.5 | F22: ='记录夹片公式 (2)'!C22 -> 59 | G22: ='记录夹片公式 (2)'!D22 -> 59 | H22: ='记录夹片公式 (2)'!E22 -> 60.5 | I22: ='记录夹片公式 (2)'!F22 -> 62.5 | J22: ='记录夹片公式 (2)'!G22 -> / | K22: =AVERAGE(F22:I22) -> 60.25 | M22: 合格 | S22: /
A23: ='记录夹片公式 (2)'!A24 -> 12 | D23: 无锈蚀 | E23: ='记录夹片公式 (2)'!B24 -> 58.5 | F23: ='记录夹片公式 (2)'!C24 -> 60 | G23: ='记录夹片公式 (2)'!D24 -> 62.5 | H23: ='记录夹片公式 (2)'!E24 -> 62.5 | I23: ='记录夹片公式 (2)'!F24 -> 60.5 | J23: ='记录夹片公式 (2)'!G24 -> / | K23: =AVERAGE(F23:I23) -> 61.375 | M23: 合格 | S23: /
A24: ='记录夹片公式 (2)'!A26 -> 13 | D24: 无锈蚀 | E24: ='记录夹片公式 (2)'!B26 -> 64 | F24: ='记录夹片公式 (2)'!C26 -> 60 | G24: ='记录夹片公式 (2)'!D26 -> 61.5 | H24: ='记录夹片公式 (2)'!E26 -> 59 | I24: ='记录夹片公式 (2)'!F26 -> 57 | J24: ='记录夹片公式 (2)'!G26 -> / | K24: =AVERAGE(F24:I24) -> 59.375 | M24: 合格 | S24: /
A25: ='记录夹片公式 (2)'!A28 -> 14 | D25: 无锈蚀 | E25: ='记录夹片公式 (2)'!B28 -> 62.5 | F25: ='记录夹片公式 (2)'!C28 -> 60 | G25: ='记录夹片公式 (2)'!D28 -> 59 | H25: ='记录夹片公式 (2)'!E28 -> 57.5 | I25: ='记录夹片公式 (2)'!F28 -> 63.5 | J25: ='记录夹片公式 (2)'!G28 -> / | K25: =AVERAGE(F25:I25) -> 60 | M25: 合格 | S25: /
A26: ='记录夹片公式 (2)'!A30 -> 15 | D26: 无锈蚀 | E26: ='记录夹片公式 (2)'!B30 -> 57.5 | F26: ='记录夹片公式 (2)'!C30 -> 57 | G26: ='记录夹片公式 (2)'!D30 -> 60.5 | H26: ='记录夹片公式 (2)'!E30 -> 58 | I26: ='记录夹片公式 (2)'!F30 -> 60 | J26: ='记录夹片公式 (2)'!G30 -> / | K26: =AVERAGE(F26:I26) -> 58.875 | M26: 合格 | S26: /
A27: ='记录夹片公式 (2)'!A32 -> 16 | D27: 无锈蚀 | E27: ='记录夹片公式 (2)'!B32 -> 63 | F27: ='记录夹片公式 (2)'!C32 -> 64 | G27: ='记录夹片公式 (2)'!D32 -> 62.5 | H27: ='记录夹片公式 (2)'!E32 -> 63.5 | I27: ='记录夹片公式 (2)'!F32 -> 60.5 | J27: ='记录夹片公式 (2)'!G32 -> / | K27: =AVERAGE(F27:I27) -> 62.625 | M27: 合格 | S27: /
A28: ='记录夹片公式 (2)'!A34 -> 17 | D28: 无锈蚀 | E28: ='记录夹片公式 (2)'!B34 -> 58.5 | F28: ='记录夹片公式 (2)'!C34 -> 58 | G28: ='记录夹片公式 (2)'!D34 -> 57.5 | H28: ='记录夹片公式 (2)'!E34 -> 58 | I28: ='记录夹片公式 (2)'!F34 -> 59.5 | J28: ='记录夹片公式 (2)'!G34 -> / | K28: =AVERAGE(F28:I28) -> 58.25 | M28: 合格 | S28: /
A29: 备注:
A31: 试验： | E31: 复核： | J31: 日期： | O31: 年 | R31: 月 | U31: 日

Sheet 记录夹片公式 (2)
B1: =ROUND(RAND()*(64-57)+57,1) -> 58.5 | C1: =ROUND(RAND()*(64-57)+57,1) -> 59.7 | D1: =ROUND(RAND()*(64-57)+57,1) -> 59.5 | E1: =ROUND(RAND()*(64-57)+57,1) -> 58.2 | F1: =ROUND(RAND()*(64-57)+57,1) -> 57.2 | J1: 56~66 | K1: 加几就是上线
A2: 1 | B2: =ROUND(B1*2,)/2 -> 58.5 | C2: =ROUND(C1*2,)/2 -> 59.5 | D2: =ROUND(D1*2,)/2 -> 59.5 | E2: =ROUND(E1*2,)/2 -> 58 | F2: =ROUND(F1*2,)/2 -> 57 | G2: / | I2: =AVERAGE(B2:E2) -> 58.875 | J2: =56+FLOOR(RAND()*10,0.5) -> 57 | L2: =56+FLOOR(RAND()*10,0.5) -> 58.5 | M2: =5+FLOOR(RAND()*2,0.2) -> 6.4
B3: =ROUND(RAND()*(64-57)+57,1) -> 58.5 | C3: =ROUND(RAND()*(64-57)+57,1) -> 58.1 | D3: =ROUND(RAND()*(64-57)+57,1) -> 59.1 | E3: =ROUND(RAND()*(64-57)+57,1) -> 59.2 | F3: =ROUND(RAND()*(64-57)+57,1) -> 58 | G3: / | J3: =56+FLOOR(RAND()*10,0.5) -> 63 | L3: =56+FLOOR(RAND()*10,0.5) -> 60.5 | M3: =5+FLOOR(RAND()*2,0.2) -> 6.4
A4: 2 | B4: =ROUND(B3*2,)/2 -> 58.5 | C4: =ROUND(C3*2,)/2 -> 58 | D4: =ROUND(D3*2,)/2 -> 59 | E4: =ROUND(E3*2,)/2 -> 59 | F4: =ROUND(F3*2,)/2 -> 58 | G4: / | I4: =AVERAGE(B4:E4) -> 58.625 | J4: =56+FLOOR(RAND()*10,0.5) -> 58.5 | L4: =56+FLOOR(RAND()*10,0.5) -> 56 | M4: =5+FLOOR(RAND()*2,0.2) -> 5.6
B5: =ROUND(RAND()*(64-57)+57,1) -> 59.1 | C5: =ROUND(RAND()*(64-57)+57,1) -> 59.3 | D5: =ROUND(RAND()*(64-57)+57,1) -> 57.8 | E5: =ROUND(RAND()*(64-57)+57,1) -> 57.4 | F5: =ROUND(RAND()*(64-57)+57,1) -> 60.4 | G5: / | J5: =56+FLOOR(RAND()*10,0.5) -> 62.5 | L5: =56+FLOOR(RAND()*10,0.5) -> 56.5 | M5: =5+FLOOR(RAND()*2,0.2) -> 6.8
A6: 3 | B6: =ROUND(B5*2,)/2 -> 59 | C6: =ROUND(C5*2,)/2 -> 59.5 | D6: =ROUND(D5*2,)/2 -> 58 | E6: =ROUND(E5*2,)/2 -> 57.5 | F6: =ROUND(F5*2,)/2 -> 60.5 | G6: / | I6: =AVERAGE(B6:E6) -> 58.5 | J6: =56+FLOOR(RAND()*10,0.5) -> 62.5 | L6: =56+FLOOR(RAND()*10,0.5) -> 62 | M6: =5+FLOOR(RAND()*2,0.2) -> 6.2
B7: =ROUND(RAND()*(64-57)+57,1) -> 60.5 | C7: =ROUND(RAND()*(64-57)+57,1) -> 63.8 | D7: =ROUND(RAND()*(64-57)+57,1) -> 61.2 | E7: =ROUND(RAND()*(64-57)+57,1) -> 59.4 | F7: =ROUND(RAND()*(64-57)+57,1) -> 60.8 | G7: / | J7: =56+FLOOR(RAND()*10,0.5) -> 62.5 | L7: =56+FLOOR(RAND()*10,0.5) -> 62 | M7: =5+FLOOR(RAND()*2,0.2) -> 5.8
A8: 4 | B8: =ROUND(B7*2,)/2 -> 60.5 | C8: =ROUND(C7*2,)/2 -> 64 | D8: =ROUND(D7*2,)/2 -> 61 | E8: =ROUND(E7*2,)/2 -> 59.5 | F8: =ROUND(F7*2,)/2 -> 61 | G8: / | I8: =AVERAGE(B8:E8) -> 61.25 | J8: =56+FLOOR(RAND()*10,0.5) -> 58 | L8: =56+FLOOR(RAND()*10,0.5) -> 62 | M8: =5+FLOOR(RAND()*2,0.2) -> 6.4
B9: =ROUND(RAND()*(64-57)+57,1) -> 58.4 | C9: =ROUND(RAND()*(64-57)+57,1) -> 58 | D9: =ROUND(RAND()*(64-57)+57,1) -> 59.6 | E9: =ROUND(RAND()*(64-57)+57,1) -> 64 | F9: =ROUND(RAND()*(64-57)+57,1) -> 58.7 | G9: / | J9: =56+FLOOR(RAND()*10,0.5) -> 65 | L9: =56+FLOOR(RAND()*10,0.5) -> 65.5 | M9: =5+FLOOR(RAND()*2,0.2) -> 6.4
A10: 5 | B10: =ROUND(B9*2,)/2 -> 58.5 | C10: =ROUND(C9*2,)/2 -> 58 | D10: =ROUND(D9*2,)/2 -> 59.5 | E10: =ROUND(E9*2,)/2 -> 64 | F10: =ROUND(F9*2,)/2 -> 58.5 | G10: / | I10: =AVERAGE(B10:E10) -> 60 | J10: =56+FLOOR(RAND()*10,0.5) -> 62.5 | L10: =56+FLOOR(RAND()*10,0.5) -> 65.5 | M10: =5+FLOOR(RAND()*2,0.2) -> 5.4
B11: =ROUND(RAND()*(64-57)+57,1) -> 63.3 | C11: =ROUND(RAND()*(64-57)+57,1) -> 59.3 | D11: =ROUND(RAND()*(64-57)+57,1) -> 57.6 | E11: =ROUND(RAND()*(64-57)+57,1) -> 58.7 | F11: =ROUND(RAND()*(64-57)+57,1) -> 58.3 | G11: / | J11: =56+FLOOR(RAND()*10,0.5) -> 64.5 | L11: =56+FLOOR(RAND()*10,0.5) -> 56.5 | M11: =5+FLOOR(RAND()*2,0.2) -> 6.4
A12: 6 | B12: =ROUND(B11*2,)/2 -> 63.5 | C12: =ROUND(C11*2,)/2 -> 59.5 | D12: =ROUND(D11*2,)/2 -> 57.5 | E12: =ROUND(E11*2,)/2 -> 58.5 | F12: =ROUND(F11*2,)/2 -> 58.5 | G12: / | I12: =AVERAGE(B12:E12) -> 59.75 | J12: =56+FLOOR(RAND()*10,0.5) -> 62.5 | L12: =56+FLOOR(RAND()*10,0.5) -> 61 | M12: =5+FLOOR(RAND()*2,0.2) -> 5.8
B13: =ROUND(RAND()*(64-57)+57,1) -> 61.5 | C13: =ROUND(RAND()*(64-57)+57,1) -> 60.7 | D13: =ROUND(RAND()*(64-57)+57,1) -> 60.8 | E13: =ROUND(RAND()*(64-57)+57,1) -> 58.4 | F13: =ROUND(RAND()*(64-57)+57,1) -> 61.7 | G13: / | J13: =56+FLOOR(RAND()*10,0.5) -> 59 | L13: =56+FLOOR(RAND()*10,0.5) -> 62.5 | M13: =5+FLOOR(RAND()*2,0.2) -> 5.4
A14: 7 | B14: =ROUND(B13*2,)/2 -> 61.5 | C14: =ROUND(C13*2,)/2 -> 60.5 | D14: =ROUND(D13*2,)/2 -> 61 | E14: =ROUND(E13*2,)/2 -> 58.5 | F14: =ROUND(F13*2,)/2 -> 61.5 | G14: / | I14: =AVERAGE(B14:E14) -> 60.375 | J14: =56+FLOOR(RAND()*10,0.5) -> 58.5 | L14: =56+FLOOR(RAND()*10,0.5) -> 60 | M14: =5+FLOOR(RAND()*2,0.2) -> 5
B15: =ROUND(RAND()*(64-57)+57,1) -> 60 | C15: =ROUND(RAND()*(64-57)+57,1) -> 59.5 | D15: =ROUND(RAND()*(64-57)+57,1) -> 63 | E15: =ROUND(RAND()*(64-57)+57,1) -> 61.4 | F15: =ROUND(RAND()*(64-57)+57,1) -> 60.9 | G15: / | J15: =56+FLOOR(RAND()*10,0.5) -> 63.5 | L15: =56+FLOOR(RAND()*10,0.5) -> 64.5 | M15: =5+FLOOR(RAND()*2,0.2) -> 5
A16: 8 | B16: =ROUND(B15*2,)/2 -> 60 | C16: =ROUND(C15*2,)/2 -> 59.5 | D16: =ROUND(D15*2,)/2 -> 63 | E16: =ROUND(E15*2,)/2 -> 61.5 | F16: =ROUND(F15*2,)/2 -> 61 | G16: / | I16: =AVERAGE(B16:E16) -> 61 | J16: =56+FLOOR(RAND()*10,0.5) -> 61 | L16: =56+FLOOR(RAND()*10,0.5) -> 61 | M16: =5+FLOOR(RAND()*2,0.2) -> 6
B17: =ROUND(RAND()*(64-57)+57,1) -> 61.6 | C17: =ROUND(RAND()*(64-57)+57,1) -> 59 | D17: =ROUND(RAND()*(64-57)+57,1) -> 57.3 | E17: =ROUND(RAND()*(64-57)+57,1) -> 60.5 | F17: =ROUND(RAND()*(64-57)+57,1) -> 63.7 | G17: / | J17: =56+FLOOR(RAND()*10,0.5) -> 64.5 | L17: =56+FLOOR(RAND()*10,0.5) -> 61 | M17: =5+FLOOR(RAND()*2,0.2) -> 5
A18: 9 | B18: =ROUND(B17*2,)/2 -> 61.5 | C18: =ROUND(C17*2,)/2 -> 59 | D18: =ROUND(D17*2,)/2 -> 57.5 | E18: =ROUND(E17*2,)/2 -> 60.5 | F18: =ROUND(F17*2,)/2 -> 63.5 | G18: / | I18: =AVERAGE(B18:E18) -> 59.625 | J18: =56+FLOOR(RAND()*10,0.5) -> 63 | L18: =56+FLOOR(RAND()*10,0.5) -> 58.5 | M18: =5+FLOOR(RAND()*2,0.2) -> 6.6
B19: =ROUND(RAND()*(64-57)+57,1) -> 60.2 | C19: =ROUND(RAND()*(64-57)+57,1) -> 62 | D19: =ROUND(RAND()*(64-57)+57,1) -> 58.1 | E19: =ROUND(RAND()*(64-57)+57,1) -> 58.7 | F19: =ROUND(RAND()*(64-57)+57,1) -> 59.7 | G19: / | J19: =56+FLOOR(RAND()*10,0.5) -> 59.5 | L19: =56+FLOOR(RAND()*10,0.5) -> 58.5 | M19: =5+FLOOR(RAND()*2,0.2) -> 6.6
A20: 10 | B20: =ROUND(B19*2,)/2 -> 60 | C20: =ROUND(C19*2,)/2 -> 62 | D20: =ROUND(D19*2,)/2 -> 58 | E20: =ROUND(E19*2,)/2 -> 58.5 | F20: =ROUND(F19*2,)/2 -> 59.5 | G20: / | I20: =AVERAGE(B20:E20) -> 59.625 | J20: =56+FLOOR(RAND()*10,0.5) -> 56.5 | L20: =56+FLOOR(RAND()*10,0.5) -> 57 | M20: =5+FLOOR(RAND()*2,0.2) -> 6.6
B21: =ROUND(RAND()*(64-57)+57,1) -> 63.4 | C21: =ROUND(RAND()*(64-57)+57,1) -> 58.9 | D21: =ROUND(RAND()*(64-57)+57,1) -> 59 | E21: =ROUND(RAND()*(64-57)+57,1) -> 60.3 | F21: =ROUND(RAND()*(64-57)+57,1) -> 62.4 | G21: / | J21: =56+FLOOR(RAND()*10,0.5) -> 62 | L21: =56+FLOOR(RAND()*10,0.5) -> 63.5 | M21: =5+FLOOR(RAND()*2,0.2) -> 6.8
A22: 11 | B22: =ROUND(B21*2,)/2 -> 63.5 | C22: =ROUND(C21*2,)/2 -> 59 | D22: =ROUND(D21*2,)/2 -> 59 | E22: =ROUND(E21*2,)/2 -> 60.5 | F22: =ROUND(F21*2,)/2 -> 62.5 | G22: / | I22: =AVERAGE(B22:E22) -> 60.5 | J22: =56+FLOOR(RAND()*10,0.5) -> 60.5 | L22: =56+FLOOR(RAND()*10,0.5) -> 62 | M22: =5+FLOOR(RAND()*2,0.2) -> 5
B23: =ROUND(RAND()*(64-57)+57,1) -> 58.7 | C23: =ROUND(RAND()*(64-57)+57,1) -> 60.1 | D23: =ROUND(RAND()*(64-57)+57,1) -> 62.5 | E23: =ROUND(RAND()*(64-57)+57,1) -> 62.3 | F23: =ROUND(RAND()*(64-57)+57,1) -> 60.5 | G23: / | J23: =56+FLOOR(RAND()*10,0.5) -> 60.5 | L23: =56+FLOOR(RAND()*10,0.5) -> 65 | M23: =5+FLOOR(RAND()*2,0.2) -> 5.2
A24: 12 | B24: =ROUND(B23*2,)/2 -> 58.5 | C24: =ROUND(C23*2,)/2 -> 60 | D24: =ROUND(D23*2,)/2 -> 62.5 | E24: =ROUND(E23*2,)/2 -> 62.5 | F24: =ROUND(F23*2,)/2 -> 60.5 | G24: / | I24: =AVERAGE(B24:E24) -> 60.875 | J24: =56+FLOOR(RAND()*10,0.5) -> 59 | L24: =56+FLOOR(RAND()*10,0.5) -> 58 | M24: =5+FLOOR(RAND()*2,0.2) -> 5
B25: =ROUND(RAND()*(64-57)+57,1) -> 63.9 | C25: =ROUND(RAND()*(64-57)+57,1) -> 59.9 | D25: =ROUND(RAND()*(64-57)+57,1) -> 61.3 | E25: =ROUND(RAND()*(64-57)+57,1) -> 58.9 | F25: =ROUND(RAND()*(64-57)+57,1) -> 57.2 | G25: / | J25: =56+FLOOR(RAND()*10,0.5) -> 58
A26: 13 | B26: =ROUND(B25*2,)/2 -> 64 | C26: =ROUND(C25*2,)/2 -> 60 | D26: =ROUND(D25*2,)/2 -> 61.5 | E26: =ROUND(E25*2,)/2 -> 59 | F26: =ROUND(F25*2,)/2 -> 57 | G26: / | I26: =AVERAGE(B26:E26) -> 61.125
B27: =ROUND(RAND()*(64-57)+57,1) -> 62.4 | C27: =ROUND(RAND()*(64-57)+57,1) -> 60 | D27: =ROUND(RAND()*(64-57)+57,1) -> 58.8 | E27: =ROUND(RAND()*(64-57)+57,1) -> 57.4 | F27: =ROUND(RAND()*(64-57)+57,1) -> 63.7 | G27: /
A28: 14 | B28: =ROUND(B27*2,)/2 -> 62.5 | C28: =ROUND(C27*2,)/2 -> 60 | D28: =ROUND(D27*2,)/2 -> 59 | E28: =ROUND(E27*2,)/2 -> 57.5 | F28: =ROUND(F27*2,)/2 -> 63.5 | G28: / | I28: =AVERAGE(B28:E28) -> 59.75
B29: =ROUND(RAND()*(64-57)+57,1) -> 57.4 | C29: =ROUND(RAND()*(64-57)+57,1) -> 57.1 | D29: =ROUND(RAND()*(64-57)+57,1) -> 60.4 | E29: =ROUND(RAND()*(64-57)+57,1) -> 57.9 | F29: =ROUND(RAND()*(64-57)+57,1) -> 60 | G29: /
A30: 15 | B30: =ROUND(B29*2,)/2 -> 57.5 | C30: =ROUND(C29*2,)/2 -> 57 | D30: =ROUND(D29*2,)/2 -> 60.5 | E30: =ROUND(E29*2,)/2 -> 58 | F30: =ROUND(F29*2,)/2 -> 60 | G30: / | I30: =AVERAGE(B30:E30) -> 58.25
B31: =ROUND(RAND()*(64-57)+57,1) -> 62.9 | C31: =ROUND(RAND()*(64-57)+57,1) -> 64 | D31: =ROUND(RAND()*(64-57)+57,1) -> 62.5 | E31: =ROUND(RAND()*(64-57)+57,1) -> 63.3 | F31: =ROUND(RAND()*(64-57)+57,1) -> 60.3 | G31: /
A32: 16 | B32: =ROUND(B31*2,)/2 -> 63 | C32: =ROUND(C31*2,)/2 -> 64 | D32: =ROUND(D31*2,)/2 -> 62.5 | E32: =ROUND(E31*2,)/2 -> 63.5 | F32: =ROUND(F31*2,)/2 -> 60.5 | G32: / | I32: =AVERAGE(B32:E32) -> 63.25
B33: =ROUND(RAND()*(64-57)+57,1) -> 58.5 | C33: =ROUND(RAND()*(64-57)+57,1) -> 58 | D33: =ROUND(RAND()*(64-57)+57,1) -> 57.3 | E33: =ROUND(RAND()*(64-57)+57,1) -> 58.2 | F33: =ROUND(RAND()*(64-57)+57,1) -> 59.7 | G33: /
A34: 17 | B34: =ROUND(B33*2,)/2 -> 58.5 | C34: =ROUND(C33*2,)/2 -> 58 | D34: =ROUND(D33*2,)/2 -> 57.5 | E34: =ROUND(E33*2,)/2 -> 58 | F34: =ROUND(F33*2,)/2 -> 59.5 | G34: / | I34: =AVERAGE(B34:E34) -> 58
B35: =ROUND(RAND()*(64-57)+57,1) -> 63.6 | C35: =ROUND(RAND()*(64-57)+57,1) -> 60.8 | D35: =ROUND(RAND()*(64-57)+57,1) -> 60.7 | E35: =ROUND(RAND()*(64-57)+57,1) -> 59.5 | F35: =ROUND(RAND()*(64-57)+57,1) -> 60.1 | G35: /
A36: 18 | B36: =ROUND(B35*2,)/2 -> 63.5 | C36: =ROUND(C35*2,)/2 -> 61 | D36: =ROUND(D35*2,)/2 -> 60.5 | E36: =ROUND(E35*2,)/2 -> 59.5 | F36: =ROUND(F35*2,)/2 -> 60 | G36: / | I36: =AVERAGE(B36:E36) -> 61.125
B37: =ROUND(RAND()*(64-57)+57,1) -> 62.1 | C37: =ROUND(RAND()*(64-57)+57,1) -> 57.9 | D37: =ROUND(RAND()*(64-57)+57,1) -> 58.7 | E37: =ROUND(RAND()*(64-57)+57,1) -> 63.3 | F37: =ROUND(RAND()*(64-57)+57,1) -> 58.3 | G37: /
A38: 19 | B38: =ROUND(B37*2,)/2 -> 62 | C38: =ROUND(C37*2,)/2 -> 58 | D38: =ROUND(D37*2,)/2 -> 58.5 | E38: =ROUND(E37*2,)/2 -> 63.5 | F38: =ROUND(F37*2,)/2 -> 58.5 | G38: / | I38: =AVERAGE(B38:E38) -> 60.5
B39: =ROUND(RAND()*(64-57)+57,1) -> 57.9 | C39: =ROUND(RAND()*(64-57)+57,1) -> 62.7 | D39: =ROUND(RAND()*(64-57)+57,1) -> 63 | E39: =ROUND(RAND()*(64-57)+57,1) -> 61.9 | F39: =ROUND(RAND()*(64-57)+57,1) -> 60.8 | G39: /
A40: 20 | B40: =ROUND(B39*2,)/2 -> 58 | C40: =ROUND(C39*2,)/2 -> 62.5 | D40: =ROUND(D39*2,)/2 -> 63 | E40: =ROUND(E39*2,)/2 -> 62 | F40: =ROUND(F39*2,)/2 -> 61 | G40: / | I40: =AVERAGE(B40:E40) -> 61.375
...
