Workbook

Sheet 加载计算书
A1: 北京中铁房山桥梁有限公司龙口制梁场
A2: 静 载 试 验 计 算 书
A3: 一、 | B3: 试验原因
B4: 实地核查
A6: 二、 | B6: 试验梁基本数据表
B7: 1 | C7: 试验梁号 | H7: FL32QB-0020
B8: 2 | C8: 设计图号 | H8: 通桥（2012）2101-Ⅰ
B9: 3 | C9: 跨度(m) | H9: 32
B10: 4 | C10: 设计混凝土强度(MPa) | H10: C55
B11: 5 | C11: 设计弹性模量(GPa) | H11: 36
B12: 6 | C12: 混凝土灌注时间 | H12: 2014.10.27
B13: 7 | C13: 终张拉时间 | H13: 2014.11.16
B14: 8 | C14: 静载试验时间 | H14: 2014.12.24
B15: 9 | C15: 终张－静载试验的天数 | H15: 38
A17: 三、 | B17: 设计院提供静载试验参数
B18: 1 | C18: 跨度L(m) | H18: 32
B19: 2 | C19: 梁体质量对跨中的弯矩Mz(kN.m) | H19: 5272.3 | J19: =3.14*(25*25-15*15)*150/1000000000*7850*4 -> 5.91576
B20: 3 | C20: 道渣线路设备质量对跨中弯矩Md(kN.m) | H20: 6001.9
B21: 4 | C21: 防水层质量对跨中的弯矩Mf(kN.m) | H21: 368.8
B22: 5 | C22: 活载对跨中的弯矩Mh(kN.m) | H22: 8231.2 | J22: =15.4*0.17*4 -> 10.472
B23: 6 | C23: 冲击系数1＋μ | H23: 1.194
B24: 7 | C24: 跨中换算截面面积A0(m2) | H24: 1.33642
B25: 8 | C25: 对跨中截面下边缘换算截面抵抗矩W0(m3) | H25: 0.848094
B26: 9 | C26: 预应力钢束面积Ay(m2) | H26: 0.01218
B27: 10 | C27: 预应力合力中心至换算截面重心轴的距离e0(m) | H27: 1.1108
B28: 11 | C28: 收缩、徐变损失σL6(MPa) | H28: 162.93
B29: 12 | C29: 钢束松弛损失σL5(MPa) | H29: 11.94
B30: 13 | C30: 设计挠跨比f/L | H30: 1/1892
B31: 14 | C31: 设计抗裂安全系数kf | H31: 1.26
C34: P P | D34: P P | E34: P
C40: 加载图示
A41: 四、 | B41: 计算相关系数α
B42: R=5P/2
B43: M1=R×L/2=5P/2×32/2=40P
B44: M=∑PiXi=M1-8P-4P=28P
B45: 得α= | C45: 28
A47: 五、 | B47: 计算未完成应力损失的补偿弯矩ΔMS
B48: 根据梁体基本数据表中终张-加载时间的天数， | K48: =(1-0.5)/38*36+0.5 -> 0.97368421
B49: 查《预制后张法预应力混凝土简支梁静载试验方法》附录， | J49: =(0.43-0.4)/10*8+0.4 -> 0.424
B50: 查得η1、η2，并按下列公式ΔσS、ΔMS；
...

Sheet 加载记录表
A1: 静载试验加载记录表
A2: 试验梁号 | C2: =加载计算书!H7 -> FL32QB-0020 | F2: =加载计算书!H8 -> 通桥（2012）2101-Ⅰ | J2: 跨 度 （m） | M2: =加载计算书!H9 -> 32 | P2: 梁 别 | R2: 直线边梁
A3: 试验日期 | C3: =加载计算书!H14 -> 2014.12.24 | J3: 量测仪表 | M3: 百分表 | P3: 梁内外侧 | R3: 侧
A4: 加 载 情 况 | B4: 阶段 | C4: 第一加载循环 | J4: 第二加载循环
B5: 加载等级 K | C5: 初始 状态 | D5: =[1]加载计算!B79 -> Ka | E5: 0.6 | F5: =[1]加载计算!B81 -> 0.8 | G5: =[1]加载计算!B82 -> Kb | H5: =[1]加载计算!B83 -> 1 | I5: 初始 状态 | J5: =[1]加载计算!B79 -> Ka | K5: 0.6 | L5: =[1]加载计算!B81 -> 0.8 | M5: =[1]加载计算!B82 -> Kb | N5: =[1]加载计算!B83 -> 1 | O5: =[1]加载计算!B84 -> 1.05 | P5: =[1]加载计算!B85 -> 1.1 | Q5: =[1]加载计算!B86 -> 1.15 | R5: =[1]加载计算!B87 -> 1.2 | S5: 初始 状态
B6: 加载值 Pk (kN) | C6: 0 | D6: =加载计算书!F89 -> 282.09266 | E6: =加载计算书!F90 -> 292.14695 | F6: =加载计算书!F91 -> 434.10552 | G6: =加载计算书!F92 -> 528.29989 | H6: =加载计算书!F93 -> 576.06409 | I6: 0 | J6: =D6 -> 282.09266 | K6: =E6 -> 292.14695 | L6: =F6 -> 434.10552 | M6: =G6 -> 528.29989 | N6: =H6 -> 576.06409 | O6: =加载计算书!F94 -> 611.55373 | P6: =加载计算书!F95 -> 647.04337 | Q6: =加载计算书!F96 -> 682.53302 | R6: =加载计算书!F97 -> 718.02266 | S6: 0
A7: 实际持荷时间
A8: 读数仪标定计算值
A9: 读数仪实际值 | S9: -
A10: 附注 | D10: #传感器
A11: 企业名称 | D11: 北京中铁房山桥梁有限公司龙口制梁场 | H11: 操作者 | M11: 计算者 | Q11: 复核者
A12: 检验单位名称 | D12: 中铁十四局集团 | H12: 现场监视人 | N12: 签认日期

Sheet 加载时间记录表
A1: 静载试验加载时间记录表
A2: 试验梁号 | C2: =加载计算书!H7 -> FL32QB-0020 | E2: 设计图号 | H2: =加载计算书!H8 -> 通桥（2012）2101-Ⅰ | L2: 跨 度 （m） | N2: =加载计算书!H9 -> 32 | P2: 梁 别 | R2: =加载记录表!R2 -> 直线边梁
A3: 试验阶段 | C3: 第一加载循环 | J3: 第二加载循环
A4: 加载等级 K | C4: 0 | D4: Ka | E4: 0.6 | F4: 0.8 | G4: Kb | H4: 1 | I4: 0 | J4: Ka | K4: 0.6 | L4: 0.8 | M4: Kb | N4: 1 | O4: 1.05 | P4: 1.1 | Q4: 1.15 | R4: `1.20 | S4: 0
A5: 持荷开始时刻 | C5: - | S5: -
A6: 持荷结束时刻 | C6: - | S6: -
A7: 实际持荷时间 | C7: - | S7: -
A8: 附注 | C8: 1.各加载级间1.00级以前持荷3min，1.00级及以后持荷5min；第一循环Kf=1.00静停20min；第二循环Kf=1.20静停20min。 2.第一循环与第二循环之间静停（挠度恢复）10min。 3.记录实际持荷/静停的起止时刻（时：分：秒）。
A9: 企业名称 | C9: =加载记录表!D11 -> 北京中铁房山桥梁有限公司龙口制梁场 | I9: 记录人 | O9: 复核人
A10: 检验单位名称 | C10: =加载记录表!D12 -> 中铁十四局集团 | I10: 现场监视人 | O10: 签认日期

Sheet 加载挠度记录表
A1: 静载试验挠度记录表
A2: 试验梁号 | C2: =加载计算书!H7 -> FL32QB-0020 | F2: 设计图号 | H2: =加载计算书!H8 -> 通桥（2012）2101-Ⅰ | K2: 跨 度（m） | N2: =加载计算书!H9 -> 32 | Q2: 梁 别 | S2: =加载记录表!R2 -> 直线边梁
A3: 试验日期 | C3: =加载计算书!H14 -> 2014.12.24 | K3: 量测仪表 | N3: 百分表 | Q3: 梁侧 | S3: 大面侧
A4: 加 载 情 况 | B4: 阶段 | C4: 第一加载循环 | K4: 第二加载循环 | U4: 第一加载循环挠度 | V4: 第二加载循环挠度
B5: 加载级别 | C5: 初始 状态 | D5: =[1]加载计算!B79 -> Ka | E5: 0.6 | F5: =[1]加载计算!B81 -> 0.8 | G5: =[1]加载计算!B82 -> Kb | H5: =[1]加载计算!B83 -> 1 | I5: 初始 状态 | J5: 初始 状态 | K5: =[1]加载计算!B79 -> Ka | L5: 0.6 | M5: =[1]加载计算!B81 -> 0.8 | N5: =[1]加载计算!B82 -> Kb | O5: =[1]加载计算!B83 -> 1 | P5: =[1]加载计算!B84 -> 1.05 | Q5: =[1]加载计算!B85 -> 1.1 | R5: =[1]加载计算!B86 -> 1.15 | S5: =[1]加载计算!B87 -> 1.2 | T5: 初始状态
B6: 加载值(kN) | D6: =加载计算书!F89 -> 282.09266 | E6: =加载计算书!F90 -> 292.14695 | F6: =加载计算书!F91 -> 434.10552 | G6: =加载计算书!F92 -> 528.29989 | H6: =加载计算书!F93 -> 576.06409 | K6: =D6 -> 282.09266 | L6: =E6 -> 292.14695 | M6: =F6 -> 434.10552 | N6: =G6 -> 528.29989 | O6: =H6 -> 576.06409 | P6: =加载计算书!F94 -> 611.55373 | Q6: =加载计算书!F95 -> 647.04337 | R6: =加载计算书!F96 -> 682.53302 | S6: =加载计算书!F97 -> 718.02266 | T6: -
A7: 各 测 点 读 数 | B7: 支点△龙 | T7: -
B8: 跨中fL/2 | T8: -
B9: 支点△烟 | T9: -
A10: 挠度值（mm）f=fL/2-（△龙+△烟）/2 | U10: =G10-D10 -> 0 | V10: =N10-K10 -> 0
A11: 附注 | C11: 1.△龙、△烟为两端支座下沉量； 2.挠度测量应在持荷即将结束前进行； 3.每个加载循环的挠度值取梁两侧挠度的平均值。
A14: 企业名称 | C14: =加载记录表!D11 -> 北京中铁房山桥梁有限公司龙口制梁场 | I14: 操作者 | L14: 记录者 | O14: 计算者 | R14: 复核者
A15: 检验单位名称 | I15: 现场监视人 | P15: 签认日期
A16: 静载试验挠度记录表
A17: 试验梁号 | C17: =C2 -> FL32QB-0020 | F17: 设计图号 | H17: =H2 -> 通桥（2012）2101-Ⅰ | K17: 跨 度（m） | N17: =N2 -> 32 | Q17: 梁 别 | S17: =加载记录表!R2 -> 直线边梁
A18: 试验日期 | C18: =C3 -> 2014.12.24 | K18: 量测仪表 | N18: 百分表 | Q18: 梁侧 | S18: 小面侧
A19: 加 载 情 况 | B19: 阶段 | C19: 第一加载循环 | K19: 第二加载循环 | U19: 第一加载循环挠度 | V19: 第二加载循环挠度
B20: 加载级别 | C20: =C5 -> 初始 状态 | D20: =D5 -> Ka | E20: =E5 -> 0.6 | F20: =F5 -> 0.8 | G20: =G5 -> Kb | H20: =H5 -> 1 | I20: =I5 -> 初始 状态 | J20: =J5 -> 初始 状态 | ... T20: =T5 -> 初始状态
B21: 加载值(kN) | D21: =D6 -> 282.09266 | E21: =E6 -> 292.14695 | F21: =F6 -> 434.10552 | G21: =G6 -> 528.29989 | H21: =H6 -> 576.06409 | K21: =K6 -> 282.09266 | L21: =L6 -> 292.14695 | M21: =M6 -> 434.10552 | N21: =N6 -> 528.29989 | O21: =O6 -> 576.06409 | P21: =P6 -> 611.55373 | Q21: =Q6 -> 647.04337 | R21: =R6 -> 682.53302 | S21: =S6 -> 718.02266 | T21: -
A22: 各 测 点 读 数 | B22: =B7 -> 支点△龙 | T22: -
B23: 跨中fL/2 | T23: -
B24: =B9 -> 支点△烟 | T24: -
A25: =A10 -> 挠度值（mm）f=fL/2-（△龙+△烟）/2 | C25: =C23-(C24+C22)/2 -> 0 | D25: =D23-(D24+D22)/2 -> 0 | E25: =E23-(E24+E22)/2 -> 0 | F25: =F23-(F24+F22)/2 -> 0 | G25: =G23-(G24+G22)/2 -> 0 | H25: =H23-(H24+H22)/2 -> 0 | I25: =I23-(I24+I22)/2 -> 0 | J25: =J23-(J24+J22)/2 -> 0 | ... S25: =S23-(S24+S22)/2 -> 0 | U25: =G25-D25 -> 0 | V25: =N25-K25 -> 0
A26: 附注 | C26: =C11 -> 1.△龙、△烟为两端支座下沉量； 2.挠度测量应在持荷即将结束前进行； 3.每个加载循环的挠度值取梁两侧挠度的平均值。 | U26: 第一循环两侧平均挠度 | V26: 第二循环两侧平均挠度
U27: =(U10+U25)/2 -> 0 | V27: =(V10+V25)/2 -> 0
A28: 企业名称 | C28: =加载记录表!D11 -> 北京中铁房山桥梁有限公司龙口制梁场 | I28: 操作者 | L28: 记录者 | O28: 计算者 | R28: 复核者 | U28: =32000/U27 -> #DIV/0!
A29: 检验单位名称 | C29: 中铁十四局集团 | I29: 现场监视人 | P29: 签认日期
U31: =1.0409*U27 -> 0 | V31: =1.0409*V27 -> 0
U32: =32000/U31 -> #DIV/0! | V32: =1.0409*V31 -> 0
V33: =1.05*32000/1835 -> 18.310627
U34: =32000/V32 -> #DIV/0!
U35: =32000/V33 -> 1747.619 | V35: =32000/V31 -> #DIV/0!

Sheet 加载挠度记录表 (整理后的)
A1: 静载试验挠度记录表
A2: 试验梁号 | C2: =加载计算书!H7 -> FL32QB-0020 | F2: 设计图号 | H2: =加载计算书!H8 -> 通桥（2012）2101-Ⅰ | K2: 跨 度（m） | N2: =加载计算书!H9 -> 32 | Q2: 梁 别 | S2: 直线边梁
A3: 试验日期 | C3: =加载计算书!H14 -> 2014.12.24 | K3: 量测仪表 | N3: 百分表 | Q3: 梁侧
A4: 加 载 情 况 | B4: 阶段 | C4: 第一加载循环 | K4: 第二加载循环 | U4: 第一加载循环挠度 | V4: 第二加载循环挠度
B5: 加载级别 | C5: 初始 状态 | D5: =[1]加载计算!B79 -> Ka | E5: 0.6 | F5: =[1]加载计算!B81 -> 0.8 | G5: =[1]加载计算!B82 -> Kb | H5: =[1]加载计算!B83 -> 1 | I5: 初始 状态 | J5: 初始 状态 | K5: =[1]加载计算!B79 -> Ka | L5: 0.6 | M5: =[1]加载计算!B81 -> 0.8 | N5: =[1]加载计算!B82 -> Kb | O5: =[1]加载计算!B83 -> 1 | P5: =[1]加载计算!B84 -> 1.05 | Q5: =[1]加载计算!B85 -> 1.1 | R5: =[1]加载计算!B86 -> 1.15 | S5: =[1]加载计算!B87 -> 1.2 | T5: 初始状态
B6: 加载值(kN) | D6: =加载计算书!F89 -> 282.09266 | E6: =加载计算书!F90 -> 292.14695 | F6: =加载计算书!F91 -> 434.10552 | G6: =加载计算书!F92 -> 528.29989 | H6: =加载计算书!F93 -> 576.06409 | I6: 0 | J6: 0 | K6: =D6 -> 282.09266 | L6: =E6 -> 292.14695 | M6: =F6 -> 434.10552 | N6: =G6 -> 528.29989 | O6: =H6 -> 576.06409 | P6: =加载计算书!F94 -> 611.55373 | Q6: =加载计算书!F95 -> 647.04337 | R6: =加载计算书!F96 -> 682.53302 | S6: =加载计算书!F97 -> 718.02266 | T6: -
A7: 各 测 点 读 数 | B7: 支点△龙外 | T7: -
B8: 跨中fL/2外 | T8: -
B9: 支点△烟外 | T9: -
B10: 支点△龙内 | T10: -
B11: 跨中fL/2内 | T11: -
B12: 支点△烟内 | T12: -
A13: 挠度值（mm）f=（fL/2外+fL/2内-（△北外+△南外+△北内+△南内）/2）/2 | C13: =(C8+C11-(C7+C9+C10+C12)/2)/2 -> 0 | D13: =(D8+D11-(D7+D9+D10+D12)/2)/2 -> 0 | E13: =(E8+E11-(E7+E9+E10+E12)/2)/2 -> 0 | F13: =(F8+F11-(F7+F9+F10+F12)/2)/2 -> 0 | G13: =(G8+G11-(G7+G9+G10+G12)/2)/2 -> 0 | H13: =(H8+H11-(H7+H9+H10+H12)/2)/2 -> 0 | J13: =(J8+J11-(J7+J9+J10+J12)/2)/2 -> 0 | K13: =(K8+K11-(K7+K9+K10+K12)/2)/2 -> 0 | L13: =(L8+L11-(L7+L9+L10+L12)/2)/2 -> 0 | M13: =(M8+M11-(M7+M9+M10+M12)/2)/2 -> 0 | N13: =(N8+N11-(N7+N9+N10+N12)/2)/2 -> 0 | O13: =(O8+O11-(O7+O9+O10+O12)/2)/2 -> 0 | P13: =(P8+P11-(P7+P9+P10+P12)/2)/2 -> 0 | Q13: =(Q8+Q11-(Q7+Q9+Q10+Q12)/2)/2 -> 0 | ... S13: =(S8+S11-(S7+S9+S10+S12)/2)/2 -> 0 | U13: =G13-D13 -> 0 | V13: =N13-K13 -> 0
A14: 附注 | C14: 1.△龙、△烟为两端支座下沉量； 2.挠度测量应在持荷即将结束前进行； 3.每个加载循环的挠度值取梁两侧挠度的平均值。
A15: 企业名称 | C15: =加载记录表!D11 -> 北京中铁房山桥梁有限公司龙口制梁场 | I15: 操作者 | L15: 记录者 | O15: 计算者 | R15: 复核者
A16: 检验单位名称 | I16: 现场监视人 | P16: 签认日期 | R16: 41968
U18: =1.0409*#REF! -> #REF! | V18: =1.0409*#REF! -> #REF!
U19: =32000/U18 -> #REF! | V19: =1.0409*V18 -> #REF!
V20: =1.05*32000/1835 -> 18.310627
U21: =32000/V19 -> #REF!
U22: =32000/V20 -> 1747.619 | V22: =32000/V18 -> #REF!

Sheet 试验报告
A1: 静载试验弯曲抗裂试验报告
A3: 试验梁号 | D3: =加载计算书!H7 -> FL32QB-0020 | H3: 灌筑日期 | J3: =加载计算书!H12 -> 2014.10.27 | L3: 设计混凝土等级(MPa) | R3: =加载计算书!H10 -> C55
A4: 设计图号 | D4: =加载计算书!H8 -> 通桥（2012）2101-Ⅰ | H4: 张拉日期 | J4: =加载计算书!H13 -> 2014.11.16 | L4: 终张拉混凝土强度(MPa) | R4: 60.9
A5: 设计安全抗裂系数 Kf | D5: =加载计算书!H31 -> 1.26 | H5: 试验日期 | J5: =加载计算书!H14 -> 2014.12.24 | L5: 梁体混凝土28天强度(MPa) | R5: 60.4
A6: 设计挠跨比 f/L | D6: =加载计算书!H30 -> 1/1892 | H6: 检验类别 | J6: 局级投产鉴定 | L6: 梁体混凝土28天弹性模量(GPa) | R6: 46.9 | V6: ka | W6: 0.6 | X6: 0.8 | Y6: kb | Z6: 1 | AA6: 1.05 | AB6: 1.1 | AC6: 1.15 | AD6: 1.2 | AH6: ka | AI6: 0.6 | AJ6: 0.8 | AK6: kb | AL6: 1
A7: 静 载 试 验 情 况 | B7: 第一加载循环 | C7: 加载等级 K | F7: =[1]加载计算!B79 -> Ka | H7: 0.6 | J7: =[1]加载计算!B81 -> 0.8 | L7: =[1]加载计算!B82 -> Kb | O7: =[1]加载计算!B83 -> 1 | R7: 初始状态
C8: 荷载 Pk (kN) | F8: =加载挠度记录表!D6 -> 282.09266 | H8: =加载挠度记录表!E6 -> 292.14695 | J8: =加载挠度记录表!F6 -> 434.10552 | L8: =加载挠度记录表!G6 -> 528.29989 | O8: =加载挠度记录表!H6 -> 576.06409 | R8: - | U8: -0.01 | V8: 7.78 | W8: 7.75 | X8: 7.72 | Y8: 7.66 | Z8: 7.61 | AA8: 7.56 | AB8: 7.51 | AC8: 7.5 | AD8: 7.49 | AG8: -0.01 | AH8: -0.28 | AI8: -0.28 | AJ8: -0.53 | AK8: -0.74 | AL8: -0.84
C9: 跨中挠度实测值 f (mm) | F9: ='加载挠度记录表 (整理后的)'!D13 -> 0 | H9: ='加载挠度记录表 (整理后的)'!E13 -> 0 | J9: ='加载挠度记录表 (整理后的)'!F13 -> 0 | L9: ='加载挠度记录表 (整理后的)'!G13 -> 0 | O9: ='加载挠度记录表 (整理后的)'!H13 -> 0 | R9: - | U9: 0 | V9: 0.84 | W9: 0.86 | X9: 0.93 | Y9: 0.99 | Z9: 1.04 | AA9: 1.07 | AB9: 1.1 | AC9: 1.15 | AD9: 1.18 | AG9: 0 | AH9: 0.06 | AI9: 0.08 | AJ9: 0.17 | AK9: 0.3 | AL9: 0.37
C10: 静荷载挠跨比 f/L | F10: f1/L=(fkb-fka)/L= | I10: (25.66-12.34)= | K10: 1/ | L10: =32000/(L9-F9) -> #DIV/0! | U10: 0.02 | V10: 0.77 | W10: 0.79 | X10: 0.8 | Y10: 0.78 | Z10: 0.76 | AA10: 0.69 | AB10: 0.62 | AC10: 0.57 | AD10: 0.56 | AG10: 0.02 | AH10: 0.17 | AI10: 0.17 | AJ10: 0.11 | AK10: -0.19 | AL10: -0.41
C11: 梁体出现裂缝情况 | F11: 未出现受力裂纹 | U11: 0 | V11: 0.49 | W11: 0.51 | X11: 0.63 | Y11: 0.71 | Z11: 0.79 | AA11: 0.78 | AB11: 0.81 | AC11: 0.85 | AD11: 0.9 | AG11: 0 | AH11: 0.58 | AI11: 0.6 | AJ11: 0.8 | AK11: 0.05 | AL11: 0.99
B12: 第二加载循环 | C12: 加载等级 K | F12: =[1]加载计算!B79 -> Ka | G12: 0.6 | H12: =[1]加载计算!B81 -> 0.8 | I12: =[1]加载计算!B82 -> Kb | J12: =[1]加载计算!B83 -> 1 | K12: =[1]加载计算!B84 -> 1.05 | L12: =[1]加载计算!B85 -> 1.1 | M12: =[1]加载计算!B86 -> 1.15 | O12: =[1]加载计算!B87 -> 1.2 | R12: 初始状态 | U12: =(U8+U9+U10+U11)/4 -> 0.0025 | V12: =(V8+V9+V10+V11)/4 -> 2.47 | W12: =(W8+W9+W10+W11)/4 -> 2.4775 | X12: =(X8+X9+X10+X11)/4 -> 2.52 | Y12: =(Y8+Y9+Y10+Y11)/4 -> 2.535 | Z12: =(Z8+Z9+Z10+Z11)/4 -> 2.55 | AA12: =(AA8+AA9+AA10+AA11)/4 -> 2.525 | AB12: =(AB8+AB9+AB10+AB11)/4 -> 2.51 | ... AD12: =(AD8+AD9+AD10+AD11)/4 -> 2.5325 | AG12: =(AG8+AG9+AG10+AG11)/4 -> 0.0025 | AH12: =(AH8+AH9+AH10+AH11)/4 -> 0.1325 | AI12: =(AI8+AI9+AI10+AI11)/4 -> 0.1425 | AJ12: =(AJ8+AJ9+AJ10+AJ11)/4 -> 0.1375 | AK12: =(AK8+AK9+AK10+AK11)/4 -> -0.145 | AL12: =(AL8+AL9+AL10+AL11)/4 -> 0.0275
C13: 荷载 Pk (kN) | F13: =F8 -> 282.09266 | G13: =H8 -> 292.14695 | H13: =J8 -> 434.10552 | I13: =L8 -> 528.29989 | J13: =O8 -> 576.06409 | K13: =加载挠度记录表!P6 -> 611.55373 | L13: =加载挠度记录表!Q6 -> 647.04337 | M13: =加载挠度记录表!R6 -> 682.53302 | O13: =加载挠度记录表!S6 -> 718.02266 | R13: -
C14: 跨中挠度实测值 f (mm) | F14: ='加载挠度记录表 (整理后的)'!K13 -> 0 | G14: ='加载挠度记录表 (整理后的)'!L13 -> 0 | H14: ='加载挠度记录表 (整理后的)'!M13 -> 0 | I14: ='加载挠度记录表 (整理后的)'!N13 -> 0 | J14: ='加载挠度记录表 (整理后的)'!O13 -> 0 | K14: ='加载挠度记录表 (整理后的)'!P13 -> 0 | L14: ='加载挠度记录表 (整理后的)'!Q13 -> 0 | M14: ='加载挠度记录表 (整理后的)'!R13 -> 0 | O14: ='加载挠度记录表 (整理后的)'!S13 -> 0 | R14: -
C15: 静荷载挠跨比 f/L | F15: f2/L=(fkb-fka)/L= | I15: (26.2-13.48)= | K15: 1/ | L15: =32000/(I14-F14) -> #DIV/0! | U15: 0.54 | V15: 14.57 | W15: 15.57 | X15: 22.8 | Y15: 28.12 | Z15: 30.78 | AA15: 33.01 | AB15: 33.41 | AC15: 37.62 | AD15: 39.77 | AG15: 0.54 | AH15: 13.37 | AI15: 13.76 | AJ15: 21.34 | AK15: 27.03 | AL15: 30.64
C16: 梁体出现裂缝情况 | F16: 未出现受力裂纹 | U16: 0.75 | V16: 15.18 | W16: 14.37 | X16: 22.03 | Y16: 28.13 | Z16: 31.39 | AA16: 33.64 | AB16: 36.05 | AC16: 38.26 | AD16: 40.33 | AG16: 0.75 | AH16: 14.02 | AI16: 14.37 | AJ16: 22.03 | AK16: 28.13 | AL16: 31.39
A17: 加 载 图 式 | F17: 裂缝示意图 | L17: 试验结论 | U17: =(U15+U16)/2 -> 0.645 | V17: =(V15+V16)/2 -> 14.875 | W17: =(W15+W16)/2 -> 14.97 | X17: =(X15+X16)/2 -> 22.415 | Y17: =(Y15+Y16)/2 -> 28.125 | Z17: =(Z15+Z16)/2 -> 31.085 | AA17: =(AA15+AA16)/2 -> 33.325 | AB17: =(AB15+AB16)/2 -> 34.73 | ... AD17: =(AD15+AD16)/2 -> 40.05 | AG17: =(AG15+AG16)/2 -> 0.645 | AH17: =(AH15+AH16)/2 -> 13.695 | AI17: =(AI15+AI16)/2 -> 14.065 | AJ17: =(AJ15+AJ16)/2 -> 21.685 | AK17: =(AK15+AK16)/2 -> 27.58 | AL17: =(AL15+AL16)/2 -> 31.015
F18: 未出现受力裂纹 | L18: 梁体在Kf=1.20加载等级下持荷20min，梁底面及下翼缘的边角未发现任何受力裂纹；且在静活载级下： 实测挠跨比Ψf实测/L=1.0409×12.71/32000=1/2418＜1.05×1/2049=1/1951， 故判定：静载弯曲抗裂试验合格。
U20: =U17-U12 -> 0.6425 | V20: =V17-V12 -> 12.405 | W20: =W17-W12 -> 12.4925 | X20: =X17-X12 -> 19.895 | Y20: =Y17-Y12 -> 25.59 | Z20: =Z17-Z12 -> 28.535 | AA20: =AA17-AA12 -> 30.8 | AB20: =AB17-AB12 -> 32.22 | ... AD20: =AD17-AD12 -> 37.5175 | AG20: =AG17-AG12 -> 0.6425 | AH20: =AH17-AH12 -> 13.5625 | AI20: =AI17-AI12 -> 13.9225 | AJ20: =AJ17-AJ12 -> 21.5475 | AK20: =AK17-AK12 -> 27.725 | AL20: =AL17-AL12 -> 30.9875
A23: 企业名称 | C23: =加载记录表!D11 -> 北京中铁房山桥梁有限公司龙口制梁场 | J23: 试验负责人 | N23: 企业主管
A24: 检验单位名称 | J24: 技术负责人 | N24: 检验主管 | V24: =2402/1.0409 -> 2307.6184 | W24: =Y20-V20 -> 13.185 | AI24: =AK20-AH20 -> 14.1625
V25: =2517/1.0409 -> 2418.0997 | W25: =W24/32000 -> 0.00041203125 | AI25: =AI24/32000 -> 0.00044257812
V26: =32000/2402 -> 13.322231 | W26: =1/W25 -> 2427.0004 | X26: =W26*1.0409 -> 2526.2647 | AI26: =1/AI25 -> 2259.4881
V27: =32000/13.322/1.0409 -> 2307.6585
V28: =32000/2517 -> 12.713548

Sheet 传感器、千斤顶分布
A1: 加载千斤顶、传感器及百分表位置分布表
A2: 设备 位置 | B2: 距跨中8米(龙) | C2: 距跨中4米(龙) | D2: 跨中 | E2: 距跨中4米(烟) | F2: 距跨中8米(烟)
A4: 千斤顶编号
A5: 油表编号
A6: 油泵编号
A7: 传感器编号
A8: 百分表编号
A9: 设 备 位 置 图 示
A28: 制表： | C28: 审核：
